22-May-22 04:01:20 - INFO - /home/omarconde/pruebas/pruebas/views.py changed, reloading.
22-May-22 04:04:11 - INFO - /home/omarconde/pruebas/pruebas/views.py changed, reloading.
22-May-22 04:07:25 - INFO - usuario logueado:Saul
22-May-22 04:16:32 - WARNING - Not Found: /
22-May-22 04:16:37 - WARNING - Not Found: /favicon.ico
22-May-22 04:16:45 - ERROR - Internal Server Error: /verificar_token
Traceback (most recent call last):
  File "/usr/lib/python3/dist-packages/django/core/handlers/exception.py", line 34, in inner
    response = get_response(request)
  File "/usr/lib/python3/dist-packages/django/core/handlers/base.py", line 115, in _get_response
    response = self.process_exception_by_middleware(e, request)
  File "/usr/lib/python3/dist-packages/django/core/handlers/base.py", line 113, in _get_response
    response = wrapped_callback(request, *callback_args, **callback_kwargs)
  File "/home/omarconde/pruebas/pruebas/views.py", line 55, in verificar_token
    return render(request, t)
  File "/usr/lib/python3/dist-packages/django/shortcuts.py", line 36, in render
    content = loader.render_to_string(template_name, context, request, using=using)
  File "/usr/lib/python3/dist-packages/django/template/loader.py", line 61, in render_to_string
    template = get_template(template_name, using=using)
  File "/usr/lib/python3/dist-packages/django/template/loader.py", line 15, in get_template
    return engine.get_template(template_name)
  File "/usr/lib/python3/dist-packages/django/template/backends/django.py", line 34, in get_template
    return Template(self.engine.get_template(template_name), self)
  File "/usr/lib/python3/dist-packages/django/template/engine.py", line 143, in get_template
    template, origin = self.find_template(template_name)
  File "/usr/lib/python3/dist-packages/django/template/engine.py", line 125, in find_template
    template = loader.get_template(name, skip=skip)
  File "/usr/lib/python3/dist-packages/django/template/loaders/base.py", line 29, in get_template
    return Template(
  File "/usr/lib/python3/dist-packages/django/template/base.py", line 156, in __init__
    self.nodelist = self.compile_nodelist()
  File "/usr/lib/python3/dist-packages/django/template/base.py", line 194, in compile_nodelist
    return parser.parse()
  File "/usr/lib/python3/dist-packages/django/template/base.py", line 478, in parse
    raise self.error(token, e)
  File "/usr/lib/python3/dist-packages/django/template/base.py", line 476, in parse
    compiled_result = compile_func(self, token)
  File "/usr/lib/python3/dist-packages/django/template/loader_tags.py", line 266, in do_extends
    nodelist = parser.parse()
  File "/usr/lib/python3/dist-packages/django/template/base.py", line 478, in parse
    raise self.error(token, e)
  File "/usr/lib/python3/dist-packages/django/template/base.py", line 476, in parse
    compiled_result = compile_func(self, token)
  File "/usr/lib/python3/dist-packages/django/template/loader_tags.py", line 209, in do_block
    nodelist = parser.parse(('endblock',))
  File "/usr/lib/python3/dist-packages/django/template/base.py", line 483, in parse
    self.unclosed_block_tag(parse_until)
  File "/usr/lib/python3/dist-packages/django/template/base.py", line 544, in unclosed_block_tag
    raise self.error(token, msg)
django.template.exceptions.TemplateSyntaxError: Unclosed tag on line 3: 'block'. Looking for one of: endblock.
22-May-22 04:16:45 - WARNING - Not Found: /favicon.ico
22-May-22 04:17:14 - WARNING - Not Found: /favicon.ico
22-May-22 04:19:38 - INFO - /home/omarconde/pruebas/pruebas/views.py changed, reloading.
22-May-22 04:19:57 - INFO - usuario logueado:Saul
22-May-22 04:20:07 - INFO - /home/omarconde/pruebas/pruebas/views.py changed, reloading.
22-May-22 04:20:22 - INFO - /home/omarconde/pruebas/pruebas/views.py changed, reloading.
22-May-22 04:23:16 - WARNING - Not Found: /
22-May-22 04:25:35 - INFO - usuario logueado:Saul
22-May-22 04:26:17 - WARNING - Not Found: /favicon.ico
22-May-22 04:55:29 - INFO - /home/omarconde/pruebas/pruebas/views.py changed, reloading.
23-May-22 03:28:49 - WARNING - Not Found: /
23-May-22 03:28:51 - WARNING - Not Found: /favicon.ico
23-May-22 03:29:34 - WARNING - Not Found: /favicon.ico
23-May-22 03:30:01 - ERROR - Internal Server Error: /Registro_Alumnos
Traceback (most recent call last):
  File "/usr/lib/python3/dist-packages/django/core/handlers/exception.py", line 34, in inner
    response = get_response(request)
  File "/usr/lib/python3/dist-packages/django/core/handlers/base.py", line 115, in _get_response
    response = self.process_exception_by_middleware(e, request)
  File "/usr/lib/python3/dist-packages/django/core/handlers/base.py", line 113, in _get_response
    response = wrapped_callback(request, *callback_args, **callback_kwargs)
  File "/home/omarconde/pruebas/pruebas/views.py", line 111, in Registro_Alumnos
    print(alumno.contrasena)
AttributeError: 'Alumnos' object has no attribute 'contrasena'
23-May-22 03:30:47 - INFO - /home/omarconde/pruebas/pruebas/views.py changed, reloading.
23-May-22 03:30:51 - ERROR - Internal Server Error: /Registro_Alumnos
Traceback (most recent call last):
  File "/usr/lib/python3/dist-packages/django/core/handlers/exception.py", line 34, in inner
    response = get_response(request)
  File "/usr/lib/python3/dist-packages/django/core/handlers/base.py", line 124, in _get_response
    raise ValueError(
ValueError: The view pruebas.views.Registro_Alumnos didn't return an HttpResponse object. It returned None instead.
23-May-22 03:30:51 - WARNING - Not Found: /favicon.ico
23-May-22 03:31:24 - INFO - /home/omarconde/pruebas/pruebas/views.py changed, reloading.
23-May-22 03:31:29 - ERROR - Internal Server Error: /Registro_Alumnos
Traceback (most recent call last):
  File "/usr/lib/python3/dist-packages/django/core/handlers/exception.py", line 34, in inner
    response = get_response(request)
  File "/usr/lib/python3/dist-packages/django/core/handlers/base.py", line 124, in _get_response
    raise ValueError(
ValueError: The view pruebas.views.Registro_Alumnos didn't return an HttpResponse object. It returned None instead.
23-May-22 03:32:18 - INFO - /home/omarconde/pruebas/pruebas/views.py changed, reloading.
23-May-22 03:44:30 - INFO - /home/omarconde/pruebas/pruebas/views.py changed, reloading.
23-May-22 03:45:56 - INFO - /home/omarconde/pruebas/pruebas/views.py changed, reloading.
23-May-22 03:46:21 - ERROR - Internal Server Error: /Registro_Alumnos
Traceback (most recent call last):
  File "/usr/lib/python3/dist-packages/django/core/handlers/exception.py", line 34, in inner
    response = get_response(request)
  File "/usr/lib/python3/dist-packages/django/core/handlers/base.py", line 115, in _get_response
    response = self.process_exception_by_middleware(e, request)
  File "/usr/lib/python3/dist-packages/django/core/handlers/base.py", line 113, in _get_response
    response = wrapped_callback(request, *callback_args, **callback_kwargs)
  File "/home/omarconde/pruebas/pruebas/views.py", line 111, in Registro_Alumnos
    errores = verificacion_de_contrasenas(contrasena)
  File "/home/omarconde/pruebas/pruebas/views.py", line 122, in verificacion_de_contrasenas
    if alumno.Contraseña == '':
NameError: name 'alumno' is not defined
23-May-22 03:47:01 - INFO - /home/omarconde/pruebas/pruebas/views.py changed, reloading.
23-May-22 03:47:09 - ERROR - Internal Server Error: /Registro_Alumnos
Traceback (most recent call last):
  File "/usr/lib/python3/dist-packages/django/core/handlers/exception.py", line 34, in inner
    response = get_response(request)
  File "/usr/lib/python3/dist-packages/django/core/handlers/base.py", line 115, in _get_response
    response = self.process_exception_by_middleware(e, request)
  File "/usr/lib/python3/dist-packages/django/core/handlers/base.py", line 113, in _get_response
    response = wrapped_callback(request, *callback_args, **callback_kwargs)
  File "/home/omarconde/pruebas/pruebas/views.py", line 111, in Registro_Alumnos
    errores = verificacion_de_contrasenas(alumno)
  File "/home/omarconde/pruebas/pruebas/views.py", line 124, in verificacion_de_contrasenas
    if len(alumno.Contrasena) < 10:
AttributeError: 'Alumnos' object has no attribute 'Contrasena'
23-May-22 03:47:31 - INFO - /home/omarconde/pruebas/pruebas/views.py changed, reloading.
23-May-22 03:48:28 - INFO - /home/omarconde/pruebas/pruebas/views.py changed, reloading.
23-May-22 03:50:35 - INFO - /home/omarconde/pruebas/pruebas/views.py changed, reloading.
23-May-22 03:53:25 - INFO - /home/omarconde/pruebas/modelo/models.py changed, reloading.
23-May-22 04:09:26 - INFO - /home/omarconde/pruebas/pruebas/views.py changed, reloading.
23-May-22 04:10:17 - INFO - /home/omarconde/pruebas/pruebas/views.py changed, reloading.
23-May-22 04:11:11 - INFO - /home/omarconde/pruebas/pruebas/views.py changed, reloading.
23-May-22 04:12:53 - ERROR - Internal Server Error: /Registro_Alumnos
Traceback (most recent call last):
  File "/usr/lib/python3/dist-packages/django/core/handlers/exception.py", line 34, in inner
    response = get_response(request)
  File "/usr/lib/python3/dist-packages/django/core/handlers/base.py", line 115, in _get_response
    response = self.process_exception_by_middleware(e, request)
  File "/usr/lib/python3/dist-packages/django/core/handlers/base.py", line 113, in _get_response
    response = wrapped_callback(request, *callback_args, **callback_kwargs)
  File "/home/omarconde/pruebas/pruebas/views.py", line 111, in Registro_Alumnos
    errores = verificacion_de_contrasenas(alumno)
  File "/home/omarconde/pruebas/pruebas/views.py", line 128, in verificacion_de_contrasenas
    errores_password.append('La contraseña al menos debe contener una letra mayúscula')
NameError: name 'errores_password' is not defined
23-May-22 04:13:15 - INFO - /home/omarconde/pruebas/pruebas/views.py changed, reloading.
23-May-22 04:16:48 - INFO - /home/omarconde/pruebas/pruebas/views.py changed, reloading.
23-May-22 04:21:14 - INFO - /home/omarconde/pruebas/pruebas/views.py changed, reloading.
23-May-22 04:21:42 - INFO - /home/omarconde/pruebas/pruebas/views.py changed, reloading.
23-May-22 04:23:45 - INFO - /home/omarconde/pruebas/pruebas/views.py changed, reloading.
23-May-22 04:25:07 - INFO - /home/omarconde/pruebas/pruebas/views.py changed, reloading.
23-May-22 04:25:15 - ERROR - Internal Server Error: /Registro_Alumnos
Traceback (most recent call last):
  File "/usr/lib/python3/dist-packages/django/core/handlers/exception.py", line 34, in inner
    response = get_response(request)
  File "/usr/lib/python3/dist-packages/django/core/handlers/base.py", line 115, in _get_response
    response = self.process_exception_by_middleware(e, request)
  File "/usr/lib/python3/dist-packages/django/core/handlers/base.py", line 113, in _get_response
    response = wrapped_callback(request, *callback_args, **callback_kwargs)
  File "/home/omarconde/pruebas/pruebas/views.py", line 111, in Registro_Alumnos
    errores = verificacion_de_contrasenas(alumno)
  File "/home/omarconde/pruebas/pruebas/views.py", line 124, in verificacion_de_contrasenas
    errores_password.append('La contraseña no debe contener espacios')
NameError: name 'errores_password' is not defined
23-May-22 04:25:38 - INFO - /home/omarconde/pruebas/pruebas/views.py changed, reloading.
23-May-22 04:27:06 - INFO - /home/omarconde/pruebas/pruebas/views.py changed, reloading.
23-May-22 04:27:45 - INFO - /home/omarconde/pruebas/pruebas/views.py changed, reloading.
23-May-22 04:33:36 - INFO - /home/omarconde/pruebas/pruebas/views.py changed, reloading.
23-May-22 04:33:39 - INFO - /home/omarconde/pruebas/pruebas/views.py changed, reloading.
23-May-22 04:33:45 - WARNING - Not Found: /favicon.ico
23-May-22 04:39:44 - WARNING - Not Found: /favicon.ico
23-May-22 05:04:33 - INFO - /home/omarconde/pruebas/pruebas/views.py changed, reloading.
23-May-22 23:09:47 - WARNING - Not Found: /
23-May-22 23:11:39 - INFO - /home/omarconde/pruebas/pruebas/views.py changed, reloading.
23-May-22 23:13:46 - INFO - /home/omarconde/pruebas/pruebas/views.py changed, reloading.
23-May-22 23:13:56 - ERROR - Internal Server Error: /Registro_Alumnos
Traceback (most recent call last):
  File "/usr/lib/python3/dist-packages/django/core/handlers/exception.py", line 34, in inner
    response = get_response(request)
  File "/usr/lib/python3/dist-packages/django/core/handlers/base.py", line 115, in _get_response
    response = self.process_exception_by_middleware(e, request)
  File "/usr/lib/python3/dist-packages/django/core/handlers/base.py", line 113, in _get_response
    response = wrapped_callback(request, *callback_args, **callback_kwargs)
  File "/home/omarconde/pruebas/pruebas/views.py", line 112, in Registro_Alumnos
    errores = verificacion_de_contrasenas(alumno)
NameError: name 'verificacion_de_contrasenas' is not defined
23-May-22 23:15:26 - INFO - /home/omarconde/pruebas/pruebas/views.py changed, reloading.
23-May-22 23:16:52 - INFO - /home/omarconde/pruebas/pruebas/views.py changed, reloading.
23-May-22 23:16:57 - ERROR - Internal Server Error: /Registro_Alumnos
Traceback (most recent call last):
  File "/usr/lib/python3/dist-packages/django/core/handlers/exception.py", line 34, in inner
    response = get_response(request)
  File "/usr/lib/python3/dist-packages/django/core/handlers/base.py", line 115, in _get_response
    response = self.process_exception_by_middleware(e, request)
  File "/usr/lib/python3/dist-packages/django/core/handlers/base.py", line 113, in _get_response
    response = wrapped_callback(request, *callback_args, **callback_kwargs)
  File "/home/omarconde/pruebas/pruebas/views.py", line 112, in Registro_Alumnos
    errores = recoleccion_de_errores_del_registro(alumno)
  File "/home/omarconde/pruebas/pruebas/views.py", line 152, in recoleccion_de_errores_del_registro
    errores_contrasena = verificacion_de_contrasenas(alumno)
NameError: name 'verificacion_de_contrasenas' is not defined
23-May-22 23:17:29 - INFO - /home/omarconde/pruebas/pruebas/views.py changed, reloading.
23-May-22 23:17:57 - INFO - /home/omarconde/pruebas/pruebas/views.py changed, reloading.
23-May-22 23:57:57 - INFO - /home/omarconde/pruebas/pruebas/views.py changed, reloading.
24-May-22 00:03:06 - INFO - /home/omarconde/pruebas/modelo/models.py changed, reloading.
24-May-22 00:07:24 - INFO - /home/omarconde/pruebas/pruebas/views.py changed, reloading.
24-May-22 00:07:50 - INFO - /home/omarconde/pruebas/pruebas/views.py changed, reloading.
24-May-22 00:09:29 - INFO - /home/omarconde/pruebas/pruebas/views.py changed, reloading.
24-May-22 00:11:32 - ERROR - Internal Server Error: /Registro_Alumnos
Traceback (most recent call last):
  File "/usr/lib/python3/dist-packages/django/core/handlers/exception.py", line 34, in inner
    response = get_response(request)
  File "/usr/lib/python3/dist-packages/django/core/handlers/base.py", line 115, in _get_response
    response = self.process_exception_by_middleware(e, request)
  File "/usr/lib/python3/dist-packages/django/core/handlers/base.py", line 113, in _get_response
    response = wrapped_callback(request, *callback_args, **callback_kwargs)
  File "/home/omarconde/pruebas/pruebas/views.py", line 114, in Registro_Alumnos
    Elsalt = get_random_string(length=16)
NameError: name 'get_random_string' is not defined
24-May-22 00:11:33 - WARNING - Not Found: /favicon.ico
24-May-22 00:12:04 - INFO - /home/omarconde/pruebas/pruebas/views.py changed, reloading.
24-May-22 00:12:14 - ERROR - Internal Server Error: /Registro_Alumnos
Traceback (most recent call last):
  File "/usr/lib/python3/dist-packages/django/core/handlers/exception.py", line 34, in inner
    response = get_response(request)
  File "/usr/lib/python3/dist-packages/django/core/handlers/base.py", line 115, in _get_response
    response = self.process_exception_by_middleware(e, request)
  File "/usr/lib/python3/dist-packages/django/core/handlers/base.py", line 113, in _get_response
    response = wrapped_callback(request, *callback_args, **callback_kwargs)
  File "/home/omarconde/pruebas/pruebas/views.py", line 116, in Registro_Alumnos
    binario = (contrasena + Elsalt).enconde('utf-8')
AttributeError: 'str' object has no attribute 'enconde'
24-May-22 00:13:36 - INFO - /home/omarconde/pruebas/pruebas/views.py changed, reloading.
24-May-22 00:13:46 - ERROR - Internal Server Error: /Registro_Alumnos
Traceback (most recent call last):
  File "/usr/lib/python3/dist-packages/django/core/handlers/exception.py", line 34, in inner
    response = get_response(request)
  File "/usr/lib/python3/dist-packages/django/core/handlers/base.py", line 115, in _get_response
    response = self.process_exception_by_middleware(e, request)
  File "/usr/lib/python3/dist-packages/django/core/handlers/base.py", line 113, in _get_response
    response = wrapped_callback(request, *callback_args, **callback_kwargs)
  File "/home/omarconde/pruebas/pruebas/views.py", line 117, in Registro_Alumnos
    hasher = hashlib.sha256()
NameError: name 'hashlib' is not defined
24-May-22 00:14:38 - INFO - /home/omarconde/pruebas/pruebas/views.py changed, reloading.
24-May-22 00:14:45 - ERROR - Internal Server Error: /Registro_Alumnos
Traceback (most recent call last):
  File "/usr/lib/python3/dist-packages/django/core/handlers/exception.py", line 34, in inner
    response = get_response(request)
  File "/usr/lib/python3/dist-packages/django/core/handlers/base.py", line 115, in _get_response
    response = self.process_exception_by_middleware(e, request)
  File "/usr/lib/python3/dist-packages/django/core/handlers/base.py", line 113, in _get_response
    response = wrapped_callback(request, *callback_args, **callback_kwargs)
  File "/home/omarconde/pruebas/pruebas/views.py", line 117, in Registro_Alumnos
    hasher = hashlib.sha256()
NameError: name 'hashlib' is not defined
24-May-22 00:15:09 - INFO - /home/omarconde/pruebas/pruebas/views.py changed, reloading.
24-May-22 00:21:10 - INFO - /home/omarconde/pruebas/pruebas/views.py changed, reloading.
24-May-22 00:21:51 - ERROR - Internal Server Error: /login
Traceback (most recent call last):
  File "/home/omarconde/pruebas/pruebas/views.py", line 90, in login
    mandar_mensaje_al_bot(request)
  File "/home/omarconde/pruebas/pruebas/views.py", line 36, in mandar_mensaje_al_bot
    datos_guardados = models.Alumnos.objects.get(NombreAlumno=nombre)
  File "/usr/lib/python3/dist-packages/django/db/models/manager.py", line 82, in manager_method
    return getattr(self.get_queryset(), name)(*args, **kwargs)
  File "/usr/lib/python3/dist-packages/django/db/models/query.py", line 410, in get
    raise self.model.MultipleObjectsReturned(
modelo.models.Alumnos.MultipleObjectsReturned: get() returned more than one Alumnos -- it returned 9!

During handling of the above exception, another exception occurred:

Traceback (most recent call last):
  File "/usr/lib/python3/dist-packages/django/core/handlers/exception.py", line 34, in inner
    response = get_response(request)
  File "/usr/lib/python3/dist-packages/django/core/handlers/base.py", line 115, in _get_response
    response = self.process_exception_by_middleware(e, request)
  File "/usr/lib/python3/dist-packages/django/core/handlers/base.py", line 113, in _get_response
    response = wrapped_callback(request, *callback_args, **callback_kwargs)
  File "/home/omarconde/pruebas/pruebas/views.py", line 94, in login
    return render(request,t,{'errores',errores})
UnboundLocalError: local variable 't' referenced before assignment
24-May-22 00:21:53 - WARNING - Not Found: /favicon.ico
24-May-22 00:26:41 - INFO - /home/omarconde/pruebas/pruebas/views.py changed, reloading.
24-May-22 00:27:53 - INFO - /home/omarconde/pruebas/pruebas/views.py changed, reloading.
24-May-22 00:28:03 - ERROR - Internal Server Error: /login
Traceback (most recent call last):
  File "/usr/lib/python3/dist-packages/django/core/handlers/exception.py", line 34, in inner
    response = get_response(request)
  File "/usr/lib/python3/dist-packages/django/core/handlers/base.py", line 124, in _get_response
    raise ValueError(
ValueError: The view pruebas.views.login didn't return an HttpResponse object. It returned None instead.
24-May-22 00:28:05 - WARNING - Not Found: /favicon.ico
24-May-22 00:28:40 - INFO - /home/omarconde/pruebas/pruebas/views.py changed, reloading.
24-May-22 00:30:49 - ERROR - Internal Server Error: /login
Traceback (most recent call last):
  File "/home/omarconde/pruebas/pruebas/views.py", line 87, in login
    alumno = models.Alumnos.objects.get(NombreAlumno=nombre,Contraseña=contraseña)
  File "/usr/lib/python3/dist-packages/django/db/models/manager.py", line 82, in manager_method
    return getattr(self.get_queryset(), name)(*args, **kwargs)
  File "/usr/lib/python3/dist-packages/django/db/models/query.py", line 406, in get
    raise self.model.DoesNotExist(
modelo.models.Alumnos.DoesNotExist: Alumnos matching query does not exist.

During handling of the above exception, another exception occurred:

Traceback (most recent call last):
  File "/usr/lib/python3/dist-packages/django/core/handlers/exception.py", line 34, in inner
    response = get_response(request)
  File "/usr/lib/python3/dist-packages/django/core/handlers/base.py", line 115, in _get_response
    response = self.process_exception_by_middleware(e, request)
  File "/usr/lib/python3/dist-packages/django/core/handlers/base.py", line 113, in _get_response
    response = wrapped_callback(request, *callback_args, **callback_kwargs)
  File "/home/omarconde/pruebas/pruebas/views.py", line 95, in login
    return render(request,t,{'errores',errores})
UnboundLocalError: local variable 't' referenced before assignment
24-May-22 00:32:17 - INFO - /home/omarconde/pruebas/pruebas/views.py changed, reloading.
24-May-22 00:32:25 - ERROR - Internal Server Error: /login
Traceback (most recent call last):
  File "/home/omarconde/pruebas/pruebas/views.py", line 87, in login
    alumno = models.Alumnos.objects.get(NombreAlumno=nombre,Contraseña=contraseña)
  File "/usr/lib/python3/dist-packages/django/db/models/manager.py", line 82, in manager_method
    return getattr(self.get_queryset(), name)(*args, **kwargs)
  File "/usr/lib/python3/dist-packages/django/db/models/query.py", line 406, in get
    raise self.model.DoesNotExist(
modelo.models.Alumnos.DoesNotExist: Alumnos matching query does not exist.

During handling of the above exception, another exception occurred:

Traceback (most recent call last):
  File "/usr/lib/python3/dist-packages/django/core/handlers/exception.py", line 34, in inner
    response = get_response(request)
  File "/usr/lib/python3/dist-packages/django/core/handlers/base.py", line 115, in _get_response
    response = self.process_exception_by_middleware(e, request)
  File "/usr/lib/python3/dist-packages/django/core/handlers/base.py", line 113, in _get_response
    response = wrapped_callback(request, *callback_args, **callback_kwargs)
  File "/home/omarconde/pruebas/pruebas/views.py", line 95, in login
    return render(request,'login.html',{'errores',errores})
TypeError: unhashable type: 'list'
24-May-22 00:33:28 - INFO - /home/omarconde/pruebas/pruebas/views.py changed, reloading.
24-May-22 00:39:24 - INFO - /home/omarconde/pruebas/pruebas/views.py changed, reloading.
24-May-22 00:39:56 - INFO - usuario logueado:David
24-May-22 01:05:05 - WARNING - Not Found: /
24-May-22 01:05:05 - WARNING - Not Found: /favicon.ico
24-May-22 01:06:39 - WARNING - Not Found: /
24-May-22 01:07:31 - ERROR - Internal Server Error: /verificar_scripts
Traceback (most recent call last):
  File "/usr/local/lib/python3.9/dist-packages/django/core/handlers/exception.py", line 55, in inner
    response = get_response(request)
  File "/usr/local/lib/python3.9/dist-packages/django/core/handlers/base.py", line 197, in _get_response
    response = wrapped_callback(request, *callback_args, **callback_kwargs)
  File "/home/valito/Proyecto/Proyectoprograsegura1/ProyectoSeg/pruebas/views.py", line 23, in verificar_scripts
    salida = subprocess.Popen(Comando,stdout=subprocess.PIPE, stderr=subprocess.PIPE)
  File "/usr/lib/python3.9/subprocess.py", line 951, in __init__
    self._execute_child(args, executable, preexec_fn, close_fds,
  File "/usr/lib/python3.9/subprocess.py", line 1823, in _execute_child
    raise child_exception_type(errno_num, err_msg, err_filename)
FileNotFoundError: [Errno 2] No such file or directory: '/home/omarconde/hola.sh'
24-May-22 01:09:31 - ERROR - Internal Server Error: /verificar_scripts
Traceback (most recent call last):
  File "/usr/local/lib/python3.9/dist-packages/django/core/handlers/exception.py", line 55, in inner
    response = get_response(request)
  File "/usr/local/lib/python3.9/dist-packages/django/core/handlers/base.py", line 197, in _get_response
    response = wrapped_callback(request, *callback_args, **callback_kwargs)
  File "/home/valito/Proyecto/Proyectoprograsegura1/ProyectoSeg/pruebas/views.py", line 23, in verificar_scripts
    salida = subprocess.Popen(Comando,stdout=subprocess.PIPE, stderr=subprocess.PIPE)
  File "/usr/lib/python3.9/subprocess.py", line 951, in __init__
    self._execute_child(args, executable, preexec_fn, close_fds,
  File "/usr/lib/python3.9/subprocess.py", line 1823, in _execute_child
    raise child_exception_type(errno_num, err_msg, err_filename)
FileNotFoundError: [Errno 2] No such file or directory: '/home/omarconde/hola.sh'
24-May-22 01:11:32 - INFO - /home/valito/Proyecto/Proyectoprograsegura1/ProyectoSeg/pruebas/views.py changed, reloading.
24-May-22 01:21:45 - INFO - /home/valito/Proyecto/Proyectoprograsegura1/ProyectoSeg/modelo/models.py changed, reloading.
24-May-22 01:37:43 - INFO - /home/valito/Proyecto/Proyectoprograsegura1/ProyectoSeg/pruebas/views.py changed, reloading.
24-May-22 01:37:55 - ERROR - Internal Server Error: /verificar_scripts
Traceback (most recent call last):
  File "/usr/local/lib/python3.9/dist-packages/django/core/handlers/exception.py", line 55, in inner
    response = get_response(request)
  File "/usr/local/lib/python3.9/dist-packages/django/core/handlers/base.py", line 197, in _get_response
    response = wrapped_callback(request, *callback_args, **callback_kwargs)
  File "/home/valito/Proyecto/Proyectoprograsegura1/ProyectoSeg/pruebas/views.py", line 25, in verificar_scripts
    Storage.save()
NameError: name 'Storage' is not defined
24-May-22 01:38:29 - INFO - /home/valito/Proyecto/Proyectoprograsegura1/ProyectoSeg/pruebas/views.py changed, reloading.
24-May-22 03:11:33 - INFO - /home/valito/Proyecto/Proyectoprograsegura1/ProyectoSeg/pruebas/views.py changed, reloading.
24-May-22 03:11:46 - ERROR - Internal Server Error: /verificar_scripts
Traceback (most recent call last):
  File "/usr/local/lib/python3.9/dist-packages/django/utils/datastructures.py", line 84, in __getitem__
    list_ = super().__getitem__(key)
KeyError: 'ahivosubido'

During handling of the above exception, another exception occurred:

Traceback (most recent call last):
  File "/usr/local/lib/python3.9/dist-packages/django/core/handlers/exception.py", line 55, in inner
    response = get_response(request)
  File "/usr/local/lib/python3.9/dist-packages/django/core/handlers/base.py", line 197, in _get_response
    response = wrapped_callback(request, *callback_args, **callback_kwargs)
  File "/home/valito/Proyecto/Proyectoprograsegura1/ProyectoSeg/pruebas/views.py", line 20, in verificar_scripts
    file = request.FILES['ahivosubido']
  File "/usr/local/lib/python3.9/dist-packages/django/utils/datastructures.py", line 86, in __getitem__
    raise MultiValueDictKeyError(key)
django.utils.datastructures.MultiValueDictKeyError: 'ahivosubido'
24-May-22 03:12:46 - INFO - /home/valito/Proyecto/Proyectoprograsegura1/ProyectoSeg/pruebas/views.py changed, reloading.
24-May-22 03:12:50 - ERROR - Internal Server Error: /verificar_scripts
Traceback (most recent call last):
  File "/usr/local/lib/python3.9/dist-packages/django/utils/datastructures.py", line 84, in __getitem__
    list_ = super().__getitem__(key)
KeyError: 'archivosubido'

During handling of the above exception, another exception occurred:

Traceback (most recent call last):
  File "/usr/local/lib/python3.9/dist-packages/django/core/handlers/exception.py", line 55, in inner
    response = get_response(request)
  File "/usr/local/lib/python3.9/dist-packages/django/core/handlers/base.py", line 197, in _get_response
    response = wrapped_callback(request, *callback_args, **callback_kwargs)
  File "/home/valito/Proyecto/Proyectoprograsegura1/ProyectoSeg/pruebas/views.py", line 20, in verificar_scripts
    file = request.FILES['archivosubido']
  File "/usr/local/lib/python3.9/dist-packages/django/utils/datastructures.py", line 86, in __getitem__
    raise MultiValueDictKeyError(key)
django.utils.datastructures.MultiValueDictKeyError: 'archivosubido'
24-May-22 03:18:48 - INFO - /home/valito/Proyecto/Proyectoprograsegura1/ProyectoSeg/pruebas/views.py changed, reloading.
24-May-22 03:18:56 - ERROR - Internal Server Error: /verificar_scripts
Traceback (most recent call last):
  File "/usr/local/lib/python3.9/dist-packages/django/utils/datastructures.py", line 84, in __getitem__
    list_ = super().__getitem__(key)
KeyError: 'archivosubido'

During handling of the above exception, another exception occurred:

Traceback (most recent call last):
  File "/usr/local/lib/python3.9/dist-packages/django/core/handlers/exception.py", line 55, in inner
    response = get_response(request)
  File "/usr/local/lib/python3.9/dist-packages/django/core/handlers/base.py", line 197, in _get_response
    response = wrapped_callback(request, *callback_args, **callback_kwargs)
  File "/home/valito/Proyecto/Proyectoprograsegura1/ProyectoSeg/pruebas/views.py", line 22, in verificar_scripts
    file = request.FILES['archivosubido']
  File "/usr/local/lib/python3.9/dist-packages/django/utils/datastructures.py", line 86, in __getitem__
    raise MultiValueDictKeyError(key)
django.utils.datastructures.MultiValueDictKeyError: 'archivosubido'
24-May-22 03:19:08 - ERROR - Internal Server Error: /verificar_scripts
Traceback (most recent call last):
  File "/usr/local/lib/python3.9/dist-packages/django/utils/datastructures.py", line 84, in __getitem__
    list_ = super().__getitem__(key)
KeyError: 'archivosubido'

During handling of the above exception, another exception occurred:

Traceback (most recent call last):
  File "/usr/local/lib/python3.9/dist-packages/django/core/handlers/exception.py", line 55, in inner
    response = get_response(request)
  File "/usr/local/lib/python3.9/dist-packages/django/core/handlers/base.py", line 197, in _get_response
    response = wrapped_callback(request, *callback_args, **callback_kwargs)
  File "/home/valito/Proyecto/Proyectoprograsegura1/ProyectoSeg/pruebas/views.py", line 22, in verificar_scripts
    file = request.FILES['archivosubido']
  File "/usr/local/lib/python3.9/dist-packages/django/utils/datastructures.py", line 86, in __getitem__
    raise MultiValueDictKeyError(key)
django.utils.datastructures.MultiValueDictKeyError: 'archivosubido'
24-May-22 03:19:11 - ERROR - Internal Server Error: /verificar_scripts
Traceback (most recent call last):
  File "/usr/local/lib/python3.9/dist-packages/django/utils/datastructures.py", line 84, in __getitem__
    list_ = super().__getitem__(key)
KeyError: 'archivosubido'

During handling of the above exception, another exception occurred:

Traceback (most recent call last):
  File "/usr/local/lib/python3.9/dist-packages/django/core/handlers/exception.py", line 55, in inner
    response = get_response(request)
  File "/usr/local/lib/python3.9/dist-packages/django/core/handlers/base.py", line 197, in _get_response
    response = wrapped_callback(request, *callback_args, **callback_kwargs)
  File "/home/valito/Proyecto/Proyectoprograsegura1/ProyectoSeg/pruebas/views.py", line 22, in verificar_scripts
    file = request.FILES['archivosubido']
  File "/usr/local/lib/python3.9/dist-packages/django/utils/datastructures.py", line 86, in __getitem__
    raise MultiValueDictKeyError(key)
django.utils.datastructures.MultiValueDictKeyError: 'archivosubido'
24-May-22 03:19:21 - ERROR - Internal Server Error: /verificar_scripts
Traceback (most recent call last):
  File "/usr/local/lib/python3.9/dist-packages/django/utils/datastructures.py", line 84, in __getitem__
    list_ = super().__getitem__(key)
KeyError: 'archivosubido'

During handling of the above exception, another exception occurred:

Traceback (most recent call last):
  File "/usr/local/lib/python3.9/dist-packages/django/core/handlers/exception.py", line 55, in inner
    response = get_response(request)
  File "/usr/local/lib/python3.9/dist-packages/django/core/handlers/base.py", line 197, in _get_response
    response = wrapped_callback(request, *callback_args, **callback_kwargs)
  File "/home/valito/Proyecto/Proyectoprograsegura1/ProyectoSeg/pruebas/views.py", line 22, in verificar_scripts
    file = request.FILES['archivosubido']
  File "/usr/local/lib/python3.9/dist-packages/django/utils/datastructures.py", line 86, in __getitem__
    raise MultiValueDictKeyError(key)
django.utils.datastructures.MultiValueDictKeyError: 'archivosubido'
24-May-22 03:24:21 - INFO - /home/valito/Proyecto/Proyectoprograsegura1/ProyectoSeg/pruebas/views.py changed, reloading.
24-May-22 03:24:44 - ERROR - Internal Server Error: /verificar_scripts
Traceback (most recent call last):
  File "/usr/local/lib/python3.9/dist-packages/django/core/handlers/exception.py", line 55, in inner
    response = get_response(request)
  File "/usr/local/lib/python3.9/dist-packages/django/core/handlers/base.py", line 197, in _get_response
    response = wrapped_callback(request, *callback_args, **callback_kwargs)
  File "/home/valito/Proyecto/Proyectoprograsegura1/ProyectoSeg/pruebas/views.py", line 23, in verificar_scripts
    archivo = models.AlumnosA(upload=file)
AttributeError: module 'modelo.models' has no attribute 'AlumnosA'
24-May-22 03:25:19 - ERROR - Internal Server Error: /verificar_scripts
Traceback (most recent call last):
  File "/usr/local/lib/python3.9/dist-packages/django/core/handlers/exception.py", line 55, in inner
    response = get_response(request)
  File "/usr/local/lib/python3.9/dist-packages/django/core/handlers/base.py", line 197, in _get_response
    response = wrapped_callback(request, *callback_args, **callback_kwargs)
  File "/home/valito/Proyecto/Proyectoprograsegura1/ProyectoSeg/pruebas/views.py", line 23, in verificar_scripts
    archivo = models.AlumnosA(upload=file)
AttributeError: module 'modelo.models' has no attribute 'AlumnosA'
24-May-22 03:26:47 - INFO - /home/valito/Proyecto/Proyectoprograsegura1/ProyectoSeg/pruebas/views.py changed, reloading.
24-May-22 03:30:30 - INFO - /home/valito/Proyecto/Proyectoprograsegura1/ProyectoSeg/pruebas/views.py changed, reloading.
24-May-22 03:32:07 - ERROR - Internal Server Error: /verificar_scripts
Traceback (most recent call last):
  File "/usr/local/lib/python3.9/dist-packages/django/core/handlers/exception.py", line 55, in inner
    response = get_response(request)
  File "/usr/local/lib/python3.9/dist-packages/django/core/handlers/base.py", line 197, in _get_response
    response = wrapped_callback(request, *callback_args, **callback_kwargs)
  File "/home/valito/Proyecto/Proyectoprograsegura1/ProyectoSeg/pruebas/views.py", line 23, in verificar_scripts
    archivo = models.AlumnosA(upload=file)
AttributeError: module 'modelo.models' has no attribute 'AlumnosA'
24-May-22 03:32:53 - INFO - /home/valito/Proyecto/Proyectoprograsegura1/ProyectoSeg/pruebas/views.py changed, reloading.
24-May-22 03:32:59 - ERROR - Internal Server Error: /verificar_scripts
Traceback (most recent call last):
  File "/usr/local/lib/python3.9/dist-packages/django/db/backends/utils.py", line 89, in _execute
    return self.cursor.execute(sql, params)
  File "/usr/local/lib/python3.9/dist-packages/django/db/backends/sqlite3/base.py", line 477, in execute
    return Database.Cursor.execute(self, query, params)
sqlite3.IntegrityError: NOT NULL constraint failed: modelo_archivosa.usuario_id

The above exception was the direct cause of the following exception:

Traceback (most recent call last):
  File "/usr/local/lib/python3.9/dist-packages/django/core/handlers/exception.py", line 55, in inner
    response = get_response(request)
  File "/usr/local/lib/python3.9/dist-packages/django/core/handlers/base.py", line 197, in _get_response
    response = wrapped_callback(request, *callback_args, **callback_kwargs)
  File "/home/valito/Proyecto/Proyectoprograsegura1/ProyectoSeg/pruebas/views.py", line 24, in verificar_scripts
    archivo.save()
  File "/usr/local/lib/python3.9/dist-packages/django/db/models/base.py", line 806, in save
    self.save_base(
  File "/usr/local/lib/python3.9/dist-packages/django/db/models/base.py", line 857, in save_base
    updated = self._save_table(
  File "/usr/local/lib/python3.9/dist-packages/django/db/models/base.py", line 1000, in _save_table
    results = self._do_insert(
  File "/usr/local/lib/python3.9/dist-packages/django/db/models/base.py", line 1041, in _do_insert
    return manager._insert(
  File "/usr/local/lib/python3.9/dist-packages/django/db/models/manager.py", line 85, in manager_method
    return getattr(self.get_queryset(), name)(*args, **kwargs)
  File "/usr/local/lib/python3.9/dist-packages/django/db/models/query.py", line 1434, in _insert
    return query.get_compiler(using=using).execute_sql(returning_fields)
  File "/usr/local/lib/python3.9/dist-packages/django/db/models/sql/compiler.py", line 1621, in execute_sql
    cursor.execute(sql, params)
  File "/usr/local/lib/python3.9/dist-packages/django/db/backends/utils.py", line 103, in execute
    return super().execute(sql, params)
  File "/usr/local/lib/python3.9/dist-packages/django/db/backends/utils.py", line 67, in execute
    return self._execute_with_wrappers(
  File "/usr/local/lib/python3.9/dist-packages/django/db/backends/utils.py", line 80, in _execute_with_wrappers
    return executor(sql, params, many, context)
  File "/usr/local/lib/python3.9/dist-packages/django/db/backends/utils.py", line 89, in _execute
    return self.cursor.execute(sql, params)
  File "/usr/local/lib/python3.9/dist-packages/django/db/utils.py", line 91, in __exit__
    raise dj_exc_value.with_traceback(traceback) from exc_value
  File "/usr/local/lib/python3.9/dist-packages/django/db/backends/utils.py", line 89, in _execute
    return self.cursor.execute(sql, params)
  File "/usr/local/lib/python3.9/dist-packages/django/db/backends/sqlite3/base.py", line 477, in execute
    return Database.Cursor.execute(self, query, params)
django.db.utils.IntegrityError: NOT NULL constraint failed: modelo_archivosa.usuario_id
24-May-22 03:40:58 - INFO - /home/valito/Proyecto/Proyectoprograsegura1/ProyectoSeg/pruebas/views.py changed, reloading.
24-May-22 03:41:02 - ERROR - Internal Server Error: /verificar_scripts
Traceback (most recent call last):
  File "/usr/local/lib/python3.9/dist-packages/django/core/handlers/exception.py", line 55, in inner
    response = get_response(request)
  File "/usr/local/lib/python3.9/dist-packages/django/core/handlers/base.py", line 197, in _get_response
    response = wrapped_callback(request, *callback_args, **callback_kwargs)
  File "/home/valito/Proyecto/Proyectoprograsegura1/ProyectoSeg/pruebas/views.py", line 23, in verificar_scripts
    archivo = models.ArchivosA(upload=file, usuario=pk)
NameError: name 'pk' is not defined
24-May-22 03:41:19 - INFO - /home/valito/Proyecto/Proyectoprograsegura1/ProyectoSeg/pruebas/views.py changed, reloading.
24-May-22 03:41:27 - ERROR - Internal Server Error: /verificar_scripts
Traceback (most recent call last):
  File "/usr/local/lib/python3.9/dist-packages/django/db/backends/utils.py", line 89, in _execute
    return self.cursor.execute(sql, params)
  File "/usr/local/lib/python3.9/dist-packages/django/db/backends/sqlite3/base.py", line 477, in execute
    return Database.Cursor.execute(self, query, params)
sqlite3.IntegrityError: NOT NULL constraint failed: modelo_archivosa.usuario_id

The above exception was the direct cause of the following exception:

Traceback (most recent call last):
  File "/usr/local/lib/python3.9/dist-packages/django/core/handlers/exception.py", line 55, in inner
    response = get_response(request)
  File "/usr/local/lib/python3.9/dist-packages/django/core/handlers/base.py", line 197, in _get_response
    response = wrapped_callback(request, *callback_args, **callback_kwargs)
  File "/home/valito/Proyecto/Proyectoprograsegura1/ProyectoSeg/pruebas/views.py", line 24, in verificar_scripts
    archivo.save()
  File "/usr/local/lib/python3.9/dist-packages/django/db/models/base.py", line 806, in save
    self.save_base(
  File "/usr/local/lib/python3.9/dist-packages/django/db/models/base.py", line 857, in save_base
    updated = self._save_table(
  File "/usr/local/lib/python3.9/dist-packages/django/db/models/base.py", line 1000, in _save_table
    results = self._do_insert(
  File "/usr/local/lib/python3.9/dist-packages/django/db/models/base.py", line 1041, in _do_insert
    return manager._insert(
  File "/usr/local/lib/python3.9/dist-packages/django/db/models/manager.py", line 85, in manager_method
    return getattr(self.get_queryset(), name)(*args, **kwargs)
  File "/usr/local/lib/python3.9/dist-packages/django/db/models/query.py", line 1434, in _insert
    return query.get_compiler(using=using).execute_sql(returning_fields)
  File "/usr/local/lib/python3.9/dist-packages/django/db/models/sql/compiler.py", line 1621, in execute_sql
    cursor.execute(sql, params)
  File "/usr/local/lib/python3.9/dist-packages/django/db/backends/utils.py", line 103, in execute
    return super().execute(sql, params)
  File "/usr/local/lib/python3.9/dist-packages/django/db/backends/utils.py", line 67, in execute
    return self._execute_with_wrappers(
  File "/usr/local/lib/python3.9/dist-packages/django/db/backends/utils.py", line 80, in _execute_with_wrappers
    return executor(sql, params, many, context)
  File "/usr/local/lib/python3.9/dist-packages/django/db/backends/utils.py", line 89, in _execute
    return self.cursor.execute(sql, params)
  File "/usr/local/lib/python3.9/dist-packages/django/db/utils.py", line 91, in __exit__
    raise dj_exc_value.with_traceback(traceback) from exc_value
  File "/usr/local/lib/python3.9/dist-packages/django/db/backends/utils.py", line 89, in _execute
    return self.cursor.execute(sql, params)
  File "/usr/local/lib/python3.9/dist-packages/django/db/backends/sqlite3/base.py", line 477, in execute
    return Database.Cursor.execute(self, query, params)
django.db.utils.IntegrityError: NOT NULL constraint failed: modelo_archivosa.usuario_id
24-May-22 03:45:01 - INFO - /home/valito/Proyecto/Proyectoprograsegura1/ProyectoSeg/pruebas/views.py changed, reloading.
24-May-22 03:45:07 - ERROR - Internal Server Error: /verificar_scripts
Traceback (most recent call last):
  File "/usr/local/lib/python3.9/dist-packages/django/core/handlers/exception.py", line 55, in inner
    response = get_response(request)
  File "/usr/local/lib/python3.9/dist-packages/django/core/handlers/base.py", line 197, in _get_response
    response = wrapped_callback(request, *callback_args, **callback_kwargs)
  File "/home/valito/Proyecto/Proyectoprograsegura1/ProyectoSeg/pruebas/views.py", line 23, in verificar_scripts
    archivo = models.ArchivosA(upload=file, usuario=Alumnos.NombreAlumno.pk)
NameError: name 'Alumnos' is not defined
24-May-22 03:47:53 - INFO - /home/valito/Proyecto/Proyectoprograsegura1/ProyectoSeg/pruebas/views.py changed, reloading.
24-May-22 03:48:00 - ERROR - Internal Server Error: /verificar_scripts
Traceback (most recent call last):
  File "/usr/local/lib/python3.9/dist-packages/django/core/handlers/exception.py", line 55, in inner
    response = get_response(request)
  File "/usr/local/lib/python3.9/dist-packages/django/core/handlers/base.py", line 197, in _get_response
    response = wrapped_callback(request, *callback_args, **callback_kwargs)
  File "/home/valito/Proyecto/Proyectoprograsegura1/ProyectoSeg/pruebas/views.py", line 24, in verificar_scripts
    archivo = models.ArchivosA(upload=file, usuario=alumnosScript.NombreAlumno.pk)
AttributeError: 'str' object has no attribute 'pk'
24-May-22 03:53:42 - INFO - /home/valito/Proyecto/Proyectoprograsegura1/ProyectoSeg/pruebas/views.py changed, reloading.
24-May-22 03:53:47 - ERROR - Internal Server Error: /verificar_scripts
Traceback (most recent call last):
  File "/usr/local/lib/python3.9/dist-packages/django/db/backends/utils.py", line 89, in _execute
    return self.cursor.execute(sql, params)
  File "/usr/local/lib/python3.9/dist-packages/django/db/backends/sqlite3/base.py", line 477, in execute
    return Database.Cursor.execute(self, query, params)
sqlite3.IntegrityError: NOT NULL constraint failed: modelo_archivosa.usuario_id

The above exception was the direct cause of the following exception:

Traceback (most recent call last):
  File "/usr/local/lib/python3.9/dist-packages/django/core/handlers/exception.py", line 55, in inner
    response = get_response(request)
  File "/usr/local/lib/python3.9/dist-packages/django/core/handlers/base.py", line 197, in _get_response
    response = wrapped_callback(request, *callback_args, **callback_kwargs)
  File "/home/valito/Proyecto/Proyectoprograsegura1/ProyectoSeg/pruebas/views.py", line 25, in verificar_scripts
    archivo.save()
  File "/usr/local/lib/python3.9/dist-packages/django/db/models/base.py", line 806, in save
    self.save_base(
  File "/usr/local/lib/python3.9/dist-packages/django/db/models/base.py", line 857, in save_base
    updated = self._save_table(
  File "/usr/local/lib/python3.9/dist-packages/django/db/models/base.py", line 1000, in _save_table
    results = self._do_insert(
  File "/usr/local/lib/python3.9/dist-packages/django/db/models/base.py", line 1041, in _do_insert
    return manager._insert(
  File "/usr/local/lib/python3.9/dist-packages/django/db/models/manager.py", line 85, in manager_method
    return getattr(self.get_queryset(), name)(*args, **kwargs)
  File "/usr/local/lib/python3.9/dist-packages/django/db/models/query.py", line 1434, in _insert
    return query.get_compiler(using=using).execute_sql(returning_fields)
  File "/usr/local/lib/python3.9/dist-packages/django/db/models/sql/compiler.py", line 1621, in execute_sql
    cursor.execute(sql, params)
  File "/usr/local/lib/python3.9/dist-packages/django/db/backends/utils.py", line 103, in execute
    return super().execute(sql, params)
  File "/usr/local/lib/python3.9/dist-packages/django/db/backends/utils.py", line 67, in execute
    return self._execute_with_wrappers(
  File "/usr/local/lib/python3.9/dist-packages/django/db/backends/utils.py", line 80, in _execute_with_wrappers
    return executor(sql, params, many, context)
  File "/usr/local/lib/python3.9/dist-packages/django/db/backends/utils.py", line 89, in _execute
    return self.cursor.execute(sql, params)
  File "/usr/local/lib/python3.9/dist-packages/django/db/utils.py", line 91, in __exit__
    raise dj_exc_value.with_traceback(traceback) from exc_value
  File "/usr/local/lib/python3.9/dist-packages/django/db/backends/utils.py", line 89, in _execute
    return self.cursor.execute(sql, params)
  File "/usr/local/lib/python3.9/dist-packages/django/db/backends/sqlite3/base.py", line 477, in execute
    return Database.Cursor.execute(self, query, params)
django.db.utils.IntegrityError: NOT NULL constraint failed: modelo_archivosa.usuario_id
24-May-22 03:54:31 - INFO - /home/valito/Proyecto/Proyectoprograsegura1/ProyectoSeg/pruebas/views.py changed, reloading.
24-May-22 03:54:56 - ERROR - Internal Server Error: /verificar_scripts
Traceback (most recent call last):
  File "/usr/local/lib/python3.9/dist-packages/django/core/handlers/exception.py", line 55, in inner
    response = get_response(request)
  File "/usr/local/lib/python3.9/dist-packages/django/core/handlers/base.py", line 197, in _get_response
    response = wrapped_callback(request, *callback_args, **callback_kwargs)
  File "/home/valito/Proyecto/Proyectoprograsegura1/ProyectoSeg/pruebas/views.py", line 24, in verificar_scripts
    archivo = models.ArchivosA(upload=file, usuario=alumnosScript.NombreAlumno.pk)
AttributeError: 'str' object has no attribute 'pk'
24-May-22 04:01:52 - INFO - /home/valito/Proyecto/Proyectoprograsegura1/ProyectoSeg/pruebas/views.py changed, reloading.
24-May-22 04:01:56 - ERROR - Internal Server Error: /verificar_scripts
Traceback (most recent call last):
  File "/usr/local/lib/python3.9/dist-packages/django/core/handlers/exception.py", line 55, in inner
    response = get_response(request)
  File "/usr/local/lib/python3.9/dist-packages/django/core/handlers/base.py", line 197, in _get_response
    response = wrapped_callback(request, *callback_args, **callback_kwargs)
  File "/home/valito/Proyecto/Proyectoprograsegura1/ProyectoSeg/pruebas/views.py", line 23, in verificar_scripts
    alumnosScript=models.Alumnos.objects.get(pk=id_alumnos)
NameError: name 'id_alumnos' is not defined
24-May-22 04:02:36 - INFO - /home/valito/Proyecto/Proyectoprograsegura1/ProyectoSeg/pruebas/views.py changed, reloading.
24-May-22 04:02:40 - ERROR - Internal Server Error: /verificar_scripts
Traceback (most recent call last):
  File "/usr/local/lib/python3.9/dist-packages/django/core/handlers/exception.py", line 55, in inner
    response = get_response(request)
  File "/usr/local/lib/python3.9/dist-packages/django/core/handlers/base.py", line 197, in _get_response
    response = wrapped_callback(request, *callback_args, **callback_kwargs)
  File "/home/valito/Proyecto/Proyectoprograsegura1/ProyectoSeg/pruebas/views.py", line 23, in verificar_scripts
    alumnosScript=models.Alumnos.objects.get(pk=1)
  File "/usr/local/lib/python3.9/dist-packages/django/db/models/manager.py", line 85, in manager_method
    return getattr(self.get_queryset(), name)(*args, **kwargs)
  File "/usr/local/lib/python3.9/dist-packages/django/db/models/query.py", line 496, in get
    raise self.model.DoesNotExist(
modelo.models.Alumnos.DoesNotExist: Alumnos matching query does not exist.
24-May-22 04:07:52 - INFO - /home/valito/Proyecto/Proyectoprograsegura1/ProyectoSeg/pruebas/settings.py changed, reloading.
24-May-22 04:38:44 - ERROR - Internal Server Error: /Registro_Alumnos
Traceback (most recent call last):
  File "/usr/local/lib/python3.9/dist-packages/django/db/backends/utils.py", line 89, in _execute
    return self.cursor.execute(sql, params)
psycopg2.errors.StringDataRightTruncation: el valor es demasiado largo para el tipo character varying(20)


The above exception was the direct cause of the following exception:

Traceback (most recent call last):
  File "/usr/local/lib/python3.9/dist-packages/django/core/handlers/exception.py", line 55, in inner
    response = get_response(request)
  File "/usr/local/lib/python3.9/dist-packages/django/core/handlers/base.py", line 197, in _get_response
    response = wrapped_callback(request, *callback_args, **callback_kwargs)
  File "/home/valito/Proyecto/Proyectoprograsegura1/ProyectoSeg/pruebas/views.py", line 130, in Registro_Alumnos
    alumno.save()
  File "/usr/local/lib/python3.9/dist-packages/django/db/models/base.py", line 806, in save
    self.save_base(
  File "/usr/local/lib/python3.9/dist-packages/django/db/models/base.py", line 857, in save_base
    updated = self._save_table(
  File "/usr/local/lib/python3.9/dist-packages/django/db/models/base.py", line 1000, in _save_table
    results = self._do_insert(
  File "/usr/local/lib/python3.9/dist-packages/django/db/models/base.py", line 1041, in _do_insert
    return manager._insert(
  File "/usr/local/lib/python3.9/dist-packages/django/db/models/manager.py", line 85, in manager_method
    return getattr(self.get_queryset(), name)(*args, **kwargs)
  File "/usr/local/lib/python3.9/dist-packages/django/db/models/query.py", line 1434, in _insert
    return query.get_compiler(using=using).execute_sql(returning_fields)
  File "/usr/local/lib/python3.9/dist-packages/django/db/models/sql/compiler.py", line 1621, in execute_sql
    cursor.execute(sql, params)
  File "/usr/local/lib/python3.9/dist-packages/django/db/backends/utils.py", line 103, in execute
    return super().execute(sql, params)
  File "/usr/local/lib/python3.9/dist-packages/django/db/backends/utils.py", line 67, in execute
    return self._execute_with_wrappers(
  File "/usr/local/lib/python3.9/dist-packages/django/db/backends/utils.py", line 80, in _execute_with_wrappers
    return executor(sql, params, many, context)
  File "/usr/local/lib/python3.9/dist-packages/django/db/backends/utils.py", line 89, in _execute
    return self.cursor.execute(sql, params)
  File "/usr/local/lib/python3.9/dist-packages/django/db/utils.py", line 91, in __exit__
    raise dj_exc_value.with_traceback(traceback) from exc_value
  File "/usr/local/lib/python3.9/dist-packages/django/db/backends/utils.py", line 89, in _execute
    return self.cursor.execute(sql, params)
django.db.utils.DataError: el valor es demasiado largo para el tipo character varying(20)

24-May-22 04:39:49 - ERROR - Internal Server Error: /Registro_Alumnos
Traceback (most recent call last):
  File "/usr/local/lib/python3.9/dist-packages/django/db/backends/utils.py", line 89, in _execute
    return self.cursor.execute(sql, params)
psycopg2.errors.StringDataRightTruncation: el valor es demasiado largo para el tipo character varying(20)


The above exception was the direct cause of the following exception:

Traceback (most recent call last):
  File "/usr/local/lib/python3.9/dist-packages/django/core/handlers/exception.py", line 55, in inner
    response = get_response(request)
  File "/usr/local/lib/python3.9/dist-packages/django/core/handlers/base.py", line 197, in _get_response
    response = wrapped_callback(request, *callback_args, **callback_kwargs)
  File "/home/valito/Proyecto/Proyectoprograsegura1/ProyectoSeg/pruebas/views.py", line 130, in Registro_Alumnos
    alumno.save()
  File "/usr/local/lib/python3.9/dist-packages/django/db/models/base.py", line 806, in save
    self.save_base(
  File "/usr/local/lib/python3.9/dist-packages/django/db/models/base.py", line 857, in save_base
    updated = self._save_table(
  File "/usr/local/lib/python3.9/dist-packages/django/db/models/base.py", line 1000, in _save_table
    results = self._do_insert(
  File "/usr/local/lib/python3.9/dist-packages/django/db/models/base.py", line 1041, in _do_insert
    return manager._insert(
  File "/usr/local/lib/python3.9/dist-packages/django/db/models/manager.py", line 85, in manager_method
    return getattr(self.get_queryset(), name)(*args, **kwargs)
  File "/usr/local/lib/python3.9/dist-packages/django/db/models/query.py", line 1434, in _insert
    return query.get_compiler(using=using).execute_sql(returning_fields)
  File "/usr/local/lib/python3.9/dist-packages/django/db/models/sql/compiler.py", line 1621, in execute_sql
    cursor.execute(sql, params)
  File "/usr/local/lib/python3.9/dist-packages/django/db/backends/utils.py", line 103, in execute
    return super().execute(sql, params)
  File "/usr/local/lib/python3.9/dist-packages/django/db/backends/utils.py", line 67, in execute
    return self._execute_with_wrappers(
  File "/usr/local/lib/python3.9/dist-packages/django/db/backends/utils.py", line 80, in _execute_with_wrappers
    return executor(sql, params, many, context)
  File "/usr/local/lib/python3.9/dist-packages/django/db/backends/utils.py", line 89, in _execute
    return self.cursor.execute(sql, params)
  File "/usr/local/lib/python3.9/dist-packages/django/db/utils.py", line 91, in __exit__
    raise dj_exc_value.with_traceback(traceback) from exc_value
  File "/usr/local/lib/python3.9/dist-packages/django/db/backends/utils.py", line 89, in _execute
    return self.cursor.execute(sql, params)
django.db.utils.DataError: el valor es demasiado largo para el tipo character varying(20)

24-May-22 04:41:11 - ERROR - Internal Server Error: /Registro_Alumnos
Traceback (most recent call last):
  File "/usr/local/lib/python3.9/dist-packages/django/db/backends/utils.py", line 89, in _execute
    return self.cursor.execute(sql, params)
psycopg2.errors.StringDataRightTruncation: el valor es demasiado largo para el tipo character varying(20)


The above exception was the direct cause of the following exception:

Traceback (most recent call last):
  File "/usr/local/lib/python3.9/dist-packages/django/core/handlers/exception.py", line 55, in inner
    response = get_response(request)
  File "/usr/local/lib/python3.9/dist-packages/django/core/handlers/base.py", line 197, in _get_response
    response = wrapped_callback(request, *callback_args, **callback_kwargs)
  File "/home/valito/Proyecto/Proyectoprograsegura1/ProyectoSeg/pruebas/views.py", line 130, in Registro_Alumnos
    alumno.save()
  File "/usr/local/lib/python3.9/dist-packages/django/db/models/base.py", line 806, in save
    self.save_base(
  File "/usr/local/lib/python3.9/dist-packages/django/db/models/base.py", line 857, in save_base
    updated = self._save_table(
  File "/usr/local/lib/python3.9/dist-packages/django/db/models/base.py", line 1000, in _save_table
    results = self._do_insert(
  File "/usr/local/lib/python3.9/dist-packages/django/db/models/base.py", line 1041, in _do_insert
    return manager._insert(
  File "/usr/local/lib/python3.9/dist-packages/django/db/models/manager.py", line 85, in manager_method
    return getattr(self.get_queryset(), name)(*args, **kwargs)
  File "/usr/local/lib/python3.9/dist-packages/django/db/models/query.py", line 1434, in _insert
    return query.get_compiler(using=using).execute_sql(returning_fields)
  File "/usr/local/lib/python3.9/dist-packages/django/db/models/sql/compiler.py", line 1621, in execute_sql
    cursor.execute(sql, params)
  File "/usr/local/lib/python3.9/dist-packages/django/db/backends/utils.py", line 103, in execute
    return super().execute(sql, params)
  File "/usr/local/lib/python3.9/dist-packages/django/db/backends/utils.py", line 67, in execute
    return self._execute_with_wrappers(
  File "/usr/local/lib/python3.9/dist-packages/django/db/backends/utils.py", line 80, in _execute_with_wrappers
    return executor(sql, params, many, context)
  File "/usr/local/lib/python3.9/dist-packages/django/db/backends/utils.py", line 89, in _execute
    return self.cursor.execute(sql, params)
  File "/usr/local/lib/python3.9/dist-packages/django/db/utils.py", line 91, in __exit__
    raise dj_exc_value.with_traceback(traceback) from exc_value
  File "/usr/local/lib/python3.9/dist-packages/django/db/backends/utils.py", line 89, in _execute
    return self.cursor.execute(sql, params)
django.db.utils.DataError: el valor es demasiado largo para el tipo character varying(20)

24-May-22 05:10:57 - INFO - /home/valito/Proyecto/Proyectoprograsegura1/ProyectoSeg/modelo/models.py changed, reloading.
24-May-22 05:13:48 - INFO - /home/valito/Proyecto/Proyectoprograsegura1/ProyectoSeg/pruebas/views.py changed, reloading.
24-May-22 05:14:30 - ERROR - Internal Server Error: /verificar_scripts
Traceback (most recent call last):
  File "/usr/local/lib/python3.9/dist-packages/django/core/handlers/exception.py", line 55, in inner
    response = get_response(request)
  File "/usr/local/lib/python3.9/dist-packages/django/core/handlers/base.py", line 197, in _get_response
    response = wrapped_callback(request, *callback_args, **callback_kwargs)
  File "/home/valito/Proyecto/Proyectoprograsegura1/ProyectoSeg/pruebas/views.py", line 23, in verificar_scripts
    alumnosScript=models.Alumnos.objects.get(pk=id_alumno)
NameError: name 'id_alumno' is not defined
24-May-22 05:14:46 - INFO - /home/valito/Proyecto/Proyectoprograsegura1/ProyectoSeg/pruebas/views.py changed, reloading.
24-May-22 05:27:05 - WARNING - Not Found: /
24-May-22 05:27:06 - WARNING - Not Found: /favicon.ico
24-May-22 05:28:10 - WARNING - Not Found: /
24-May-22 05:28:11 - WARNING - Not Found: /favicon.ico
24-May-22 18:45:48 - WARNING - Not Found: /
24-May-22 18:46:04 - ERROR - Internal Server Error: /verificar_scripts
Traceback (most recent call last):
  File "/usr/local/lib/python3.9/dist-packages/django/utils/datastructures.py", line 84, in __getitem__
    list_ = super().__getitem__(key)
KeyError: 'archivosubido'

During handling of the above exception, another exception occurred:

Traceback (most recent call last):
  File "/usr/local/lib/python3.9/dist-packages/django/core/handlers/exception.py", line 55, in inner
    response = get_response(request)
  File "/usr/local/lib/python3.9/dist-packages/django/core/handlers/base.py", line 197, in _get_response
    response = wrapped_callback(request, *callback_args, **callback_kwargs)
  File "/home/valito/Proyecto/Proyectoprograsegura1/ProyectoSeg/pruebas/views.py", line 22, in verificar_scripts
    file = request.FILES['archivosubido']
  File "/usr/local/lib/python3.9/dist-packages/django/utils/datastructures.py", line 86, in __getitem__
    raise MultiValueDictKeyError(key)
django.utils.datastructures.MultiValueDictKeyError: 'archivosubido'
24-May-22 18:46:46 - INFO - /home/valito/Proyecto/Proyectoprograsegura1/ProyectoSeg/pruebas/views.py changed, reloading.
24-May-22 18:50:55 - INFO - /home/valito/Proyecto/Proyectoprograsegura1/ProyectoSeg/modelo/models.py changed, reloading.
24-May-22 18:55:18 - INFO - /home/valito/Proyecto/Proyectoprograsegura1/ProyectoSeg/modelo/models.py changed, reloading.
24-May-22 19:08:26 - INFO - /home/valito/Proyecto/Proyectoprograsegura1/ProyectoSeg/pruebas/settings.py changed, reloading.
24-May-22 20:01:37 - INFO - /home/valito/Proyecto/Proyectoprograsegura1/ProyectoSeg/pruebas/settings.py changed, reloading.
24-May-22 20:04:48 - INFO - /home/valito/Proyecto/Proyectoprograsegura1/ProyectoSeg/pruebas/settings.py changed, reloading.
25-May-22 16:47:24 - WARNING - Not Found: /
25-May-22 16:50:20 - INFO - /home/valito/Proyecto/Proyectoprograsegura1/ProyectoSeg/pruebas/settings.py changed, reloading.
25-May-22 16:51:39 - WARNING - Not Found: /
25-May-22 16:51:51 - WARNING - Not Found: /archivos/1
25-May-22 16:55:40 - INFO - /home/valito/Proyecto/Proyectoprograsegura1/ProyectoSeg/pruebas/settings.py changed, reloading.
25-May-22 17:00:07 - INFO - /home/valito/Proyecto/Proyectoprograsegura1/ProyectoSeg/pruebas/settings.py changed, reloading.
25-May-22 17:04:15 - INFO - /home/valito/Proyecto/Proyectoprograsegura1/ProyectoSeg/pruebas/settings.py changed, reloading.
25-May-22 17:06:02 - INFO - /home/valito/Proyecto/Proyectoprograsegura1/ProyectoSeg/pruebas/settings.py changed, reloading.
25-May-22 17:15:03 - INFO - /home/valito/Proyecto/Proyectoprograsegura1/ProyectoSeg/pruebas/settings.py changed, reloading.
25-May-22 17:26:28 - INFO - /home/valito/Proyecto/Proyectoprograsegura1/ProyectoSeg/pruebas/settings.py changed, reloading.
25-May-22 17:28:44 - WARNING - Not Found: /
25-May-22 17:31:47 - INFO - /home/valito/Proyecto/Proyectoprograsegura1/ProyectoSeg/pruebas/settings.py changed, reloading.
25-May-22 17:33:05 - INFO - /home/valito/Proyecto/Proyectoprograsegura1/ProyectoSeg/modelo/models.py changed, reloading.
25-May-22 17:33:35 - INFO - /home/valito/Proyecto/Proyectoprograsegura1/ProyectoSeg/modelo/models.py changed, reloading.
25-May-22 17:33:58 - WARNING - Not Found: /
25-May-22 17:35:45 - WARNING - Not Found: /archivos/
25-May-22 17:35:53 - WARNING - Not Found: /archivos/1
25-May-22 17:36:03 - WARNING - Not Found: /archivos/1
25-May-22 17:39:07 - WARNING - Not Found: /archivos/1
25-May-22 17:50:00 - INFO - /home/valito/Proyecto/Proyectoprograsegura1/ProyectoSeg/pruebas/views.py changed, reloading.
25-May-22 17:52:58 - INFO - /home/valito/Proyecto/Proyectoprograsegura1/ProyectoSeg/pruebas/views.py changed, reloading.
25-May-22 18:12:43 - INFO - /home/valito/Proyecto/Proyectoprograsegura1/ProyectoSeg/modelo/models.py changed, reloading.
25-May-22 18:44:06 - WARNING - Not Found: /
25-May-22 18:44:07 - WARNING - Not Found: /favicon.ico
25-May-22 18:44:12 - ERROR - Internal Server Error: /verificar_scripts
Traceback (most recent call last):
  File "/usr/local/lib/python3.9/dist-packages/django/core/handlers/exception.py", line 55, in inner
    response = get_response(request)
  File "/usr/local/lib/python3.9/dist-packages/django/core/handlers/base.py", line 197, in _get_response
    response = wrapped_callback(request, *callback_args, **callback_kwargs)
  File "/home/valito/Proyecto/Proyectoprograsegura1/ProyectoSeg/pruebas/views.py", line 31, in verificar_scripts
    salida = subprocess.Popen(comando, stdout=subprocess.PIPE, stderr=subprocess.PIPE)
  File "/usr/lib/python3.9/subprocess.py", line 951, in __init__
    self._execute_child(args, executable, preexec_fn, close_fds,
  File "/usr/lib/python3.9/subprocess.py", line 1823, in _execute_child
    raise child_exception_type(errno_num, err_msg, err_filename)
FileNotFoundError: [Errno 2] No such file or directory: 'obj.get_file'
25-May-22 18:44:56 - INFO - /home/valito/Proyecto/Proyectoprograsegura1/ProyectoSeg/pruebas/views.py changed, reloading.
25-May-22 18:45:24 - ERROR - Internal Server Error: /verificar_scripts
Traceback (most recent call last):
  File "/usr/local/lib/python3.9/dist-packages/django/core/handlers/exception.py", line 55, in inner
    response = get_response(request)
  File "/usr/local/lib/python3.9/dist-packages/django/core/handlers/base.py", line 197, in _get_response
    response = wrapped_callback(request, *callback_args, **callback_kwargs)
  File "/home/valito/Proyecto/Proyectoprograsegura1/ProyectoSeg/pruebas/views.py", line 31, in verificar_scripts
    salida = subprocess.Popen(comando, stdout=subprocess.PIPE, stderr=subprocess.PIPE)
  File "/usr/lib/python3.9/subprocess.py", line 951, in __init__
    self._execute_child(args, executable, preexec_fn, close_fds,
  File "/usr/lib/python3.9/subprocess.py", line 1823, in _execute_child
    raise child_exception_type(errno_num, err_msg, err_filename)
FileNotFoundError: [Errno 2] No such file or directory: 'get_file'
25-May-22 18:46:16 - INFO - /home/valito/Proyecto/Proyectoprograsegura1/ProyectoSeg/pruebas/views.py changed, reloading.
25-May-22 18:46:18 - ERROR - Internal Server Error: /verificar_scripts
Traceback (most recent call last):
  File "/usr/local/lib/python3.9/dist-packages/django/core/handlers/exception.py", line 55, in inner
    response = get_response(request)
  File "/usr/local/lib/python3.9/dist-packages/django/core/handlers/base.py", line 197, in _get_response
    response = wrapped_callback(request, *callback_args, **callback_kwargs)
  File "/home/valito/Proyecto/Proyectoprograsegura1/ProyectoSeg/pruebas/views.py", line 31, in verificar_scripts
    salida = subprocess.Popen(comando, stdout=subprocess.PIPE, stderr=subprocess.PIPE)
  File "/usr/lib/python3.9/subprocess.py", line 951, in __init__
    self._execute_child(args, executable, preexec_fn, close_fds,
  File "/usr/lib/python3.9/subprocess.py", line 1823, in _execute_child
    raise child_exception_type(errno_num, err_msg, err_filename)
FileNotFoundError: [Errno 2] No such file or directory: 'Archivosa.get_file'
25-May-22 18:49:36 - INFO - /home/valito/Proyecto/Proyectoprograsegura1/ProyectoSeg/pruebas/views.py changed, reloading.
25-May-22 18:49:38 - ERROR - Internal Server Error: /verificar_scripts
Traceback (most recent call last):
  File "/usr/local/lib/python3.9/dist-packages/django/core/handlers/exception.py", line 55, in inner
    response = get_response(request)
  File "/usr/local/lib/python3.9/dist-packages/django/core/handlers/base.py", line 197, in _get_response
    response = wrapped_callback(request, *callback_args, **callback_kwargs)
  File "/home/valito/Proyecto/Proyectoprograsegura1/ProyectoSeg/pruebas/views.py", line 31, in verificar_scripts
    salida = subprocess.Popen(comando, stdout=subprocess.PIPE, stderr=subprocess.PIPE)
  File "/usr/lib/python3.9/subprocess.py", line 951, in __init__
    self._execute_child(args, executable, preexec_fn, close_fds,
  File "/usr/lib/python3.9/subprocess.py", line 1698, in _execute_child
    and os.path.dirname(executable)
  File "/usr/lib/python3.9/posixpath.py", line 152, in dirname
    p = os.fspath(p)
TypeError: expected str, bytes or os.PathLike object, not method
25-May-22 18:49:54 - INFO - /home/valito/Proyecto/Proyectoprograsegura1/ProyectoSeg/pruebas/views.py changed, reloading.
25-May-22 18:50:02 - ERROR - Internal Server Error: /verificar_scripts
Traceback (most recent call last):
  File "/usr/local/lib/python3.9/dist-packages/django/core/handlers/exception.py", line 55, in inner
    response = get_response(request)
  File "/usr/local/lib/python3.9/dist-packages/django/core/handlers/base.py", line 197, in _get_response
    response = wrapped_callback(request, *callback_args, **callback_kwargs)
  File "/home/valito/Proyecto/Proyectoprograsegura1/ProyectoSeg/pruebas/views.py", line 31, in verificar_scripts
    salida = subprocess.Popen(comando, stdout=subprocess.PIPE, stderr=subprocess.PIPE)
  File "/usr/lib/python3.9/subprocess.py", line 951, in __init__
    self._execute_child(args, executable, preexec_fn, close_fds,
  File "/usr/lib/python3.9/subprocess.py", line 1823, in _execute_child
    raise child_exception_type(errno_num, err_msg, err_filename)
FileNotFoundError: [Errno 2] No such file or directory: 'obj.get_file'
25-May-22 18:50:10 - ERROR - Internal Server Error: /verificar_scripts
Traceback (most recent call last):
  File "/usr/local/lib/python3.9/dist-packages/django/core/handlers/exception.py", line 55, in inner
    response = get_response(request)
  File "/usr/local/lib/python3.9/dist-packages/django/core/handlers/base.py", line 197, in _get_response
    response = wrapped_callback(request, *callback_args, **callback_kwargs)
  File "/home/valito/Proyecto/Proyectoprograsegura1/ProyectoSeg/pruebas/views.py", line 31, in verificar_scripts
    salida = subprocess.Popen(comando, stdout=subprocess.PIPE, stderr=subprocess.PIPE)
  File "/usr/lib/python3.9/subprocess.py", line 951, in __init__
    self._execute_child(args, executable, preexec_fn, close_fds,
  File "/usr/lib/python3.9/subprocess.py", line 1823, in _execute_child
    raise child_exception_type(errno_num, err_msg, err_filename)
FileNotFoundError: [Errno 2] No such file or directory: 'obj.get_file'
25-May-22 18:50:55 - INFO - /home/valito/Proyecto/Proyectoprograsegura1/ProyectoSeg/pruebas/views.py changed, reloading.
25-May-22 18:50:56 - ERROR - Internal Server Error: /verificar_scripts
Traceback (most recent call last):
  File "/usr/local/lib/python3.9/dist-packages/django/core/handlers/exception.py", line 55, in inner
    response = get_response(request)
  File "/usr/local/lib/python3.9/dist-packages/django/core/handlers/base.py", line 197, in _get_response
    response = wrapped_callback(request, *callback_args, **callback_kwargs)
  File "/home/valito/Proyecto/Proyectoprograsegura1/ProyectoSeg/pruebas/views.py", line 32, in verificar_scripts
    salida = subprocess.Popen(comando, stdout=subprocess.PIPE, stderr=subprocess.PIPE)
  File "/usr/lib/python3.9/subprocess.py", line 951, in __init__
    self._execute_child(args, executable, preexec_fn, close_fds,
  File "/usr/lib/python3.9/subprocess.py", line 1823, in _execute_child
    raise child_exception_type(errno_num, err_msg, err_filename)
FileNotFoundError: [Errno 2] No such file or directory: 'obj.get_file'
25-May-22 19:37:59 - INFO - /home/valito/Proyecto/Proyectoprograsegura1/ProyectoSeg/pruebas/views.py changed, reloading.
25-May-22 19:38:10 - ERROR - Internal Server Error: /verificar_scripts
Traceback (most recent call last):
  File "/usr/local/lib/python3.9/dist-packages/django/core/handlers/exception.py", line 55, in inner
    response = get_response(request)
  File "/usr/local/lib/python3.9/dist-packages/django/core/handlers/base.py", line 197, in _get_response
    response = wrapped_callback(request, *callback_args, **callback_kwargs)
  File "/home/valito/Proyecto/Proyectoprograsegura1/ProyectoSeg/pruebas/views.py", line 32, in verificar_scripts
    salida = subprocess.Popen(comando, stdout=subprocess.PIPE, stderr=subprocess.PIPE)
  File "/usr/lib/python3.9/subprocess.py", line 951, in __init__
    self._execute_child(args, executable, preexec_fn, close_fds,
  File "/usr/lib/python3.9/subprocess.py", line 1823, in _execute_child
    raise child_exception_type(errno_num, err_msg, err_filename)
FileNotFoundError: [Errno 2] No such file or directory: 'obj.upload'
25-May-22 19:38:28 - INFO - /home/valito/Proyecto/Proyectoprograsegura1/ProyectoSeg/pruebas/views.py changed, reloading.
25-May-22 19:38:29 - ERROR - Internal Server Error: /verificar_scripts
Traceback (most recent call last):
  File "/usr/local/lib/python3.9/dist-packages/django/core/handlers/exception.py", line 55, in inner
    response = get_response(request)
  File "/usr/local/lib/python3.9/dist-packages/django/core/handlers/base.py", line 197, in _get_response
    response = wrapped_callback(request, *callback_args, **callback_kwargs)
  File "/home/valito/Proyecto/Proyectoprograsegura1/ProyectoSeg/pruebas/views.py", line 32, in verificar_scripts
    salida = subprocess.Popen(comando, stdout=subprocess.PIPE, stderr=subprocess.PIPE)
  File "/usr/lib/python3.9/subprocess.py", line 951, in __init__
    self._execute_child(args, executable, preexec_fn, close_fds,
  File "/usr/lib/python3.9/subprocess.py", line 1823, in _execute_child
    raise child_exception_type(errno_num, err_msg, err_filename)
FileNotFoundError: [Errno 2] No such file or directory: '{{obj.upload}}'
25-May-22 19:39:41 - ERROR - Internal Server Error: /verificar_scripts
Traceback (most recent call last):
  File "/usr/local/lib/python3.9/dist-packages/django/core/handlers/exception.py", line 55, in inner
    response = get_response(request)
  File "/usr/local/lib/python3.9/dist-packages/django/core/handlers/base.py", line 197, in _get_response
    response = wrapped_callback(request, *callback_args, **callback_kwargs)
  File "/home/valito/Proyecto/Proyectoprograsegura1/ProyectoSeg/pruebas/views.py", line 32, in verificar_scripts
    salida = subprocess.Popen(comando, stdout=subprocess.PIPE, stderr=subprocess.PIPE)
  File "/usr/lib/python3.9/subprocess.py", line 951, in __init__
    self._execute_child(args, executable, preexec_fn, close_fds,
  File "/usr/lib/python3.9/subprocess.py", line 1823, in _execute_child
    raise child_exception_type(errno_num, err_msg, err_filename)
FileNotFoundError: [Errno 2] No such file or directory: '{{obj.upload}}'
25-May-22 19:40:28 - INFO - /home/valito/Proyecto/Proyectoprograsegura1/ProyectoSeg/pruebas/views.py changed, reloading.
25-May-22 19:40:35 - ERROR - Internal Server Error: /verificar_scripts
Traceback (most recent call last):
  File "/usr/local/lib/python3.9/dist-packages/django/core/handlers/exception.py", line 55, in inner
    response = get_response(request)
  File "/usr/local/lib/python3.9/dist-packages/django/core/handlers/base.py", line 197, in _get_response
    response = wrapped_callback(request, *callback_args, **callback_kwargs)
  File "/home/valito/Proyecto/Proyectoprograsegura1/ProyectoSeg/pruebas/views.py", line 32, in verificar_scripts
    salida = subprocess.Popen(comando, stdout=subprocess.PIPE, stderr=subprocess.PIPE)
  File "/usr/lib/python3.9/subprocess.py", line 951, in __init__
    self._execute_child(args, executable, preexec_fn, close_fds,
  File "/usr/lib/python3.9/subprocess.py", line 1823, in _execute_child
    raise child_exception_type(errno_num, err_msg, err_filename)
PermissionError: [Errno 13] Permission denied: ''
25-May-22 19:41:15 - INFO - /home/valito/Proyecto/Proyectoprograsegura1/ProyectoSeg/pruebas/views.py changed, reloading.
25-May-22 19:42:41 - INFO - /home/valito/Proyecto/Proyectoprograsegura1/ProyectoSeg/pruebas/views.py changed, reloading.
25-May-22 19:48:43 - INFO - /home/valito/Proyecto/Proyectoprograsegura1/ProyectoSeg/modelo/models.py changed, reloading.
26-May-22 04:03:38 - WARNING - Not Found: /
26-May-22 20:51:22 - INFO - /home/erik/Descargas/ProyectoSeg/pruebas/settings.py changed, reloading.
26-May-22 20:52:21 - INFO - /home/erik/Descargas/ProyectoSeg/pruebas/settings.py changed, reloading.
26-May-22 20:52:49 - INFO - /home/erik/Descargas/ProyectoSeg/pruebas/views.py changed, reloading.
26-May-22 20:57:27 - INFO - /home/erik/Descargas/ProyectoSeg/pruebas/views.py changed, reloading.
26-May-22 20:58:11 - ERROR - Internal Server Error: /verificar_scripts
Traceback (most recent call last):
  File "/usr/local/lib/python3.7/dist-packages/django/core/handlers/exception.py", line 47, in inner
    response = get_response(request)
  File "/usr/local/lib/python3.7/dist-packages/django/core/handlers/base.py", line 181, in _get_response
    response = wrapped_callback(request, *callback_args, **callback_kwargs)
  File "/home/erik/Descargas/ProyectoSeg/pruebas/views.py", line 29, in verificar_scripts
    alumnosScript=models.Alumnos.objects.get(pk=1)
  File "/usr/local/lib/python3.7/dist-packages/django/db/models/manager.py", line 85, in manager_method
    return getattr(self.get_queryset(), name)(*args, **kwargs)
  File "/usr/local/lib/python3.7/dist-packages/django/db/models/query.py", line 437, in get
    self.model._meta.object_name
modelo.models.Alumnos.DoesNotExist: Alumnos matching query does not exist.
26-May-22 20:58:48 - WARNING - Not Found: /
26-May-22 21:00:10 - WARNING - Not Found: /
26-May-22 21:00:11 - WARNING - Not Found: /
26-May-22 21:00:12 - WARNING - Not Found: /
26-May-22 21:00:12 - WARNING - Not Found: /
26-May-22 21:00:12 - WARNING - Not Found: /
26-May-22 21:00:12 - WARNING - Not Found: /
26-May-22 21:00:12 - WARNING - Not Found: /
26-May-22 21:00:12 - WARNING - Not Found: /
26-May-22 21:00:12 - WARNING - Not Found: /
26-May-22 21:00:20 - WARNING - Not Found: / verificar_scripts
26-May-22 21:00:21 - WARNING - Not Found: / verificar_scripts
26-May-22 21:00:21 - WARNING - Not Found: / verificar_scripts
26-May-22 21:00:21 - WARNING - Not Found: / verificar_scripts
26-May-22 21:00:21 - WARNING - Not Found: / verificar_scripts
26-May-22 22:29:50 - INFO - /home/erik/Descargas/ProyectoSeg/pruebas/views.py changed, reloading.
27-May-22 01:23:44 - WARNING - Not Found: /
27-May-22 01:23:45 - WARNING - Not Found: /
27-May-22 01:23:45 - WARNING - Not Found: /
27-May-22 01:23:45 - WARNING - Not Found: /
27-May-22 01:23:46 - WARNING - Not Found: /
27-May-22 01:23:46 - WARNING - Not Found: /
27-May-22 01:23:46 - WARNING - Not Found: /
27-May-22 01:23:46 - WARNING - Not Found: /
27-May-22 01:23:46 - WARNING - Not Found: /
27-May-22 01:23:46 - WARNING - Not Found: /
27-May-22 01:23:46 - WARNING - Not Found: /
27-May-22 01:23:46 - WARNING - Not Found: /
27-May-22 01:23:47 - WARNING - Not Found: /
27-May-22 01:23:47 - WARNING - Not Found: /
27-May-22 01:23:47 - WARNING - Not Found: /
27-May-22 01:23:47 - WARNING - Not Found: /
27-May-22 01:23:47 - WARNING - Not Found: /
27-May-22 01:23:47 - WARNING - Not Found: /
27-May-22 01:47:01 - INFO - /home/erik/Descargas/ProyectoSeg/pruebas/views.py changed, reloading.
27-May-22 01:47:32 - ERROR - Internal Server Error: /verificar_scripts
Traceback (most recent call last):
  File "/usr/local/lib/python3.7/dist-packages/django/core/handlers/exception.py", line 47, in inner
    response = get_response(request)
  File "/usr/local/lib/python3.7/dist-packages/django/core/handlers/base.py", line 181, in _get_response
    response = wrapped_callback(request, *callback_args, **callback_kwargs)
  File "/home/erik/Descargas/ProyectoSeg/pruebas/views.py", line 30, in verificar_scripts
    alumnosScript=models.Alumnos.objects.get(pk=2)
  File "/usr/local/lib/python3.7/dist-packages/django/db/models/manager.py", line 85, in manager_method
    return getattr(self.get_queryset(), name)(*args, **kwargs)
  File "/usr/local/lib/python3.7/dist-packages/django/db/models/query.py", line 437, in get
    self.model._meta.object_name
modelo.models.Alumnos.DoesNotExist: Alumnos matching query does not exist.
27-May-22 01:48:42 - INFO - /home/erik/Descargas/ProyectoSeg/pruebas/views.py changed, reloading.
27-May-22 01:48:52 - ERROR - Internal Server Error: /verificar_scripts
Traceback (most recent call last):
  File "/usr/local/lib/python3.7/dist-packages/django/core/handlers/exception.py", line 47, in inner
    response = get_response(request)
  File "/usr/local/lib/python3.7/dist-packages/django/core/handlers/base.py", line 181, in _get_response
    response = wrapped_callback(request, *callback_args, **callback_kwargs)
  File "/home/erik/Descargas/ProyectoSeg/pruebas/views.py", line 30, in verificar_scripts
    alumnosScript=models.Alumnos.objects.get(pk=2)
  File "/usr/local/lib/python3.7/dist-packages/django/db/models/manager.py", line 85, in manager_method
    return getattr(self.get_queryset(), name)(*args, **kwargs)
  File "/usr/local/lib/python3.7/dist-packages/django/db/models/query.py", line 437, in get
    self.model._meta.object_name
modelo.models.Alumnos.DoesNotExist: Alumnos matching query does not exist.
27-May-22 03:00:23 - WARNING - Not Found: /
27-May-22 03:00:24 - WARNING - Not Found: /
27-May-22 03:00:24 - WARNING - Not Found: /
27-May-22 03:00:24 - WARNING - Not Found: /
27-May-22 03:00:24 - WARNING - Not Found: /
27-May-22 03:00:24 - WARNING - Not Found: /
27-May-22 03:00:24 - WARNING - Not Found: /
27-May-22 03:00:25 - WARNING - Not Found: /
27-May-22 03:00:25 - WARNING - Not Found: /
27-May-22 03:00:25 - WARNING - Not Found: /
27-May-22 03:00:25 - WARNING - Not Found: /
27-May-22 03:00:25 - WARNING - Not Found: /
27-May-22 03:00:25 - WARNING - Not Found: /
27-May-22 03:00:25 - WARNING - Not Found: /
27-May-22 03:39:18 - INFO - /home/erik/Descargas/ProyectoSeg/pruebas/views.py changed, reloading.
27-May-22 03:41:18 - INFO - /home/erik/Descargas/ProyectoSeg/pruebas/views.py changed, reloading.
27-May-22 03:43:26 - ERROR - Internal Server Error: /verificar_scripts
Traceback (most recent call last):
  File "/usr/local/lib/python3.7/dist-packages/django/core/handlers/exception.py", line 47, in inner
    response = get_response(request)
  File "/usr/local/lib/python3.7/dist-packages/django/core/handlers/base.py", line 181, in _get_response
    response = wrapped_callback(request, *callback_args, **callback_kwargs)
  File "/home/erik/Descargas/ProyectoSeg/pruebas/views.py", line 33, in verificar_scripts
    archivoObtenido = open("home/erik/Descargas/ProyectoSeg/archivos/Practicas/hola.sh")
FileNotFoundError: [Errno 2] No such file or directory: 'home/erik/Descargas/ProyectoSeg/archivos/Practicas/hola.sh'
27-May-22 03:45:42 - INFO - /home/erik/Descargas/ProyectoSeg/pruebas/views.py changed, reloading.
27-May-22 04:15:20 - INFO - /home/erik/Descargas/ProyectoSeg/modelo/models.py changed, reloading.
27-May-22 04:18:20 - INFO - /home/erik/Descargas/ProyectoSeg/modelo/models.py changed, reloading.
27-May-22 04:18:37 - INFO - /home/erik/Descargas/ProyectoSeg/modelo/models.py changed, reloading.
27-May-22 04:39:01 - INFO - /home/erik/Descargas/ProyectoSeg/pruebas/views.py changed, reloading.
27-May-22 04:39:44 - ERROR - Internal Server Error: /verificar_scripts
Traceback (most recent call last):
  File "/usr/local/lib/python3.7/dist-packages/django/core/handlers/exception.py", line 47, in inner
    response = get_response(request)
  File "/usr/local/lib/python3.7/dist-packages/django/core/handlers/base.py", line 181, in _get_response
    response = wrapped_callback(request, *callback_args, **callback_kwargs)
  File "/home/erik/Descargas/ProyectoSeg/pruebas/views.py", line 33, in verificar_scripts
    obtenerArchivo = alumnosScript.upload
AttributeError: 'Alumnos' object has no attribute 'upload'
27-May-22 04:50:39 - INFO - /home/erik/Descargas/ProyectoSeg/pruebas/views.py changed, reloading.
27-May-22 05:02:19 - INFO - /home/erik/Descargas/ProyectoSeg/pruebas/views.py changed, reloading.
27-May-22 05:02:51 - ERROR - Internal Server Error: /verificar_scripts
Traceback (most recent call last):
  File "/usr/local/lib/python3.7/dist-packages/django/core/handlers/exception.py", line 47, in inner
    response = get_response(request)
  File "/usr/local/lib/python3.7/dist-packages/django/core/handlers/base.py", line 181, in _get_response
    response = wrapped_callback(request, *callback_args, **callback_kwargs)
  File "/home/erik/Descargas/ProyectoSeg/pruebas/views.py", line 44, in verificar_scripts
    salida = subprocess.Popen(comando, stdout=subprocess.PIPE, stderr=subprocess.PIPE)
  File "/usr/lib/python3.7/subprocess.py", line 775, in __init__
    restore_signals, start_new_session)
  File "/usr/lib/python3.7/subprocess.py", line 1436, in _execute_child
    executable = os.fsencode(executable)
  File "/usr/lib/python3.7/os.py", line 809, in fsencode
    filename = fspath(filename)  # Does type-checking of `filename`.
TypeError: expected str, bytes or os.PathLike object, not FieldFile
27-May-22 05:05:52 - INFO - /home/erik/Descargas/ProyectoSeg/pruebas/views.py changed, reloading.
27-May-22 05:06:06 - ERROR - Internal Server Error: /verificar_scripts
Traceback (most recent call last):
  File "/usr/local/lib/python3.7/dist-packages/django/core/handlers/exception.py", line 47, in inner
    response = get_response(request)
  File "/usr/local/lib/python3.7/dist-packages/django/core/handlers/base.py", line 181, in _get_response
    response = wrapped_callback(request, *callback_args, **callback_kwargs)
  File "/home/erik/Descargas/ProyectoSeg/pruebas/views.py", line 43, in verificar_scripts
    comando = ['/'+prueba, entrada]
TypeError: can only concatenate str (not "FieldFile") to str
27-May-22 05:07:39 - INFO - /home/erik/Descargas/ProyectoSeg/pruebas/views.py changed, reloading.
27-May-22 05:08:07 - ERROR - Internal Server Error: /verificar_scripts
Traceback (most recent call last):
  File "/usr/local/lib/python3.7/dist-packages/django/core/handlers/exception.py", line 47, in inner
    response = get_response(request)
  File "/usr/local/lib/python3.7/dist-packages/django/core/handlers/base.py", line 181, in _get_response
    response = wrapped_callback(request, *callback_args, **callback_kwargs)
  File "/home/erik/Descargas/ProyectoSeg/pruebas/views.py", line 43, in verificar_scripts
    archivotxt = prueba.decode('utf-8').strip
AttributeError: 'FieldFile' object has no attribute 'decode'
27-May-22 05:08:43 - INFO - /home/erik/Descargas/ProyectoSeg/pruebas/views.py changed, reloading.
27-May-22 05:08:59 - ERROR - Internal Server Error: /verificar_scripts
Traceback (most recent call last):
  File "/usr/local/lib/python3.7/dist-packages/django/core/handlers/exception.py", line 47, in inner
    response = get_response(request)
  File "/usr/local/lib/python3.7/dist-packages/django/core/handlers/base.py", line 181, in _get_response
    response = wrapped_callback(request, *callback_args, **callback_kwargs)
  File "/home/erik/Descargas/ProyectoSeg/pruebas/views.py", line 43, in verificar_scripts
    archivotxt = prueba.decode('utf-8').strip()
AttributeError: 'FieldFile' object has no attribute 'decode'
30-May-22 03:59:12 - WARNING - Not Found: /
30-May-22 03:59:13 - WARNING - Not Found: /favicon.ico
30-May-22 03:59:22 - ERROR - Internal Server Error: /verificar_scripts
Traceback (most recent call last):
  File "/usr/local/lib/python3.7/dist-packages/django/core/handlers/exception.py", line 47, in inner
    response = get_response(request)
  File "/usr/local/lib/python3.7/dist-packages/django/core/handlers/base.py", line 181, in _get_response
    response = wrapped_callback(request, *callback_args, **callback_kwargs)
  File "/home/erik/Descargas/ProyectoSeg/pruebas/views.py", line 43, in verificar_scripts
    archivotxt = prueba.decode('utf-8').strip()
AttributeError: 'FieldFile' object has no attribute 'decode'
30-May-22 04:18:35 - WARNING - Not Found: /
30-May-22 04:18:36 - WARNING - Not Found: /
30-May-22 04:18:38 - WARNING - Not Found: /favicon.ico
30-May-22 04:18:50 - ERROR - Internal Server Error: /verificar_scripts
Traceback (most recent call last):
  File "/usr/local/lib/python3.7/dist-packages/django/core/handlers/exception.py", line 47, in inner
    response = get_response(request)
  File "/usr/local/lib/python3.7/dist-packages/django/core/handlers/base.py", line 181, in _get_response
    response = wrapped_callback(request, *callback_args, **callback_kwargs)
  File "/home/erik/Descargas/ProyectoSeg/pruebas/views.py", line 41, in verificar_scripts
    if esperada == stdout.decode('utf-8').strip():
NameError: name 'stdout' is not defined
30-May-22 04:19:14 - INFO - /home/erik/Descargas/ProyectoSeg/pruebas/views.py changed, reloading.
30-May-22 04:19:20 - INFO - /home/erik/Descargas/ProyectoSeg/pruebas/views.py changed, reloading.
30-May-22 04:19:34 - ERROR - Internal Server Error: /verificar_scripts
Traceback (most recent call last):
  File "/usr/local/lib/python3.7/dist-packages/django/core/handlers/exception.py", line 47, in inner
    response = get_response(request)
  File "/usr/local/lib/python3.7/dist-packages/django/core/handlers/base.py", line 181, in _get_response
    response = wrapped_callback(request, *callback_args, **callback_kwargs)
  File "/home/erik/Descargas/ProyectoSeg/pruebas/views.py", line 38, in verificar_scripts
    salida = subprocess.Popen(comando, stdout=subprocess.PIPE, stderr=subprocess.PIPE)
NameError: name 'comando' is not defined
30-May-22 04:20:08 - INFO - /home/erik/Descargas/ProyectoSeg/pruebas/views.py changed, reloading.
30-May-22 04:20:13 - ERROR - Internal Server Error: /verificar_scripts
Traceback (most recent call last):
  File "/usr/local/lib/python3.7/dist-packages/django/core/handlers/exception.py", line 47, in inner
    response = get_response(request)
  File "/usr/local/lib/python3.7/dist-packages/django/core/handlers/base.py", line 181, in _get_response
    response = wrapped_callback(request, *callback_args, **callback_kwargs)
  File "/home/erik/Descargas/ProyectoSeg/pruebas/views.py", line 33, in verificar_scripts
    obj = models.ArchivosA.objects.get(pk=50)
  File "/usr/local/lib/python3.7/dist-packages/django/db/models/manager.py", line 85, in manager_method
    return getattr(self.get_queryset(), name)(*args, **kwargs)
  File "/usr/local/lib/python3.7/dist-packages/django/db/models/query.py", line 437, in get
    self.model._meta.object_name
modelo.models.ArchivosA.DoesNotExist: ArchivosA matching query does not exist.
30-May-22 04:21:40 - INFO - /home/erik/Descargas/ProyectoSeg/pruebas/views.py changed, reloading.
30-May-22 04:21:44 - ERROR - Internal Server Error: /verificar_scripts
Traceback (most recent call last):
  File "/usr/local/lib/python3.7/dist-packages/django/core/handlers/exception.py", line 47, in inner
    response = get_response(request)
  File "/usr/local/lib/python3.7/dist-packages/django/core/handlers/base.py", line 181, in _get_response
    response = wrapped_callback(request, *callback_args, **callback_kwargs)
  File "/home/erik/Descargas/ProyectoSeg/pruebas/views.py", line 38, in verificar_scripts
    salida = subprocess.Popen(comando, stdout=subprocess.PIPE, stderr=subprocess.PIPE)
NameError: name 'comando' is not defined
30-May-22 04:24:10 - INFO - /home/erik/Descargas/ProyectoSeg/pruebas/views.py changed, reloading.
30-May-22 04:25:55 - INFO - /home/erik/Descargas/ProyectoSeg/pruebas/views.py changed, reloading.
30-May-22 04:26:29 - ERROR - Internal Server Error: /verificar_scripts
Traceback (most recent call last):
  File "/usr/local/lib/python3.7/dist-packages/django/core/handlers/exception.py", line 47, in inner
    response = get_response(request)
  File "/usr/local/lib/python3.7/dist-packages/django/core/handlers/base.py", line 181, in _get_response
    response = wrapped_callback(request, *callback_args, **callback_kwargs)
  File "/home/erik/Descargas/ProyectoSeg/pruebas/views.py", line 43, in verificar_scripts
    os.chmod(ruta, stat.S_IXUSR)
NameError: name 'os' is not defined
30-May-22 04:27:26 - INFO - /home/erik/Descargas/ProyectoSeg/pruebas/views.py changed, reloading.
30-May-22 04:28:33 - INFO - /home/erik/Descargas/ProyectoSeg/pruebas/views.py changed, reloading.
30-May-22 04:28:38 - ERROR - Internal Server Error: /verificar_scripts
Traceback (most recent call last):
  File "/usr/local/lib/python3.7/dist-packages/django/core/handlers/exception.py", line 47, in inner
    response = get_response(request)
  File "/usr/local/lib/python3.7/dist-packages/django/core/handlers/base.py", line 181, in _get_response
    response = wrapped_callback(request, *callback_args, **callback_kwargs)
  File "/home/erik/Descargas/ProyectoSeg/pruebas/views.py", line 47, in verificar_scripts
    salida = subprocess.Popen(comando, stdout=subprocess.PIPE, stderr=subprocess.PIPE)
  File "/usr/lib/python3.7/subprocess.py", line 775, in __init__
    restore_signals, start_new_session)
  File "/usr/lib/python3.7/subprocess.py", line 1522, in _execute_child
    raise child_exception_type(errno_num, err_msg, err_filename)
OSError: [Errno 8] Exec format error: '/home/erik/Descargas/ProyectoSeg/archivos/Practicas/hola2_r7MsDfz.sh'
30-May-22 04:28:53 - ERROR - Internal Server Error: /verificar_scripts
Traceback (most recent call last):
  File "/usr/local/lib/python3.7/dist-packages/django/core/handlers/exception.py", line 47, in inner
    response = get_response(request)
  File "/usr/local/lib/python3.7/dist-packages/django/core/handlers/base.py", line 181, in _get_response
    response = wrapped_callback(request, *callback_args, **callback_kwargs)
  File "/home/erik/Descargas/ProyectoSeg/pruebas/views.py", line 47, in verificar_scripts
    salida = subprocess.Popen(comando, stdout=subprocess.PIPE, stderr=subprocess.PIPE)
  File "/usr/lib/python3.7/subprocess.py", line 775, in __init__
    restore_signals, start_new_session)
  File "/usr/lib/python3.7/subprocess.py", line 1522, in _execute_child
    raise child_exception_type(errno_num, err_msg, err_filename)
OSError: [Errno 8] Exec format error: '/home/erik/Descargas/ProyectoSeg/archivos/Practicas/hola2_r7MsDfz.sh'
30-May-22 04:29:27 - INFO - /home/erik/Descargas/ProyectoSeg/pruebas/views.py changed, reloading.
30-May-22 04:29:59 - ERROR - Internal Server Error: /verificar_scripts
Traceback (most recent call last):
  File "/usr/local/lib/python3.7/dist-packages/django/core/handlers/exception.py", line 47, in inner
    response = get_response(request)
  File "/usr/local/lib/python3.7/dist-packages/django/core/handlers/base.py", line 181, in _get_response
    response = wrapped_callback(request, *callback_args, **callback_kwargs)
  File "/home/erik/Descargas/ProyectoSeg/pruebas/views.py", line 47, in verificar_scripts
    salida = subprocess.Popen(comando, stdout=subprocess.PIPE, stderr=subprocess.PIPE)
  File "/usr/lib/python3.7/subprocess.py", line 775, in __init__
    restore_signals, start_new_session)
  File "/usr/lib/python3.7/subprocess.py", line 1522, in _execute_child
    raise child_exception_type(errno_num, err_msg, err_filename)
OSError: [Errno 8] Exec format error: '/home/erik/Descargas/ProyectoSeg/archivos/Practicas/hola2.sh'
30-May-22 04:33:01 - INFO - /home/erik/Descargas/ProyectoSeg/pruebas/views.py changed, reloading.
30-May-22 04:33:18 - INFO - /home/erik/Descargas/ProyectoSeg/pruebas/views.py changed, reloading.
30-May-22 04:33:35 - ERROR - Internal Server Error: /verificar_scripts
Traceback (most recent call last):
  File "/usr/local/lib/python3.7/dist-packages/django/core/handlers/exception.py", line 47, in inner
    response = get_response(request)
  File "/usr/local/lib/python3.7/dist-packages/django/core/handlers/base.py", line 181, in _get_response
    response = wrapped_callback(request, *callback_args, **callback_kwargs)
  File "/home/erik/Descargas/ProyectoSeg/pruebas/views.py", line 47, in verificar_scripts
    salida = subprocess.Popen(comando, stdout=subprocess.PIPE, stderr=subprocess.PIPE)
  File "/usr/lib/python3.7/subprocess.py", line 775, in __init__
    restore_signals, start_new_session)
  File "/usr/lib/python3.7/subprocess.py", line 1522, in _execute_child
    raise child_exception_type(errno_num, err_msg, err_filename)
OSError: [Errno 8] Exec format error: '/home/erik/Descargas/ProyectoSeg/archivos/Practicas/hola2.sh'
30-May-22 04:34:47 - INFO - /home/erik/Descargas/ProyectoSeg/pruebas/views.py changed, reloading.
30-May-22 04:34:52 - ERROR - Internal Server Error: /verificar_scripts
Traceback (most recent call last):
  File "/usr/local/lib/python3.7/dist-packages/django/core/handlers/exception.py", line 47, in inner
    response = get_response(request)
  File "/usr/local/lib/python3.7/dist-packages/django/core/handlers/base.py", line 181, in _get_response
    response = wrapped_callback(request, *callback_args, **callback_kwargs)
  File "/home/erik/Descargas/ProyectoSeg/pruebas/views.py", line 47, in verificar_scripts
    salida = subprocess.Popen(comando, stdout=subprocess.PIPE, stderr=subprocess.PIPE)
  File "/usr/lib/python3.7/subprocess.py", line 775, in __init__
    restore_signals, start_new_session)
  File "/usr/lib/python3.7/subprocess.py", line 1522, in _execute_child
    raise child_exception_type(errno_num, err_msg, err_filename)
OSError: [Errno 8] Exec format error: '/home/erik/Descargas/ProyectoSeg/archivos/Practicas/hola2.sh'
30-May-22 04:35:04 - INFO - /home/erik/Descargas/ProyectoSeg/pruebas/views.py changed, reloading.
30-May-22 04:36:04 - INFO - /home/erik/Descargas/ProyectoSeg/pruebas/views.py changed, reloading.
30-May-22 04:36:09 - ERROR - Internal Server Error: /verificar_scripts
Traceback (most recent call last):
  File "/usr/local/lib/python3.7/dist-packages/django/core/handlers/exception.py", line 47, in inner
    response = get_response(request)
  File "/usr/local/lib/python3.7/dist-packages/django/core/handlers/base.py", line 181, in _get_response
    response = wrapped_callback(request, *callback_args, **callback_kwargs)
  File "/home/erik/Descargas/ProyectoSeg/pruebas/views.py", line 47, in verificar_scripts
    salida = subprocess.Popen(comando, stdout=subprocess.PIPE, stderr=subprocess.PIPE)
  File "/usr/lib/python3.7/subprocess.py", line 775, in __init__
    restore_signals, start_new_session)
  File "/usr/lib/python3.7/subprocess.py", line 1522, in _execute_child
    raise child_exception_type(errno_num, err_msg, err_filename)
OSError: [Errno 8] Exec format error: '/home/erik/Descargas/ProyectoSeg/archivos/Practicas/hola2.sh'
30-May-22 04:36:18 - INFO - /home/erik/Descargas/ProyectoSeg/pruebas/views.py changed, reloading.
30-May-22 04:36:23 - ERROR - Internal Server Error: /verificar_scripts
Traceback (most recent call last):
  File "/usr/local/lib/python3.7/dist-packages/django/core/handlers/exception.py", line 47, in inner
    response = get_response(request)
  File "/usr/local/lib/python3.7/dist-packages/django/core/handlers/base.py", line 181, in _get_response
    response = wrapped_callback(request, *callback_args, **callback_kwargs)
  File "/home/erik/Descargas/ProyectoSeg/pruebas/views.py", line 47, in verificar_scripts
    salida = subprocess.Popen(comando, stdout=subprocess.PIPE, stderr=subprocess.PIPE)
  File "/usr/lib/python3.7/subprocess.py", line 775, in __init__
    restore_signals, start_new_session)
  File "/usr/lib/python3.7/subprocess.py", line 1522, in _execute_child
    raise child_exception_type(errno_num, err_msg, err_filename)
OSError: [Errno 8] Exec format error: '/home/erik/Descargas/ProyectoSeg/archivos/Practicas/hola2_5PS8OhU.sh'
30-May-22 04:38:37 - INFO - /home/erik/Descargas/ProyectoSeg/pruebas/views.py changed, reloading.
30-May-22 04:38:44 - ERROR - Internal Server Error: /verificar_scripts
Traceback (most recent call last):
  File "/usr/local/lib/python3.7/dist-packages/django/core/handlers/exception.py", line 47, in inner
    response = get_response(request)
  File "/usr/local/lib/python3.7/dist-packages/django/core/handlers/base.py", line 188, in _get_response
    self.check_response(response, callback)
  File "/usr/local/lib/python3.7/dist-packages/django/core/handlers/base.py", line 311, in check_response
    "instead." % name
ValueError: The view pruebas.views.verificar_scripts didn't return an HttpResponse object. It returned None instead.
30-May-22 04:39:08 - INFO - /home/erik/Descargas/ProyectoSeg/pruebas/views.py changed, reloading.
30-May-22 04:40:30 - INFO - /home/erik/Descargas/ProyectoSeg/pruebas/views.py changed, reloading.
30-May-22 04:40:53 - ERROR - Internal Server Error: /verificar_scripts
Traceback (most recent call last):
  File "/usr/local/lib/python3.7/dist-packages/django/core/handlers/exception.py", line 47, in inner
    response = get_response(request)
  File "/usr/local/lib/python3.7/dist-packages/django/core/handlers/base.py", line 181, in _get_response
    response = wrapped_callback(request, *callback_args, **callback_kwargs)
  File "/home/erik/Descargas/ProyectoSeg/pruebas/views.py", line 42, in verificar_scripts
    obj = models.ArchivosA.objects.get(pk=75)
  File "/usr/local/lib/python3.7/dist-packages/django/db/models/manager.py", line 85, in manager_method
    return getattr(self.get_queryset(), name)(*args, **kwargs)
  File "/usr/local/lib/python3.7/dist-packages/django/db/models/query.py", line 437, in get
    self.model._meta.object_name
modelo.models.ArchivosA.DoesNotExist: ArchivosA matching query does not exist.
30-May-22 04:41:11 - ERROR - Internal Server Error: /verificar_scripts
Traceback (most recent call last):
  File "/usr/local/lib/python3.7/dist-packages/django/core/handlers/exception.py", line 47, in inner
    response = get_response(request)
  File "/usr/local/lib/python3.7/dist-packages/django/core/handlers/base.py", line 181, in _get_response
    response = wrapped_callback(request, *callback_args, **callback_kwargs)
  File "/home/erik/Descargas/ProyectoSeg/pruebas/views.py", line 42, in verificar_scripts
    obj = models.ArchivosA.objects.get(pk=75)
  File "/usr/local/lib/python3.7/dist-packages/django/db/models/manager.py", line 85, in manager_method
    return getattr(self.get_queryset(), name)(*args, **kwargs)
  File "/usr/local/lib/python3.7/dist-packages/django/db/models/query.py", line 437, in get
    self.model._meta.object_name
modelo.models.ArchivosA.DoesNotExist: ArchivosA matching query does not exist.
30-May-22 04:41:49 - INFO - /home/erik/Descargas/ProyectoSeg/pruebas/views.py changed, reloading.
30-May-22 04:42:50 - INFO - /home/erik/Descargas/ProyectoSeg/pruebas/views.py changed, reloading.
30-May-22 04:44:05 - WARNING - Not Found: /
30-May-22 04:44:06 - WARNING - Not Found: /
30-May-22 04:44:14 - WARNING - Not Found: / verificar_scripts
30-May-22 04:44:14 - WARNING - Not Found: / verificar_scripts
30-May-22 04:45:54 - INFO - /home/erik/Descargas/ProyectoSeg/pruebas/views.py changed, reloading.
30-May-22 04:48:19 - INFO - /home/erik/Descargas/ProyectoSeg/pruebas/urls.py changed, reloading.
30-May-22 04:51:07 - INFO - /home/erik/Descargas/ProyectoSeg/pruebas/views.py changed, reloading.
30-May-22 04:51:32 - INFO - /home/erik/Descargas/ProyectoSeg/pruebas/urls.py changed, reloading.
30-May-22 04:51:45 - WARNING - Not Found: /
30-May-22 04:51:46 - WARNING - Not Found: /
30-May-22 04:51:46 - WARNING - Not Found: /
30-May-22 04:51:46 - WARNING - Not Found: /
30-May-22 04:51:46 - WARNING - Not Found: /
30-May-22 04:51:46 - WARNING - Not Found: /
30-May-22 04:51:47 - WARNING - Not Found: /
30-May-22 04:55:41 - WARNING - Not Found: /
30-May-22 04:55:42 - WARNING - Not Found: /
30-May-22 04:55:42 - WARNING - Not Found: /
30-May-22 05:05:16 - INFO - /home/erik/Descargas/ProyectoSeg/modelo/models.py changed, reloading.
30-May-22 05:05:23 - INFO - /home/erik/Descargas/ProyectoSeg/pruebas/views.py changed, reloading.
30-May-22 05:05:29 - INFO - /home/erik/Descargas/ProyectoSeg/pruebas/urls.py changed, reloading.
30-May-22 05:08:44 - WARNING - Not Found: /Subir_Actividad
30-May-22 05:57:26 - INFO - /home/erik/Descargas/ProyectoSeg/pruebas/views.py changed, reloading.
30-May-22 05:57:33 - WARNING - Not Found: /Subir_Actividad
30-May-22 05:57:53 - INFO - /home/erik/Descargas/ProyectoSeg/pruebas/views.py changed, reloading.
30-May-22 05:58:05 - WARNING - Not Found: /Subir_Actividad
30-May-22 05:58:30 - ERROR - Internal Server Error: /Subir_Ejercicio_Profesor
Traceback (most recent call last):
  File "/usr/local/lib/python3.7/dist-packages/django/core/handlers/exception.py", line 47, in inner
    response = get_response(request)
  File "/usr/local/lib/python3.7/dist-packages/django/core/handlers/base.py", line 181, in _get_response
    response = wrapped_callback(request, *callback_args, **callback_kwargs)
  File "/home/erik/Descargas/ProyectoSeg/pruebas/views.py", line 26, in SubirEjerciciosProfesor
    archivo = models.ArchivosA(upload=file, usuario=alumnosScript)
NameError: name 'alumnosScript' is not defined
30-May-22 05:59:10 - INFO - /home/erik/Descargas/ProyectoSeg/pruebas/views.py changed, reloading.
30-May-22 05:59:14 - ERROR - Internal Server Error: /Subir_Ejercicio_Profesor
Traceback (most recent call last):
  File "/usr/local/lib/python3.7/dist-packages/django/db/backends/utils.py", line 84, in _execute
    return self.cursor.execute(sql, params)
psycopg2.errors.NotNullViolation: el valor null para la columna «usuario_id» viola la restricción not null
DETAIL:  La fila que falla contiene (90, , null).


The above exception was the direct cause of the following exception:

Traceback (most recent call last):
  File "/usr/local/lib/python3.7/dist-packages/django/core/handlers/exception.py", line 47, in inner
    response = get_response(request)
  File "/usr/local/lib/python3.7/dist-packages/django/core/handlers/base.py", line 181, in _get_response
    response = wrapped_callback(request, *callback_args, **callback_kwargs)
  File "/home/erik/Descargas/ProyectoSeg/pruebas/views.py", line 27, in SubirEjerciciosProfesor
    archivo.save()
  File "/usr/local/lib/python3.7/dist-packages/django/db/models/base.py", line 740, in save
    force_update=force_update, update_fields=update_fields)
  File "/usr/local/lib/python3.7/dist-packages/django/db/models/base.py", line 778, in save_base
    force_update, using, update_fields,
  File "/usr/local/lib/python3.7/dist-packages/django/db/models/base.py", line 881, in _save_table
    results = self._do_insert(cls._base_manager, using, fields, returning_fields, raw)
  File "/usr/local/lib/python3.7/dist-packages/django/db/models/base.py", line 921, in _do_insert
    using=using, raw=raw,
  File "/usr/local/lib/python3.7/dist-packages/django/db/models/manager.py", line 85, in manager_method
    return getattr(self.get_queryset(), name)(*args, **kwargs)
  File "/usr/local/lib/python3.7/dist-packages/django/db/models/query.py", line 1270, in _insert
    return query.get_compiler(using=using).execute_sql(returning_fields)
  File "/usr/local/lib/python3.7/dist-packages/django/db/models/sql/compiler.py", line 1416, in execute_sql
    cursor.execute(sql, params)
  File "/usr/local/lib/python3.7/dist-packages/django/db/backends/utils.py", line 98, in execute
    return super().execute(sql, params)
  File "/usr/local/lib/python3.7/dist-packages/django/db/backends/utils.py", line 66, in execute
    return self._execute_with_wrappers(sql, params, many=False, executor=self._execute)
  File "/usr/local/lib/python3.7/dist-packages/django/db/backends/utils.py", line 75, in _execute_with_wrappers
    return executor(sql, params, many, context)
  File "/usr/local/lib/python3.7/dist-packages/django/db/backends/utils.py", line 84, in _execute
    return self.cursor.execute(sql, params)
  File "/usr/local/lib/python3.7/dist-packages/django/db/utils.py", line 90, in __exit__
    raise dj_exc_value.with_traceback(traceback) from exc_value
  File "/usr/local/lib/python3.7/dist-packages/django/db/backends/utils.py", line 84, in _execute
    return self.cursor.execute(sql, params)
django.db.utils.IntegrityError: el valor null para la columna «usuario_id» viola la restricción not null
DETAIL:  La fila que falla contiene (90, , null).

30-May-22 06:05:30 - ERROR - Internal Server Error: /Subir_Ejercicio_Profesor
Traceback (most recent call last):
  File "/usr/local/lib/python3.7/dist-packages/django/db/backends/utils.py", line 84, in _execute
    return self.cursor.execute(sql, params)
psycopg2.errors.NotNullViolation: el valor null para la columna «usuario_id» viola la restricción not null
DETAIL:  La fila que falla contiene (91, , null).


The above exception was the direct cause of the following exception:

Traceback (most recent call last):
  File "/usr/local/lib/python3.7/dist-packages/django/core/handlers/exception.py", line 47, in inner
    response = get_response(request)
  File "/usr/local/lib/python3.7/dist-packages/django/core/handlers/base.py", line 181, in _get_response
    response = wrapped_callback(request, *callback_args, **callback_kwargs)
  File "/home/erik/Descargas/ProyectoSeg/pruebas/views.py", line 27, in SubirEjerciciosProfesor
    archivo.save()
  File "/usr/local/lib/python3.7/dist-packages/django/db/models/base.py", line 740, in save
    force_update=force_update, update_fields=update_fields)
  File "/usr/local/lib/python3.7/dist-packages/django/db/models/base.py", line 778, in save_base
    force_update, using, update_fields,
  File "/usr/local/lib/python3.7/dist-packages/django/db/models/base.py", line 881, in _save_table
    results = self._do_insert(cls._base_manager, using, fields, returning_fields, raw)
  File "/usr/local/lib/python3.7/dist-packages/django/db/models/base.py", line 921, in _do_insert
    using=using, raw=raw,
  File "/usr/local/lib/python3.7/dist-packages/django/db/models/manager.py", line 85, in manager_method
    return getattr(self.get_queryset(), name)(*args, **kwargs)
  File "/usr/local/lib/python3.7/dist-packages/django/db/models/query.py", line 1270, in _insert
    return query.get_compiler(using=using).execute_sql(returning_fields)
  File "/usr/local/lib/python3.7/dist-packages/django/db/models/sql/compiler.py", line 1416, in execute_sql
    cursor.execute(sql, params)
  File "/usr/local/lib/python3.7/dist-packages/django/db/backends/utils.py", line 98, in execute
    return super().execute(sql, params)
  File "/usr/local/lib/python3.7/dist-packages/django/db/backends/utils.py", line 66, in execute
    return self._execute_with_wrappers(sql, params, many=False, executor=self._execute)
  File "/usr/local/lib/python3.7/dist-packages/django/db/backends/utils.py", line 75, in _execute_with_wrappers
    return executor(sql, params, many, context)
  File "/usr/local/lib/python3.7/dist-packages/django/db/backends/utils.py", line 84, in _execute
    return self.cursor.execute(sql, params)
  File "/usr/local/lib/python3.7/dist-packages/django/db/utils.py", line 90, in __exit__
    raise dj_exc_value.with_traceback(traceback) from exc_value
  File "/usr/local/lib/python3.7/dist-packages/django/db/backends/utils.py", line 84, in _execute
    return self.cursor.execute(sql, params)
django.db.utils.IntegrityError: el valor null para la columna «usuario_id» viola la restricción not null
DETAIL:  La fila que falla contiene (91, , null).

30-May-22 06:07:35 - INFO - /home/erik/Descargas/ProyectoSeg/pruebas/views.py changed, reloading.
30-May-22 06:20:37 - INFO - /home/erik/Descargas/ProyectoSeg/pruebas/views.py changed, reloading.
30-May-22 21:00:38 - WARNING - Not Found: /
30-May-22 21:08:52 - WARNING - Not Found: / Subir_Ejercicio_Profesor
30-May-22 21:36:11 - INFO - /home/erik/Descargas/ProyectoSeg/pruebas/views.py changed, reloading.
30-May-22 21:37:03 - WARNING - Not Found: /
30-May-22 21:38:36 - INFO - /home/erik/Descargas/ProyectoSeg/pruebas/views.py changed, reloading.
30-May-22 21:39:29 - INFO - /home/erik/Descargas/ProyectoSeg/pruebas/views.py changed, reloading.
30-May-22 21:44:34 - INFO - /home/erik/Descargas/ProyectoSeg/modelo/models.py changed, reloading.
31-May-22 01:05:43 - WARNING - Not Found: /
31-May-22 01:05:43 - WARNING - Not Found: /
31-May-22 23:44:41 - WARNING - Not Found: /
31-May-22 23:44:42 - WARNING - Not Found: /
31-May-22 23:44:42 - WARNING - Not Found: /
31-May-22 23:44:42 - WARNING - Not Found: /
31-May-22 23:45:36 - WARNING - Not Found: /
05-Jun-22 20:57:31 - WARNING - Not Found: /
05-Jun-22 20:57:31 - WARNING - Not Found: /favicon.ico
05-Jun-22 20:58:14 - WARNING - Not Found: /
05-Jun-22 20:58:15 - WARNING - Not Found: /
05-Jun-22 20:58:15 - WARNING - Not Found: /
05-Jun-22 20:58:23 - WARNING - Not Found: / Subir_Ejercicio_Profesor
05-Jun-22 20:58:24 - WARNING - Not Found: / Subir_Ejercicio_Profesor
05-Jun-22 20:58:24 - WARNING - Not Found: / Subir_Ejercicio_Profesor
06-Jun-22 01:06:27 - WARNING - Not Found: /
06-Jun-22 02:04:51 - INFO - /home/erik/Descargas/ProyectoSeg/modelo/models.py changed, reloading.
06-Jun-22 02:04:56 - INFO - /home/erik/Descargas/ProyectoSeg/pruebas/views.py changed, reloading.
06-Jun-22 02:15:48 - ERROR - Internal Server Error: /Registro_Alumnos
Traceback (most recent call last):
  File "/usr/local/lib/python3.7/dist-packages/django/core/handlers/exception.py", line 47, in inner
    response = get_response(request)
  File "/usr/local/lib/python3.7/dist-packages/django/core/handlers/base.py", line 181, in _get_response
    response = wrapped_callback(request, *callback_args, **callback_kwargs)
  File "/home/erik/Descargas/ProyectoSeg/pruebas/views.py", line 154, in Registro_Alumnos
    profesor =  models.Profesor(NombreProfesor=nombre, Matricula=matricula, Contraseña=contrasena, Tipocuenta=Tipocuenta, Chat_id=chat_id, Token_tel=telegram)
NameError: name 'telegram' is not defined
06-Jun-22 02:53:58 - INFO - /home/erik/Descargas/ProyectoSeg/pruebas/views.py changed, reloading.
06-Jun-22 02:54:21 - ERROR - Internal Server Error: /Registro_Alumnos
Traceback (most recent call last):
  File "/usr/local/lib/python3.7/dist-packages/django/core/handlers/exception.py", line 47, in inner
    response = get_response(request)
  File "/usr/local/lib/python3.7/dist-packages/django/core/handlers/base.py", line 181, in _get_response
    response = wrapped_callback(request, *callback_args, **callback_kwargs)
  File "/home/erik/Descargas/ProyectoSeg/pruebas/views.py", line 154, in Registro_Alumnos
    profesor =  models.Profesor(NombreProfesor=nombre, Matricula=matricula, Contraseña=contrasena, Tipocuenta=Tipocuenta, Chat_id=chat_id, Token_tel=telegram)
NameError: name 'telegram' is not defined
06-Jun-22 02:58:08 - INFO - /home/erik/Descargas/ProyectoSeg/pruebas/views.py changed, reloading.
06-Jun-22 02:59:02 - ERROR - Internal Server Error: /Registro_Alumnos
Traceback (most recent call last):
  File "/usr/local/lib/python3.7/dist-packages/django/core/handlers/exception.py", line 47, in inner
    response = get_response(request)
  File "/usr/local/lib/python3.7/dist-packages/django/core/handlers/base.py", line 181, in _get_response
    response = wrapped_callback(request, *callback_args, **callback_kwargs)
  File "/home/erik/Descargas/ProyectoSeg/pruebas/views.py", line 154, in Registro_Alumnos
    profesor =  models.Profesor(NombreProfesor=nombre, Matricula=matricula, Contraseña=contrasena, Tipocuenta=Tipocuenta, Chat_id=chat_id, Token_tel=toke_telegram)
NameError: name 'toke_telegram' is not defined
06-Jun-22 02:59:34 - INFO - /home/erik/Descargas/ProyectoSeg/pruebas/views.py changed, reloading.
06-Jun-22 02:59:49 - ERROR - Internal Server Error: /Registro_Alumnos
Traceback (most recent call last):
  File "/usr/local/lib/python3.7/dist-packages/django/core/handlers/exception.py", line 47, in inner
    response = get_response(request)
  File "/usr/local/lib/python3.7/dist-packages/django/core/handlers/base.py", line 181, in _get_response
    response = wrapped_callback(request, *callback_args, **callback_kwargs)
  File "/home/erik/Descargas/ProyectoSeg/pruebas/views.py", line 155, in Registro_Alumnos
    errores = recoleccion_de_errores_del_registro(alumno)
UnboundLocalError: local variable 'alumno' referenced before assignment
06-Jun-22 03:00:44 - INFO - /home/erik/Descargas/ProyectoSeg/pruebas/views.py changed, reloading.
06-Jun-22 03:01:04 - ERROR - Internal Server Error: /Registro_Alumnos
Traceback (most recent call last):
  File "/usr/local/lib/python3.7/dist-packages/django/core/handlers/exception.py", line 47, in inner
    response = get_response(request)
  File "/usr/local/lib/python3.7/dist-packages/django/core/handlers/base.py", line 181, in _get_response
    response = wrapped_callback(request, *callback_args, **callback_kwargs)
  File "/home/erik/Descargas/ProyectoSeg/pruebas/views.py", line 155, in Registro_Alumnos
    errores = recoleccion_de_errores_del_registro(profesor)
  File "/home/erik/Descargas/ProyectoSeg/pruebas/views.py", line 191, in recoleccion_de_errores_del_registro
    if alumno.NombreAlumno == '':
AttributeError: 'Profesor' object has no attribute 'NombreAlumno'
06-Jun-22 03:07:49 - INFO - /home/erik/Descargas/ProyectoSeg/pruebas/views.py changed, reloading.
06-Jun-22 03:08:00 - ERROR - Internal Server Error: /Registro_Alumnos
Traceback (most recent call last):
  File "/usr/local/lib/python3.7/dist-packages/django/core/handlers/exception.py", line 47, in inner
    response = get_response(request)
  File "/usr/local/lib/python3.7/dist-packages/django/core/handlers/base.py", line 181, in _get_response
    response = wrapped_callback(request, *callback_args, **callback_kwargs)
  File "/home/erik/Descargas/ProyectoSeg/pruebas/views.py", line 155, in Registro_Alumnos
    errores = recoleccion_de_errores_del_registro_profesor(profesor)
  File "/home/erik/Descargas/ProyectoSeg/pruebas/views.py", line 224, in recoleccion_de_errores_del_registro_profesor
    if profesor.NombreAlumno == '':
AttributeError: 'Profesor' object has no attribute 'NombreAlumno'
06-Jun-22 03:08:37 - INFO - /home/erik/Descargas/ProyectoSeg/pruebas/views.py changed, reloading.
06-Jun-22 03:24:59 - INFO - /home/erik/Descargas/ProyectoSeg/modelo/models.py changed, reloading.
06-Jun-22 03:25:21 - ERROR - Internal Server Error: /Subir_Ejercicio_Profesor
Traceback (most recent call last):
  File "/usr/local/lib/python3.7/dist-packages/django/db/backends/utils.py", line 84, in _execute
    return self.cursor.execute(sql, params)
psycopg2.errors.UndefinedColumn: no existe la columna «usuario_id» en la relación «modelo_archivosp»
LINE 1: ... "modelo_archivosp" ("NombreActividad", "upload", "usuario_i...
                                                             ^


The above exception was the direct cause of the following exception:

Traceback (most recent call last):
  File "/usr/local/lib/python3.7/dist-packages/django/core/handlers/exception.py", line 47, in inner
    response = get_response(request)
  File "/usr/local/lib/python3.7/dist-packages/django/core/handlers/base.py", line 181, in _get_response
    response = wrapped_callback(request, *callback_args, **callback_kwargs)
  File "/home/erik/Descargas/ProyectoSeg/pruebas/views.py", line 29, in SubirEjerciciosProfesor
    archivo.save()
  File "/usr/local/lib/python3.7/dist-packages/django/db/models/base.py", line 740, in save
    force_update=force_update, update_fields=update_fields)
  File "/usr/local/lib/python3.7/dist-packages/django/db/models/base.py", line 778, in save_base
    force_update, using, update_fields,
  File "/usr/local/lib/python3.7/dist-packages/django/db/models/base.py", line 881, in _save_table
    results = self._do_insert(cls._base_manager, using, fields, returning_fields, raw)
  File "/usr/local/lib/python3.7/dist-packages/django/db/models/base.py", line 921, in _do_insert
    using=using, raw=raw,
  File "/usr/local/lib/python3.7/dist-packages/django/db/models/manager.py", line 85, in manager_method
    return getattr(self.get_queryset(), name)(*args, **kwargs)
  File "/usr/local/lib/python3.7/dist-packages/django/db/models/query.py", line 1270, in _insert
    return query.get_compiler(using=using).execute_sql(returning_fields)
  File "/usr/local/lib/python3.7/dist-packages/django/db/models/sql/compiler.py", line 1416, in execute_sql
    cursor.execute(sql, params)
  File "/usr/local/lib/python3.7/dist-packages/django/db/backends/utils.py", line 98, in execute
    return super().execute(sql, params)
  File "/usr/local/lib/python3.7/dist-packages/django/db/backends/utils.py", line 66, in execute
    return self._execute_with_wrappers(sql, params, many=False, executor=self._execute)
  File "/usr/local/lib/python3.7/dist-packages/django/db/backends/utils.py", line 75, in _execute_with_wrappers
    return executor(sql, params, many, context)
  File "/usr/local/lib/python3.7/dist-packages/django/db/backends/utils.py", line 84, in _execute
    return self.cursor.execute(sql, params)
  File "/usr/local/lib/python3.7/dist-packages/django/db/utils.py", line 90, in __exit__
    raise dj_exc_value.with_traceback(traceback) from exc_value
  File "/usr/local/lib/python3.7/dist-packages/django/db/backends/utils.py", line 84, in _execute
    return self.cursor.execute(sql, params)
django.db.utils.ProgrammingError: no existe la columna «usuario_id» en la relación «modelo_archivosp»
LINE 1: ... "modelo_archivosp" ("NombreActividad", "upload", "usuario_i...
                                                             ^

06-Jun-22 03:25:30 - ERROR - Internal Server Error: /Subir_Ejercicio_Profesor
Traceback (most recent call last):
  File "/usr/local/lib/python3.7/dist-packages/django/db/backends/utils.py", line 84, in _execute
    return self.cursor.execute(sql, params)
psycopg2.errors.UndefinedColumn: no existe la columna «usuario_id» en la relación «modelo_archivosp»
LINE 1: ... "modelo_archivosp" ("NombreActividad", "upload", "usuario_i...
                                                             ^


The above exception was the direct cause of the following exception:

Traceback (most recent call last):
  File "/usr/local/lib/python3.7/dist-packages/django/core/handlers/exception.py", line 47, in inner
    response = get_response(request)
  File "/usr/local/lib/python3.7/dist-packages/django/core/handlers/base.py", line 181, in _get_response
    response = wrapped_callback(request, *callback_args, **callback_kwargs)
  File "/home/erik/Descargas/ProyectoSeg/pruebas/views.py", line 29, in SubirEjerciciosProfesor
    archivo.save()
  File "/usr/local/lib/python3.7/dist-packages/django/db/models/base.py", line 740, in save
    force_update=force_update, update_fields=update_fields)
  File "/usr/local/lib/python3.7/dist-packages/django/db/models/base.py", line 778, in save_base
    force_update, using, update_fields,
  File "/usr/local/lib/python3.7/dist-packages/django/db/models/base.py", line 881, in _save_table
    results = self._do_insert(cls._base_manager, using, fields, returning_fields, raw)
  File "/usr/local/lib/python3.7/dist-packages/django/db/models/base.py", line 921, in _do_insert
    using=using, raw=raw,
  File "/usr/local/lib/python3.7/dist-packages/django/db/models/manager.py", line 85, in manager_method
    return getattr(self.get_queryset(), name)(*args, **kwargs)
  File "/usr/local/lib/python3.7/dist-packages/django/db/models/query.py", line 1270, in _insert
    return query.get_compiler(using=using).execute_sql(returning_fields)
  File "/usr/local/lib/python3.7/dist-packages/django/db/models/sql/compiler.py", line 1416, in execute_sql
    cursor.execute(sql, params)
  File "/usr/local/lib/python3.7/dist-packages/django/db/backends/utils.py", line 98, in execute
    return super().execute(sql, params)
  File "/usr/local/lib/python3.7/dist-packages/django/db/backends/utils.py", line 66, in execute
    return self._execute_with_wrappers(sql, params, many=False, executor=self._execute)
  File "/usr/local/lib/python3.7/dist-packages/django/db/backends/utils.py", line 75, in _execute_with_wrappers
    return executor(sql, params, many, context)
  File "/usr/local/lib/python3.7/dist-packages/django/db/backends/utils.py", line 84, in _execute
    return self.cursor.execute(sql, params)
  File "/usr/local/lib/python3.7/dist-packages/django/db/utils.py", line 90, in __exit__
    raise dj_exc_value.with_traceback(traceback) from exc_value
  File "/usr/local/lib/python3.7/dist-packages/django/db/backends/utils.py", line 84, in _execute
    return self.cursor.execute(sql, params)
django.db.utils.ProgrammingError: no existe la columna «usuario_id» en la relación «modelo_archivosp»
LINE 1: ... "modelo_archivosp" ("NombreActividad", "upload", "usuario_i...
                                                             ^

06-Jun-22 03:27:39 - ERROR - Internal Server Error: /Registro_Alumnos
Traceback (most recent call last):
  File "/usr/local/lib/python3.7/dist-packages/django/core/handlers/exception.py", line 47, in inner
    response = get_response(request)
  File "/usr/local/lib/python3.7/dist-packages/django/core/handlers/base.py", line 181, in _get_response
    response = wrapped_callback(request, *callback_args, **callback_kwargs)
  File "/home/erik/Descargas/ProyectoSeg/pruebas/views.py", line 170, in Registro_Alumnos
    contexto = {'errores':errores, 'alumno':alumno}
UnboundLocalError: local variable 'alumno' referenced before assignment
06-Jun-22 03:28:41 - ERROR - Internal Server Error: /Registro_Alumnos
Traceback (most recent call last):
  File "/usr/local/lib/python3.7/dist-packages/django/core/handlers/exception.py", line 47, in inner
    response = get_response(request)
  File "/usr/local/lib/python3.7/dist-packages/django/core/handlers/base.py", line 181, in _get_response
    response = wrapped_callback(request, *callback_args, **callback_kwargs)
  File "/home/erik/Descargas/ProyectoSeg/pruebas/views.py", line 170, in Registro_Alumnos
    contexto = {'errores':errores, 'alumno':alumno}
UnboundLocalError: local variable 'alumno' referenced before assignment
06-Jun-22 03:31:15 - INFO - /home/erik/Descargas/ProyectoSeg/pruebas/views.py changed, reloading.
06-Jun-22 03:50:12 - INFO - /home/erik/Descargas/ProyectoSeg/pruebas/views.py changed, reloading.
06-Jun-22 03:50:21 - ERROR - Internal Server Error: /Registro_Alumnos
Traceback (most recent call last):
  File "/usr/local/lib/python3.7/dist-packages/django/core/handlers/exception.py", line 47, in inner
    response = get_response(request)
  File "/usr/local/lib/python3.7/dist-packages/django/core/handlers/base.py", line 181, in _get_response
    response = wrapped_callback(request, *callback_args, **callback_kwargs)
  File "/home/erik/Descargas/ProyectoSeg/pruebas/views.py", line 156, in Registro_Alumnos
    errores = recoleccion_de_errores_del_registro(alumno)
UnboundLocalError: local variable 'alumno' referenced before assignment
06-Jun-22 04:03:44 - ERROR - Internal Server Error: /Registro_Alumnos
Traceback (most recent call last):
  File "/usr/local/lib/python3.7/dist-packages/django/core/handlers/exception.py", line 47, in inner
    response = get_response(request)
  File "/usr/local/lib/python3.7/dist-packages/django/core/handlers/base.py", line 181, in _get_response
    response = wrapped_callback(request, *callback_args, **callback_kwargs)
  File "/home/erik/Descargas/ProyectoSeg/pruebas/views.py", line 156, in Registro_Alumnos
    errores = recoleccion_de_errores_del_registro(alumno)
UnboundLocalError: local variable 'alumno' referenced before assignment
06-Jun-22 04:04:43 - ERROR - Internal Server Error: /Registro_Alumnos
Traceback (most recent call last):
  File "/usr/local/lib/python3.7/dist-packages/django/core/handlers/exception.py", line 47, in inner
    response = get_response(request)
  File "/usr/local/lib/python3.7/dist-packages/django/core/handlers/base.py", line 181, in _get_response
    response = wrapped_callback(request, *callback_args, **callback_kwargs)
  File "/home/erik/Descargas/ProyectoSeg/pruebas/views.py", line 156, in Registro_Alumnos
    errores = recoleccion_de_errores_del_registro(alumno)
UnboundLocalError: local variable 'alumno' referenced before assignment
06-Jun-22 04:06:36 - ERROR - Internal Server Error: /Registro_Alumnos
Traceback (most recent call last):
  File "/usr/local/lib/python3.7/dist-packages/django/core/handlers/exception.py", line 47, in inner
    response = get_response(request)
  File "/usr/local/lib/python3.7/dist-packages/django/core/handlers/base.py", line 181, in _get_response
    response = wrapped_callback(request, *callback_args, **callback_kwargs)
  File "/home/erik/Descargas/ProyectoSeg/pruebas/views.py", line 156, in Registro_Alumnos
    errores = recoleccion_de_errores_del_registro(alumno)
UnboundLocalError: local variable 'alumno' referenced before assignment
06-Jun-22 04:09:33 - INFO - /home/erik/Descargas/ProyectoSeg/pruebas/views.py changed, reloading.
06-Jun-22 04:10:54 - INFO - /home/erik/Descargas/ProyectoSeg/pruebas/views.py changed, reloading.
06-Jun-22 04:11:16 - INFO - /home/erik/Descargas/ProyectoSeg/pruebas/views.py changed, reloading.
06-Jun-22 04:11:33 - ERROR - Internal Server Error: /Registro_Alumnos
Traceback (most recent call last):
  File "/usr/local/lib/python3.7/dist-packages/django/core/handlers/exception.py", line 47, in inner
    response = get_response(request)
  File "/usr/local/lib/python3.7/dist-packages/django/core/handlers/base.py", line 181, in _get_response
    response = wrapped_callback(request, *callback_args, **callback_kwargs)
  File "/home/erik/Descargas/ProyectoSeg/pruebas/views.py", line 155, in Registro_Alumnos
    if not errores:
UnboundLocalError: local variable 'errores' referenced before assignment
06-Jun-22 04:15:58 - ERROR - Internal Server Error: /Registro_Alumnos
Traceback (most recent call last):
  File "/usr/local/lib/python3.7/dist-packages/django/core/handlers/exception.py", line 47, in inner
    response = get_response(request)
  File "/usr/local/lib/python3.7/dist-packages/django/core/handlers/base.py", line 181, in _get_response
    response = wrapped_callback(request, *callback_args, **callback_kwargs)
  File "/home/erik/Descargas/ProyectoSeg/pruebas/views.py", line 155, in Registro_Alumnos
    if not errores:
UnboundLocalError: local variable 'errores' referenced before assignment
06-Jun-22 04:21:01 - ERROR - Internal Server Error: /Registro_Alumnos
Traceback (most recent call last):
  File "/usr/local/lib/python3.7/dist-packages/django/core/handlers/exception.py", line 47, in inner
    response = get_response(request)
  File "/usr/local/lib/python3.7/dist-packages/django/core/handlers/base.py", line 181, in _get_response
    response = wrapped_callback(request, *callback_args, **callback_kwargs)
  File "/home/erik/Descargas/ProyectoSeg/pruebas/views.py", line 169, in Registro_Alumnos
    contexto = {'errores':errores, 'alumno':alumno}
UnboundLocalError: local variable 'alumno' referenced before assignment
06-Jun-22 04:21:24 - ERROR - Internal Server Error: /Registro_Alumnos
Traceback (most recent call last):
  File "/usr/local/lib/python3.7/dist-packages/django/core/handlers/exception.py", line 47, in inner
    response = get_response(request)
  File "/usr/local/lib/python3.7/dist-packages/django/core/handlers/base.py", line 181, in _get_response
    response = wrapped_callback(request, *callback_args, **callback_kwargs)
  File "/home/erik/Descargas/ProyectoSeg/pruebas/views.py", line 169, in Registro_Alumnos
    contexto = {'errores':errores, 'alumno':alumno}
UnboundLocalError: local variable 'alumno' referenced before assignment
06-Jun-22 04:24:32 - INFO - /home/erik/Descargas/ProyectoSeg/pruebas/views.py changed, reloading.
06-Jun-22 04:30:14 - ERROR - Internal Server Error: /Subir_Ejercicio_Profesor
Traceback (most recent call last):
  File "/usr/local/lib/python3.7/dist-packages/django/db/backends/utils.py", line 84, in _execute
    return self.cursor.execute(sql, params)
psycopg2.errors.UndefinedColumn: no existe la columna «usuario_id» en la relación «modelo_archivosp»
LINE 1: ... "modelo_archivosp" ("NombreActividad", "upload", "usuario_i...
                                                             ^


The above exception was the direct cause of the following exception:

Traceback (most recent call last):
  File "/usr/local/lib/python3.7/dist-packages/django/core/handlers/exception.py", line 47, in inner
    response = get_response(request)
  File "/usr/local/lib/python3.7/dist-packages/django/core/handlers/base.py", line 181, in _get_response
    response = wrapped_callback(request, *callback_args, **callback_kwargs)
  File "/home/erik/Descargas/ProyectoSeg/pruebas/views.py", line 29, in SubirEjerciciosProfesor
    archivo.save()
  File "/usr/local/lib/python3.7/dist-packages/django/db/models/base.py", line 740, in save
    force_update=force_update, update_fields=update_fields)
  File "/usr/local/lib/python3.7/dist-packages/django/db/models/base.py", line 778, in save_base
    force_update, using, update_fields,
  File "/usr/local/lib/python3.7/dist-packages/django/db/models/base.py", line 881, in _save_table
    results = self._do_insert(cls._base_manager, using, fields, returning_fields, raw)
  File "/usr/local/lib/python3.7/dist-packages/django/db/models/base.py", line 921, in _do_insert
    using=using, raw=raw,
  File "/usr/local/lib/python3.7/dist-packages/django/db/models/manager.py", line 85, in manager_method
    return getattr(self.get_queryset(), name)(*args, **kwargs)
  File "/usr/local/lib/python3.7/dist-packages/django/db/models/query.py", line 1270, in _insert
    return query.get_compiler(using=using).execute_sql(returning_fields)
  File "/usr/local/lib/python3.7/dist-packages/django/db/models/sql/compiler.py", line 1416, in execute_sql
    cursor.execute(sql, params)
  File "/usr/local/lib/python3.7/dist-packages/django/db/backends/utils.py", line 98, in execute
    return super().execute(sql, params)
  File "/usr/local/lib/python3.7/dist-packages/django/db/backends/utils.py", line 66, in execute
    return self._execute_with_wrappers(sql, params, many=False, executor=self._execute)
  File "/usr/local/lib/python3.7/dist-packages/django/db/backends/utils.py", line 75, in _execute_with_wrappers
    return executor(sql, params, many, context)
  File "/usr/local/lib/python3.7/dist-packages/django/db/backends/utils.py", line 84, in _execute
    return self.cursor.execute(sql, params)
  File "/usr/local/lib/python3.7/dist-packages/django/db/utils.py", line 90, in __exit__
    raise dj_exc_value.with_traceback(traceback) from exc_value
  File "/usr/local/lib/python3.7/dist-packages/django/db/backends/utils.py", line 84, in _execute
    return self.cursor.execute(sql, params)
django.db.utils.ProgrammingError: no existe la columna «usuario_id» en la relación «modelo_archivosp»
LINE 1: ... "modelo_archivosp" ("NombreActividad", "upload", "usuario_i...
                                                             ^

06-Jun-22 04:31:45 - INFO - /home/erik/Descargas/ProyectoSeg/pruebas/views.py changed, reloading.
06-Jun-22 04:33:19 - ERROR - Internal Server Error: /Subir_Ejercicio_Profesor
Traceback (most recent call last):
  File "/usr/local/lib/python3.7/dist-packages/django/db/backends/utils.py", line 84, in _execute
    return self.cursor.execute(sql, params)
psycopg2.errors.UndefinedColumn: no existe la columna «usuario_id» en la relación «modelo_archivosp»
LINE 1: ... "modelo_archivosp" ("NombreActividad", "upload", "usuario_i...
                                                             ^


The above exception was the direct cause of the following exception:

Traceback (most recent call last):
  File "/usr/local/lib/python3.7/dist-packages/django/core/handlers/exception.py", line 47, in inner
    response = get_response(request)
  File "/usr/local/lib/python3.7/dist-packages/django/core/handlers/base.py", line 181, in _get_response
    response = wrapped_callback(request, *callback_args, **callback_kwargs)
  File "/home/erik/Descargas/ProyectoSeg/pruebas/views.py", line 29, in SubirEjerciciosProfesor
    archivo.save()
  File "/usr/local/lib/python3.7/dist-packages/django/db/models/base.py", line 740, in save
    force_update=force_update, update_fields=update_fields)
  File "/usr/local/lib/python3.7/dist-packages/django/db/models/base.py", line 778, in save_base
    force_update, using, update_fields,
  File "/usr/local/lib/python3.7/dist-packages/django/db/models/base.py", line 881, in _save_table
    results = self._do_insert(cls._base_manager, using, fields, returning_fields, raw)
  File "/usr/local/lib/python3.7/dist-packages/django/db/models/base.py", line 921, in _do_insert
    using=using, raw=raw,
  File "/usr/local/lib/python3.7/dist-packages/django/db/models/manager.py", line 85, in manager_method
    return getattr(self.get_queryset(), name)(*args, **kwargs)
  File "/usr/local/lib/python3.7/dist-packages/django/db/models/query.py", line 1270, in _insert
    return query.get_compiler(using=using).execute_sql(returning_fields)
  File "/usr/local/lib/python3.7/dist-packages/django/db/models/sql/compiler.py", line 1416, in execute_sql
    cursor.execute(sql, params)
  File "/usr/local/lib/python3.7/dist-packages/django/db/backends/utils.py", line 98, in execute
    return super().execute(sql, params)
  File "/usr/local/lib/python3.7/dist-packages/django/db/backends/utils.py", line 66, in execute
    return self._execute_with_wrappers(sql, params, many=False, executor=self._execute)
  File "/usr/local/lib/python3.7/dist-packages/django/db/backends/utils.py", line 75, in _execute_with_wrappers
    return executor(sql, params, many, context)
  File "/usr/local/lib/python3.7/dist-packages/django/db/backends/utils.py", line 84, in _execute
    return self.cursor.execute(sql, params)
  File "/usr/local/lib/python3.7/dist-packages/django/db/utils.py", line 90, in __exit__
    raise dj_exc_value.with_traceback(traceback) from exc_value
  File "/usr/local/lib/python3.7/dist-packages/django/db/backends/utils.py", line 84, in _execute
    return self.cursor.execute(sql, params)
django.db.utils.ProgrammingError: no existe la columna «usuario_id» en la relación «modelo_archivosp»
LINE 1: ... "modelo_archivosp" ("NombreActividad", "upload", "usuario_i...
                                                             ^

06-Jun-22 04:40:58 - WARNING - Not Found: /
06-Jun-22 04:40:59 - WARNING - Not Found: /
06-Jun-22 04:41:06 - ERROR - Internal Server Error: /Subir_Ejercicio_Profesor
Traceback (most recent call last):
  File "/usr/local/lib/python3.7/dist-packages/django/db/backends/utils.py", line 84, in _execute
    return self.cursor.execute(sql, params)
psycopg2.errors.UndefinedColumn: no existe la columna «usuario_id» en la relación «modelo_archivosp»
LINE 1: ... "modelo_archivosp" ("NombreActividad", "upload", "usuario_i...
                                                             ^


The above exception was the direct cause of the following exception:

Traceback (most recent call last):
  File "/usr/local/lib/python3.7/dist-packages/django/core/handlers/exception.py", line 47, in inner
    response = get_response(request)
  File "/usr/local/lib/python3.7/dist-packages/django/core/handlers/base.py", line 181, in _get_response
    response = wrapped_callback(request, *callback_args, **callback_kwargs)
  File "/home/erik/Descargas/ProyectoSeg/pruebas/views.py", line 29, in SubirEjerciciosProfesor
    archivo.save()
  File "/usr/local/lib/python3.7/dist-packages/django/db/models/base.py", line 740, in save
    force_update=force_update, update_fields=update_fields)
  File "/usr/local/lib/python3.7/dist-packages/django/db/models/base.py", line 778, in save_base
    force_update, using, update_fields,
  File "/usr/local/lib/python3.7/dist-packages/django/db/models/base.py", line 881, in _save_table
    results = self._do_insert(cls._base_manager, using, fields, returning_fields, raw)
  File "/usr/local/lib/python3.7/dist-packages/django/db/models/base.py", line 921, in _do_insert
    using=using, raw=raw,
  File "/usr/local/lib/python3.7/dist-packages/django/db/models/manager.py", line 85, in manager_method
    return getattr(self.get_queryset(), name)(*args, **kwargs)
  File "/usr/local/lib/python3.7/dist-packages/django/db/models/query.py", line 1270, in _insert
    return query.get_compiler(using=using).execute_sql(returning_fields)
  File "/usr/local/lib/python3.7/dist-packages/django/db/models/sql/compiler.py", line 1416, in execute_sql
    cursor.execute(sql, params)
  File "/usr/local/lib/python3.7/dist-packages/django/db/backends/utils.py", line 98, in execute
    return super().execute(sql, params)
  File "/usr/local/lib/python3.7/dist-packages/django/db/backends/utils.py", line 66, in execute
    return self._execute_with_wrappers(sql, params, many=False, executor=self._execute)
  File "/usr/local/lib/python3.7/dist-packages/django/db/backends/utils.py", line 75, in _execute_with_wrappers
    return executor(sql, params, many, context)
  File "/usr/local/lib/python3.7/dist-packages/django/db/backends/utils.py", line 84, in _execute
    return self.cursor.execute(sql, params)
  File "/usr/local/lib/python3.7/dist-packages/django/db/utils.py", line 90, in __exit__
    raise dj_exc_value.with_traceback(traceback) from exc_value
  File "/usr/local/lib/python3.7/dist-packages/django/db/backends/utils.py", line 84, in _execute
    return self.cursor.execute(sql, params)
django.db.utils.ProgrammingError: no existe la columna «usuario_id» en la relación «modelo_archivosp»
LINE 1: ... "modelo_archivosp" ("NombreActividad", "upload", "usuario_i...
                                                             ^

06-Jun-22 04:44:47 - ERROR - Internal Server Error: /Subir_Ejercicio_Profesor
Traceback (most recent call last):
  File "/usr/local/lib/python3.7/dist-packages/django/db/backends/utils.py", line 84, in _execute
    return self.cursor.execute(sql, params)
psycopg2.errors.UndefinedColumn: no existe la columna «usuario_id» en la relación «modelo_archivosp»
LINE 1: ... "modelo_archivosp" ("NombreActividad", "upload", "usuario_i...
                                                             ^


The above exception was the direct cause of the following exception:

Traceback (most recent call last):
  File "/usr/local/lib/python3.7/dist-packages/django/core/handlers/exception.py", line 47, in inner
    response = get_response(request)
  File "/usr/local/lib/python3.7/dist-packages/django/core/handlers/base.py", line 181, in _get_response
    response = wrapped_callback(request, *callback_args, **callback_kwargs)
  File "/home/erik/Descargas/ProyectoSeg/pruebas/views.py", line 29, in SubirEjerciciosProfesor
    archivo.save()
  File "/usr/local/lib/python3.7/dist-packages/django/db/models/base.py", line 740, in save
    force_update=force_update, update_fields=update_fields)
  File "/usr/local/lib/python3.7/dist-packages/django/db/models/base.py", line 778, in save_base
    force_update, using, update_fields,
  File "/usr/local/lib/python3.7/dist-packages/django/db/models/base.py", line 881, in _save_table
    results = self._do_insert(cls._base_manager, using, fields, returning_fields, raw)
  File "/usr/local/lib/python3.7/dist-packages/django/db/models/base.py", line 921, in _do_insert
    using=using, raw=raw,
  File "/usr/local/lib/python3.7/dist-packages/django/db/models/manager.py", line 85, in manager_method
    return getattr(self.get_queryset(), name)(*args, **kwargs)
  File "/usr/local/lib/python3.7/dist-packages/django/db/models/query.py", line 1270, in _insert
    return query.get_compiler(using=using).execute_sql(returning_fields)
  File "/usr/local/lib/python3.7/dist-packages/django/db/models/sql/compiler.py", line 1416, in execute_sql
    cursor.execute(sql, params)
  File "/usr/local/lib/python3.7/dist-packages/django/db/backends/utils.py", line 98, in execute
    return super().execute(sql, params)
  File "/usr/local/lib/python3.7/dist-packages/django/db/backends/utils.py", line 66, in execute
    return self._execute_with_wrappers(sql, params, many=False, executor=self._execute)
  File "/usr/local/lib/python3.7/dist-packages/django/db/backends/utils.py", line 75, in _execute_with_wrappers
    return executor(sql, params, many, context)
  File "/usr/local/lib/python3.7/dist-packages/django/db/backends/utils.py", line 84, in _execute
    return self.cursor.execute(sql, params)
  File "/usr/local/lib/python3.7/dist-packages/django/db/utils.py", line 90, in __exit__
    raise dj_exc_value.with_traceback(traceback) from exc_value
  File "/usr/local/lib/python3.7/dist-packages/django/db/backends/utils.py", line 84, in _execute
    return self.cursor.execute(sql, params)
django.db.utils.ProgrammingError: no existe la columna «usuario_id» en la relación «modelo_archivosp»
LINE 1: ... "modelo_archivosp" ("NombreActividad", "upload", "usuario_i...
                                                             ^

06-Jun-22 04:45:06 - ERROR - Internal Server Error: /Subir_Ejercicio_Profesor
Traceback (most recent call last):
  File "/usr/local/lib/python3.7/dist-packages/django/db/backends/utils.py", line 84, in _execute
    return self.cursor.execute(sql, params)
psycopg2.errors.UndefinedColumn: no existe la columna «usuario_id» en la relación «modelo_archivosp»
LINE 1: ... "modelo_archivosp" ("NombreActividad", "upload", "usuario_i...
                                                             ^


The above exception was the direct cause of the following exception:

Traceback (most recent call last):
  File "/usr/local/lib/python3.7/dist-packages/django/core/handlers/exception.py", line 47, in inner
    response = get_response(request)
  File "/usr/local/lib/python3.7/dist-packages/django/core/handlers/base.py", line 181, in _get_response
    response = wrapped_callback(request, *callback_args, **callback_kwargs)
  File "/home/erik/Descargas/ProyectoSeg/pruebas/views.py", line 29, in SubirEjerciciosProfesor
    archivo.save()
  File "/usr/local/lib/python3.7/dist-packages/django/db/models/base.py", line 740, in save
    force_update=force_update, update_fields=update_fields)
  File "/usr/local/lib/python3.7/dist-packages/django/db/models/base.py", line 778, in save_base
    force_update, using, update_fields,
  File "/usr/local/lib/python3.7/dist-packages/django/db/models/base.py", line 881, in _save_table
    results = self._do_insert(cls._base_manager, using, fields, returning_fields, raw)
  File "/usr/local/lib/python3.7/dist-packages/django/db/models/base.py", line 921, in _do_insert
    using=using, raw=raw,
  File "/usr/local/lib/python3.7/dist-packages/django/db/models/manager.py", line 85, in manager_method
    return getattr(self.get_queryset(), name)(*args, **kwargs)
  File "/usr/local/lib/python3.7/dist-packages/django/db/models/query.py", line 1270, in _insert
    return query.get_compiler(using=using).execute_sql(returning_fields)
  File "/usr/local/lib/python3.7/dist-packages/django/db/models/sql/compiler.py", line 1416, in execute_sql
    cursor.execute(sql, params)
  File "/usr/local/lib/python3.7/dist-packages/django/db/backends/utils.py", line 98, in execute
    return super().execute(sql, params)
  File "/usr/local/lib/python3.7/dist-packages/django/db/backends/utils.py", line 66, in execute
    return self._execute_with_wrappers(sql, params, many=False, executor=self._execute)
  File "/usr/local/lib/python3.7/dist-packages/django/db/backends/utils.py", line 75, in _execute_with_wrappers
    return executor(sql, params, many, context)
  File "/usr/local/lib/python3.7/dist-packages/django/db/backends/utils.py", line 84, in _execute
    return self.cursor.execute(sql, params)
  File "/usr/local/lib/python3.7/dist-packages/django/db/utils.py", line 90, in __exit__
    raise dj_exc_value.with_traceback(traceback) from exc_value
  File "/usr/local/lib/python3.7/dist-packages/django/db/backends/utils.py", line 84, in _execute
    return self.cursor.execute(sql, params)
django.db.utils.ProgrammingError: no existe la columna «usuario_id» en la relación «modelo_archivosp»
LINE 1: ... "modelo_archivosp" ("NombreActividad", "upload", "usuario_i...
                                                             ^

06-Jun-22 04:49:16 - INFO - /home/erik/Descargas/ProyectoSeg/modelo/models.py changed, reloading.
06-Jun-22 05:36:14 - WARNING - Not Found: /
06-Jun-22 05:47:30 - INFO - /home/erik/Descargas/ProyectoSeg/pruebas/views.py changed, reloading.
06-Jun-22 05:47:56 - ERROR - Internal Server Error: /verificar_scripts
Traceback (most recent call last):
  File "/usr/local/lib/python3.7/dist-packages/django/core/handlers/exception.py", line 47, in inner
    response = get_response(request)
  File "/usr/local/lib/python3.7/dist-packages/django/core/handlers/base.py", line 181, in _get_response
    response = wrapped_callback(request, *callback_args, **callback_kwargs)
  File "/home/erik/Descargas/ProyectoSeg/pruebas/views.py", line 69, in verificar_scripts
    hola = TareaProfe.pk
AttributeError: 'QuerySet' object has no attribute 'pk'
07-Jun-22 03:46:41 - WARNING - Not Found: /
07-Jun-22 03:47:20 - WARNING - Not Found: //////login
07-Jun-22 03:48:33 - WARNING - Not Found: /llllllogin
07-Jun-22 03:51:54 - ERROR - Internal Server Error: /login
Traceback (most recent call last):
  File "/home/erik/Descargas/ProyectoSeg/pruebas/views.py", line 147, in login
    alumno = models.Alumnos.objects.get(NombreAlumno=nombre)
  File "/usr/local/lib/python3.7/dist-packages/django/db/models/manager.py", line 85, in manager_method
    return getattr(self.get_queryset(), name)(*args, **kwargs)
  File "/usr/local/lib/python3.7/dist-packages/django/db/models/query.py", line 437, in get
    self.model._meta.object_name
modelo.models.Alumnos.DoesNotExist: Alumnos matching query does not exist.

During handling of the above exception, another exception occurred:

Traceback (most recent call last):
  File "/usr/local/lib/python3.7/dist-packages/django/core/handlers/exception.py", line 47, in inner
    response = get_response(request)
  File "/usr/local/lib/python3.7/dist-packages/django/core/handlers/base.py", line 181, in _get_response
    response = wrapped_callback(request, *callback_args, **callback_kwargs)
  File "/home/erik/Descargas/ProyectoSeg/pruebas/views.py", line 155, in login
    return render(request,'login.html',{'errores',errores})
TypeError: unhashable type: 'list'
07-Jun-22 04:42:38 - WARNING - Not Found: /
07-Jun-22 04:43:19 - ERROR - Internal Server Error: /verificar_scripts
Traceback (most recent call last):
  File "/usr/local/lib/python3.7/dist-packages/django/core/handlers/exception.py", line 47, in inner
    response = get_response(request)
  File "/usr/local/lib/python3.7/dist-packages/django/core/handlers/base.py", line 181, in _get_response
    response = wrapped_callback(request, *callback_args, **callback_kwargs)
  File "/home/erik/Descargas/ProyectoSeg/pruebas/views.py", line 69, in verificar_scripts
    hola = TareaProfe.pk
AttributeError: 'QuerySet' object has no attribute 'pk'
07-Jun-22 04:45:22 - INFO - /home/erik/Descargas/ProyectoSeg/pruebas/views.py changed, reloading.
07-Jun-22 04:45:56 - ERROR - Internal Server Error: /login
Traceback (most recent call last):
  File "/usr/local/lib/python3.7/dist-packages/django/core/handlers/exception.py", line 47, in inner
    response = get_response(request)
  File "/usr/local/lib/python3.7/dist-packages/django/utils/deprecation.py", line 119, in __call__
    response = self.process_response(request, response)
  File "/usr/local/lib/python3.7/dist-packages/django/middleware/clickjacking.py", line 26, in process_response
    if response.get('X-Frame-Options') is not None:
AttributeError: 'str' object has no attribute 'get'
07-Jun-22 04:47:34 - INFO - /home/erik/Descargas/ProyectoSeg/pruebas/views.py changed, reloading.
07-Jun-22 04:47:57 - ERROR - Internal Server Error: /login
Traceback (most recent call last):
  File "/usr/local/lib/python3.7/dist-packages/django/core/handlers/exception.py", line 47, in inner
    response = get_response(request)
  File "/usr/local/lib/python3.7/dist-packages/django/utils/deprecation.py", line 119, in __call__
    response = self.process_response(request, response)
  File "/usr/local/lib/python3.7/dist-packages/django/middleware/clickjacking.py", line 26, in process_response
    if response.get('X-Frame-Options') is not None:
AttributeError: 'str' object has no attribute 'get'
07-Jun-22 04:49:51 - INFO - /home/erik/Descargas/ProyectoSeg/pruebas/views.py changed, reloading.
07-Jun-22 04:50:03 - ERROR - Internal Server Error: /login
Traceback (most recent call last):
  File "/usr/local/lib/python3.7/dist-packages/django/core/handlers/exception.py", line 47, in inner
    response = get_response(request)
  File "/usr/local/lib/python3.7/dist-packages/django/utils/deprecation.py", line 119, in __call__
    response = self.process_response(request, response)
  File "/usr/local/lib/python3.7/dist-packages/django/middleware/clickjacking.py", line 26, in process_response
    if response.get('X-Frame-Options') is not None:
AttributeError: 'str' object has no attribute 'get'
07-Jun-22 04:50:19 - ERROR - Internal Server Error: /login
Traceback (most recent call last):
  File "/usr/local/lib/python3.7/dist-packages/django/core/handlers/exception.py", line 47, in inner
    response = get_response(request)
  File "/usr/local/lib/python3.7/dist-packages/django/utils/deprecation.py", line 119, in __call__
    response = self.process_response(request, response)
  File "/usr/local/lib/python3.7/dist-packages/django/middleware/clickjacking.py", line 26, in process_response
    if response.get('X-Frame-Options') is not None:
AttributeError: 'str' object has no attribute 'get'
07-Jun-22 04:51:04 - INFO - /home/erik/Descargas/ProyectoSeg/pruebas/views.py changed, reloading.
07-Jun-22 04:52:05 - INFO - /home/erik/Descargas/ProyectoSeg/pruebas/views.py changed, reloading.
07-Jun-22 04:52:25 - INFO - /home/erik/Descargas/ProyectoSeg/pruebas/views.py changed, reloading.
07-Jun-22 04:53:35 - ERROR - Internal Server Error: /verificar_scripts
Traceback (most recent call last):
  File "/usr/local/lib/python3.7/dist-packages/django/core/handlers/exception.py", line 47, in inner
    response = get_response(request)
  File "/usr/local/lib/python3.7/dist-packages/django/core/handlers/base.py", line 181, in _get_response
    response = wrapped_callback(request, *callback_args, **callback_kwargs)
  File "/home/erik/Descargas/ProyectoSeg/pruebas/views.py", line 90, in verificar_scripts
    return render(request,t,{'TareaProfe':TareaProfe})
NameError: name 'TareaProfe' is not defined
07-Jun-22 04:53:49 - INFO - /home/erik/Descargas/ProyectoSeg/pruebas/views.py changed, reloading.
07-Jun-22 04:59:18 - INFO - /home/erik/Descargas/ProyectoSeg/pruebas/views.py changed, reloading.
07-Jun-22 05:00:40 - INFO - /home/erik/Descargas/ProyectoSeg/pruebas/views.py changed, reloading.
07-Jun-22 05:09:39 - INFO - /home/erik/Descargas/ProyectoSeg/pruebas/views.py changed, reloading.
07-Jun-22 05:20:42 - INFO - /home/erik/Descargas/ProyectoSeg/pruebas/views.py changed, reloading.
07-Jun-22 05:22:27 - ERROR - Internal Server Error: /verificar_scripts
Traceback (most recent call last):
  File "/usr/local/lib/python3.7/dist-packages/django/core/handlers/exception.py", line 47, in inner
    response = get_response(request)
  File "/usr/local/lib/python3.7/dist-packages/django/core/handlers/base.py", line 181, in _get_response
    response = wrapped_callback(request, *callback_args, **callback_kwargs)
  File "/home/erik/Descargas/ProyectoSeg/pruebas/views.py", line 84, in verificar_scripts
    salida = subprocess.Popen(comando, stdout=subprocess.PIPE, stderr=subprocess.PIPE)
  File "/usr/lib/python3.7/subprocess.py", line 775, in __init__
    restore_signals, start_new_session)
  File "/usr/lib/python3.7/subprocess.py", line 1522, in _execute_child
    raise child_exception_type(errno_num, err_msg, err_filename)
OSError: [Errno 8] Exec format error: '/home/erik/Descargas/ProyectoSeg/archivos/Practicas/prueba_6b7Ao86.sh'
07-Jun-22 05:32:33 - INFO - /home/erik/Descargas/ProyectoSeg/pruebas/views.py changed, reloading.
07-Jun-22 05:34:10 - ERROR - Internal Server Error: /verificar_scripts
Traceback (most recent call last):
  File "/usr/local/lib/python3.7/dist-packages/django/core/handlers/exception.py", line 47, in inner
    response = get_response(request)
  File "/usr/local/lib/python3.7/dist-packages/django/core/handlers/base.py", line 181, in _get_response
    response = wrapped_callback(request, *callback_args, **callback_kwargs)
  File "/home/erik/Descargas/ProyectoSeg/pruebas/views.py", line 84, in verificar_scripts
    salida = subprocess.Popen(comando, stdout=subprocess.PIPE, stderr=subprocess.PIPE)
  File "/usr/lib/python3.7/subprocess.py", line 775, in __init__
    restore_signals, start_new_session)
  File "/usr/lib/python3.7/subprocess.py", line 1522, in _execute_child
    raise child_exception_type(errno_num, err_msg, err_filename)
OSError: [Errno 8] Exec format error: '/home/erik/Descargas/ProyectoSeg/archivos/Practicas/hola2.sh'
