22-May-22 04:01:20 - INFO - /home/omarconde/pruebas/pruebas/views.py changed, reloading.
22-May-22 04:04:11 - INFO - /home/omarconde/pruebas/pruebas/views.py changed, reloading.
22-May-22 04:07:25 - INFO - usuario logueado:Saul
22-May-22 04:16:32 - WARNING - Not Found: /
22-May-22 04:16:37 - WARNING - Not Found: /favicon.ico
22-May-22 04:16:45 - ERROR - Internal Server Error: /verificar_token
Traceback (most recent call last):
  File "/usr/lib/python3/dist-packages/django/core/handlers/exception.py", line 34, in inner
    response = get_response(request)
  File "/usr/lib/python3/dist-packages/django/core/handlers/base.py", line 115, in _get_response
    response = self.process_exception_by_middleware(e, request)
  File "/usr/lib/python3/dist-packages/django/core/handlers/base.py", line 113, in _get_response
    response = wrapped_callback(request, *callback_args, **callback_kwargs)
  File "/home/omarconde/pruebas/pruebas/views.py", line 55, in verificar_token
    return render(request, t)
  File "/usr/lib/python3/dist-packages/django/shortcuts.py", line 36, in render
    content = loader.render_to_string(template_name, context, request, using=using)
  File "/usr/lib/python3/dist-packages/django/template/loader.py", line 61, in render_to_string
    template = get_template(template_name, using=using)
  File "/usr/lib/python3/dist-packages/django/template/loader.py", line 15, in get_template
    return engine.get_template(template_name)
  File "/usr/lib/python3/dist-packages/django/template/backends/django.py", line 34, in get_template
    return Template(self.engine.get_template(template_name), self)
  File "/usr/lib/python3/dist-packages/django/template/engine.py", line 143, in get_template
    template, origin = self.find_template(template_name)
  File "/usr/lib/python3/dist-packages/django/template/engine.py", line 125, in find_template
    template = loader.get_template(name, skip=skip)
  File "/usr/lib/python3/dist-packages/django/template/loaders/base.py", line 29, in get_template
    return Template(
  File "/usr/lib/python3/dist-packages/django/template/base.py", line 156, in __init__
    self.nodelist = self.compile_nodelist()
  File "/usr/lib/python3/dist-packages/django/template/base.py", line 194, in compile_nodelist
    return parser.parse()
  File "/usr/lib/python3/dist-packages/django/template/base.py", line 478, in parse
    raise self.error(token, e)
  File "/usr/lib/python3/dist-packages/django/template/base.py", line 476, in parse
    compiled_result = compile_func(self, token)
  File "/usr/lib/python3/dist-packages/django/template/loader_tags.py", line 266, in do_extends
    nodelist = parser.parse()
  File "/usr/lib/python3/dist-packages/django/template/base.py", line 478, in parse
    raise self.error(token, e)
  File "/usr/lib/python3/dist-packages/django/template/base.py", line 476, in parse
    compiled_result = compile_func(self, token)
  File "/usr/lib/python3/dist-packages/django/template/loader_tags.py", line 209, in do_block
    nodelist = parser.parse(('endblock',))
  File "/usr/lib/python3/dist-packages/django/template/base.py", line 483, in parse
    self.unclosed_block_tag(parse_until)
  File "/usr/lib/python3/dist-packages/django/template/base.py", line 544, in unclosed_block_tag
    raise self.error(token, msg)
django.template.exceptions.TemplateSyntaxError: Unclosed tag on line 3: 'block'. Looking for one of: endblock.
22-May-22 04:16:45 - WARNING - Not Found: /favicon.ico
22-May-22 04:17:14 - WARNING - Not Found: /favicon.ico
22-May-22 04:19:38 - INFO - /home/omarconde/pruebas/pruebas/views.py changed, reloading.
22-May-22 04:19:57 - INFO - usuario logueado:Saul
22-May-22 04:20:07 - INFO - /home/omarconde/pruebas/pruebas/views.py changed, reloading.
22-May-22 04:20:22 - INFO - /home/omarconde/pruebas/pruebas/views.py changed, reloading.
22-May-22 04:23:16 - WARNING - Not Found: /
22-May-22 04:25:35 - INFO - usuario logueado:Saul
22-May-22 04:26:17 - WARNING - Not Found: /favicon.ico
22-May-22 04:55:29 - INFO - /home/omarconde/pruebas/pruebas/views.py changed, reloading.
23-May-22 03:28:49 - WARNING - Not Found: /
23-May-22 03:28:51 - WARNING - Not Found: /favicon.ico
23-May-22 03:29:34 - WARNING - Not Found: /favicon.ico
23-May-22 03:30:01 - ERROR - Internal Server Error: /Registro_Alumnos
Traceback (most recent call last):
  File "/usr/lib/python3/dist-packages/django/core/handlers/exception.py", line 34, in inner
    response = get_response(request)
  File "/usr/lib/python3/dist-packages/django/core/handlers/base.py", line 115, in _get_response
    response = self.process_exception_by_middleware(e, request)
  File "/usr/lib/python3/dist-packages/django/core/handlers/base.py", line 113, in _get_response
    response = wrapped_callback(request, *callback_args, **callback_kwargs)
  File "/home/omarconde/pruebas/pruebas/views.py", line 111, in Registro_Alumnos
    print(alumno.contrasena)
AttributeError: 'Alumnos' object has no attribute 'contrasena'
23-May-22 03:30:47 - INFO - /home/omarconde/pruebas/pruebas/views.py changed, reloading.
23-May-22 03:30:51 - ERROR - Internal Server Error: /Registro_Alumnos
Traceback (most recent call last):
  File "/usr/lib/python3/dist-packages/django/core/handlers/exception.py", line 34, in inner
    response = get_response(request)
  File "/usr/lib/python3/dist-packages/django/core/handlers/base.py", line 124, in _get_response
    raise ValueError(
ValueError: The view pruebas.views.Registro_Alumnos didn't return an HttpResponse object. It returned None instead.
23-May-22 03:30:51 - WARNING - Not Found: /favicon.ico
23-May-22 03:31:24 - INFO - /home/omarconde/pruebas/pruebas/views.py changed, reloading.
23-May-22 03:31:29 - ERROR - Internal Server Error: /Registro_Alumnos
Traceback (most recent call last):
  File "/usr/lib/python3/dist-packages/django/core/handlers/exception.py", line 34, in inner
    response = get_response(request)
  File "/usr/lib/python3/dist-packages/django/core/handlers/base.py", line 124, in _get_response
    raise ValueError(
ValueError: The view pruebas.views.Registro_Alumnos didn't return an HttpResponse object. It returned None instead.
23-May-22 03:32:18 - INFO - /home/omarconde/pruebas/pruebas/views.py changed, reloading.
23-May-22 03:44:30 - INFO - /home/omarconde/pruebas/pruebas/views.py changed, reloading.
23-May-22 03:45:56 - INFO - /home/omarconde/pruebas/pruebas/views.py changed, reloading.
23-May-22 03:46:21 - ERROR - Internal Server Error: /Registro_Alumnos
Traceback (most recent call last):
  File "/usr/lib/python3/dist-packages/django/core/handlers/exception.py", line 34, in inner
    response = get_response(request)
  File "/usr/lib/python3/dist-packages/django/core/handlers/base.py", line 115, in _get_response
    response = self.process_exception_by_middleware(e, request)
  File "/usr/lib/python3/dist-packages/django/core/handlers/base.py", line 113, in _get_response
    response = wrapped_callback(request, *callback_args, **callback_kwargs)
  File "/home/omarconde/pruebas/pruebas/views.py", line 111, in Registro_Alumnos
    errores = verificacion_de_contrasenas(contrasena)
  File "/home/omarconde/pruebas/pruebas/views.py", line 122, in verificacion_de_contrasenas
    if alumno.Contraseña == '':
NameError: name 'alumno' is not defined
23-May-22 03:47:01 - INFO - /home/omarconde/pruebas/pruebas/views.py changed, reloading.
23-May-22 03:47:09 - ERROR - Internal Server Error: /Registro_Alumnos
Traceback (most recent call last):
  File "/usr/lib/python3/dist-packages/django/core/handlers/exception.py", line 34, in inner
    response = get_response(request)
  File "/usr/lib/python3/dist-packages/django/core/handlers/base.py", line 115, in _get_response
    response = self.process_exception_by_middleware(e, request)
  File "/usr/lib/python3/dist-packages/django/core/handlers/base.py", line 113, in _get_response
    response = wrapped_callback(request, *callback_args, **callback_kwargs)
  File "/home/omarconde/pruebas/pruebas/views.py", line 111, in Registro_Alumnos
    errores = verificacion_de_contrasenas(alumno)
  File "/home/omarconde/pruebas/pruebas/views.py", line 124, in verificacion_de_contrasenas
    if len(alumno.Contrasena) < 10:
AttributeError: 'Alumnos' object has no attribute 'Contrasena'
23-May-22 03:47:31 - INFO - /home/omarconde/pruebas/pruebas/views.py changed, reloading.
23-May-22 03:48:28 - INFO - /home/omarconde/pruebas/pruebas/views.py changed, reloading.
23-May-22 03:50:35 - INFO - /home/omarconde/pruebas/pruebas/views.py changed, reloading.
23-May-22 03:53:25 - INFO - /home/omarconde/pruebas/modelo/models.py changed, reloading.
23-May-22 04:09:26 - INFO - /home/omarconde/pruebas/pruebas/views.py changed, reloading.
23-May-22 04:10:17 - INFO - /home/omarconde/pruebas/pruebas/views.py changed, reloading.
23-May-22 04:11:11 - INFO - /home/omarconde/pruebas/pruebas/views.py changed, reloading.
23-May-22 04:12:53 - ERROR - Internal Server Error: /Registro_Alumnos
Traceback (most recent call last):
  File "/usr/lib/python3/dist-packages/django/core/handlers/exception.py", line 34, in inner
    response = get_response(request)
  File "/usr/lib/python3/dist-packages/django/core/handlers/base.py", line 115, in _get_response
    response = self.process_exception_by_middleware(e, request)
  File "/usr/lib/python3/dist-packages/django/core/handlers/base.py", line 113, in _get_response
    response = wrapped_callback(request, *callback_args, **callback_kwargs)
  File "/home/omarconde/pruebas/pruebas/views.py", line 111, in Registro_Alumnos
    errores = verificacion_de_contrasenas(alumno)
  File "/home/omarconde/pruebas/pruebas/views.py", line 128, in verificacion_de_contrasenas
    errores_password.append('La contraseña al menos debe contener una letra mayúscula')
NameError: name 'errores_password' is not defined
23-May-22 04:13:15 - INFO - /home/omarconde/pruebas/pruebas/views.py changed, reloading.
23-May-22 04:16:48 - INFO - /home/omarconde/pruebas/pruebas/views.py changed, reloading.
23-May-22 04:21:14 - INFO - /home/omarconde/pruebas/pruebas/views.py changed, reloading.
23-May-22 04:21:42 - INFO - /home/omarconde/pruebas/pruebas/views.py changed, reloading.
23-May-22 04:23:45 - INFO - /home/omarconde/pruebas/pruebas/views.py changed, reloading.
23-May-22 04:25:07 - INFO - /home/omarconde/pruebas/pruebas/views.py changed, reloading.
23-May-22 04:25:15 - ERROR - Internal Server Error: /Registro_Alumnos
Traceback (most recent call last):
  File "/usr/lib/python3/dist-packages/django/core/handlers/exception.py", line 34, in inner
    response = get_response(request)
  File "/usr/lib/python3/dist-packages/django/core/handlers/base.py", line 115, in _get_response
    response = self.process_exception_by_middleware(e, request)
  File "/usr/lib/python3/dist-packages/django/core/handlers/base.py", line 113, in _get_response
    response = wrapped_callback(request, *callback_args, **callback_kwargs)
  File "/home/omarconde/pruebas/pruebas/views.py", line 111, in Registro_Alumnos
    errores = verificacion_de_contrasenas(alumno)
  File "/home/omarconde/pruebas/pruebas/views.py", line 124, in verificacion_de_contrasenas
    errores_password.append('La contraseña no debe contener espacios')
NameError: name 'errores_password' is not defined
23-May-22 04:25:38 - INFO - /home/omarconde/pruebas/pruebas/views.py changed, reloading.
23-May-22 04:27:06 - INFO - /home/omarconde/pruebas/pruebas/views.py changed, reloading.
23-May-22 04:27:45 - INFO - /home/omarconde/pruebas/pruebas/views.py changed, reloading.
23-May-22 04:33:36 - INFO - /home/omarconde/pruebas/pruebas/views.py changed, reloading.
23-May-22 04:33:39 - INFO - /home/omarconde/pruebas/pruebas/views.py changed, reloading.
23-May-22 04:33:45 - WARNING - Not Found: /favicon.ico
23-May-22 04:39:44 - WARNING - Not Found: /favicon.ico
23-May-22 05:04:33 - INFO - /home/omarconde/pruebas/pruebas/views.py changed, reloading.
23-May-22 23:09:47 - WARNING - Not Found: /
23-May-22 23:11:39 - INFO - /home/omarconde/pruebas/pruebas/views.py changed, reloading.
23-May-22 23:13:46 - INFO - /home/omarconde/pruebas/pruebas/views.py changed, reloading.
23-May-22 23:13:56 - ERROR - Internal Server Error: /Registro_Alumnos
Traceback (most recent call last):
  File "/usr/lib/python3/dist-packages/django/core/handlers/exception.py", line 34, in inner
    response = get_response(request)
  File "/usr/lib/python3/dist-packages/django/core/handlers/base.py", line 115, in _get_response
    response = self.process_exception_by_middleware(e, request)
  File "/usr/lib/python3/dist-packages/django/core/handlers/base.py", line 113, in _get_response
    response = wrapped_callback(request, *callback_args, **callback_kwargs)
  File "/home/omarconde/pruebas/pruebas/views.py", line 112, in Registro_Alumnos
    errores = verificacion_de_contrasenas(alumno)
NameError: name 'verificacion_de_contrasenas' is not defined
23-May-22 23:15:26 - INFO - /home/omarconde/pruebas/pruebas/views.py changed, reloading.
23-May-22 23:16:52 - INFO - /home/omarconde/pruebas/pruebas/views.py changed, reloading.
23-May-22 23:16:57 - ERROR - Internal Server Error: /Registro_Alumnos
Traceback (most recent call last):
  File "/usr/lib/python3/dist-packages/django/core/handlers/exception.py", line 34, in inner
    response = get_response(request)
  File "/usr/lib/python3/dist-packages/django/core/handlers/base.py", line 115, in _get_response
    response = self.process_exception_by_middleware(e, request)
  File "/usr/lib/python3/dist-packages/django/core/handlers/base.py", line 113, in _get_response
    response = wrapped_callback(request, *callback_args, **callback_kwargs)
  File "/home/omarconde/pruebas/pruebas/views.py", line 112, in Registro_Alumnos
    errores = recoleccion_de_errores_del_registro(alumno)
  File "/home/omarconde/pruebas/pruebas/views.py", line 152, in recoleccion_de_errores_del_registro
    errores_contrasena = verificacion_de_contrasenas(alumno)
NameError: name 'verificacion_de_contrasenas' is not defined
23-May-22 23:17:29 - INFO - /home/omarconde/pruebas/pruebas/views.py changed, reloading.
23-May-22 23:17:57 - INFO - /home/omarconde/pruebas/pruebas/views.py changed, reloading.
23-May-22 23:57:57 - INFO - /home/omarconde/pruebas/pruebas/views.py changed, reloading.
24-May-22 00:03:06 - INFO - /home/omarconde/pruebas/modelo/models.py changed, reloading.
24-May-22 00:07:24 - INFO - /home/omarconde/pruebas/pruebas/views.py changed, reloading.
24-May-22 00:07:50 - INFO - /home/omarconde/pruebas/pruebas/views.py changed, reloading.
24-May-22 00:09:29 - INFO - /home/omarconde/pruebas/pruebas/views.py changed, reloading.
24-May-22 00:11:32 - ERROR - Internal Server Error: /Registro_Alumnos
Traceback (most recent call last):
  File "/usr/lib/python3/dist-packages/django/core/handlers/exception.py", line 34, in inner
    response = get_response(request)
  File "/usr/lib/python3/dist-packages/django/core/handlers/base.py", line 115, in _get_response
    response = self.process_exception_by_middleware(e, request)
  File "/usr/lib/python3/dist-packages/django/core/handlers/base.py", line 113, in _get_response
    response = wrapped_callback(request, *callback_args, **callback_kwargs)
  File "/home/omarconde/pruebas/pruebas/views.py", line 114, in Registro_Alumnos
    Elsalt = get_random_string(length=16)
NameError: name 'get_random_string' is not defined
24-May-22 00:11:33 - WARNING - Not Found: /favicon.ico
24-May-22 00:12:04 - INFO - /home/omarconde/pruebas/pruebas/views.py changed, reloading.
24-May-22 00:12:14 - ERROR - Internal Server Error: /Registro_Alumnos
Traceback (most recent call last):
  File "/usr/lib/python3/dist-packages/django/core/handlers/exception.py", line 34, in inner
    response = get_response(request)
  File "/usr/lib/python3/dist-packages/django/core/handlers/base.py", line 115, in _get_response
    response = self.process_exception_by_middleware(e, request)
  File "/usr/lib/python3/dist-packages/django/core/handlers/base.py", line 113, in _get_response
    response = wrapped_callback(request, *callback_args, **callback_kwargs)
  File "/home/omarconde/pruebas/pruebas/views.py", line 116, in Registro_Alumnos
    binario = (contrasena + Elsalt).enconde('utf-8')
AttributeError: 'str' object has no attribute 'enconde'
24-May-22 00:13:36 - INFO - /home/omarconde/pruebas/pruebas/views.py changed, reloading.
24-May-22 00:13:46 - ERROR - Internal Server Error: /Registro_Alumnos
Traceback (most recent call last):
  File "/usr/lib/python3/dist-packages/django/core/handlers/exception.py", line 34, in inner
    response = get_response(request)
  File "/usr/lib/python3/dist-packages/django/core/handlers/base.py", line 115, in _get_response
    response = self.process_exception_by_middleware(e, request)
  File "/usr/lib/python3/dist-packages/django/core/handlers/base.py", line 113, in _get_response
    response = wrapped_callback(request, *callback_args, **callback_kwargs)
  File "/home/omarconde/pruebas/pruebas/views.py", line 117, in Registro_Alumnos
    hasher = hashlib.sha256()
NameError: name 'hashlib' is not defined
24-May-22 00:14:38 - INFO - /home/omarconde/pruebas/pruebas/views.py changed, reloading.
24-May-22 00:14:45 - ERROR - Internal Server Error: /Registro_Alumnos
Traceback (most recent call last):
  File "/usr/lib/python3/dist-packages/django/core/handlers/exception.py", line 34, in inner
    response = get_response(request)
  File "/usr/lib/python3/dist-packages/django/core/handlers/base.py", line 115, in _get_response
    response = self.process_exception_by_middleware(e, request)
  File "/usr/lib/python3/dist-packages/django/core/handlers/base.py", line 113, in _get_response
    response = wrapped_callback(request, *callback_args, **callback_kwargs)
  File "/home/omarconde/pruebas/pruebas/views.py", line 117, in Registro_Alumnos
    hasher = hashlib.sha256()
NameError: name 'hashlib' is not defined
24-May-22 00:15:09 - INFO - /home/omarconde/pruebas/pruebas/views.py changed, reloading.
24-May-22 00:21:10 - INFO - /home/omarconde/pruebas/pruebas/views.py changed, reloading.
24-May-22 00:21:51 - ERROR - Internal Server Error: /login
Traceback (most recent call last):
  File "/home/omarconde/pruebas/pruebas/views.py", line 90, in login
    mandar_mensaje_al_bot(request)
  File "/home/omarconde/pruebas/pruebas/views.py", line 36, in mandar_mensaje_al_bot
    datos_guardados = models.Alumnos.objects.get(NombreAlumno=nombre)
  File "/usr/lib/python3/dist-packages/django/db/models/manager.py", line 82, in manager_method
    return getattr(self.get_queryset(), name)(*args, **kwargs)
  File "/usr/lib/python3/dist-packages/django/db/models/query.py", line 410, in get
    raise self.model.MultipleObjectsReturned(
modelo.models.Alumnos.MultipleObjectsReturned: get() returned more than one Alumnos -- it returned 9!

During handling of the above exception, another exception occurred:

Traceback (most recent call last):
  File "/usr/lib/python3/dist-packages/django/core/handlers/exception.py", line 34, in inner
    response = get_response(request)
  File "/usr/lib/python3/dist-packages/django/core/handlers/base.py", line 115, in _get_response
    response = self.process_exception_by_middleware(e, request)
  File "/usr/lib/python3/dist-packages/django/core/handlers/base.py", line 113, in _get_response
    response = wrapped_callback(request, *callback_args, **callback_kwargs)
  File "/home/omarconde/pruebas/pruebas/views.py", line 94, in login
    return render(request,t,{'errores',errores})
UnboundLocalError: local variable 't' referenced before assignment
24-May-22 00:21:53 - WARNING - Not Found: /favicon.ico
24-May-22 00:26:41 - INFO - /home/omarconde/pruebas/pruebas/views.py changed, reloading.
24-May-22 00:27:53 - INFO - /home/omarconde/pruebas/pruebas/views.py changed, reloading.
24-May-22 00:28:03 - ERROR - Internal Server Error: /login
Traceback (most recent call last):
  File "/usr/lib/python3/dist-packages/django/core/handlers/exception.py", line 34, in inner
    response = get_response(request)
  File "/usr/lib/python3/dist-packages/django/core/handlers/base.py", line 124, in _get_response
    raise ValueError(
ValueError: The view pruebas.views.login didn't return an HttpResponse object. It returned None instead.
24-May-22 00:28:05 - WARNING - Not Found: /favicon.ico
24-May-22 00:28:40 - INFO - /home/omarconde/pruebas/pruebas/views.py changed, reloading.
24-May-22 00:30:49 - ERROR - Internal Server Error: /login
Traceback (most recent call last):
  File "/home/omarconde/pruebas/pruebas/views.py", line 87, in login
    alumno = models.Alumnos.objects.get(NombreAlumno=nombre,Contraseña=contraseña)
  File "/usr/lib/python3/dist-packages/django/db/models/manager.py", line 82, in manager_method
    return getattr(self.get_queryset(), name)(*args, **kwargs)
  File "/usr/lib/python3/dist-packages/django/db/models/query.py", line 406, in get
    raise self.model.DoesNotExist(
modelo.models.Alumnos.DoesNotExist: Alumnos matching query does not exist.

During handling of the above exception, another exception occurred:

Traceback (most recent call last):
  File "/usr/lib/python3/dist-packages/django/core/handlers/exception.py", line 34, in inner
    response = get_response(request)
  File "/usr/lib/python3/dist-packages/django/core/handlers/base.py", line 115, in _get_response
    response = self.process_exception_by_middleware(e, request)
  File "/usr/lib/python3/dist-packages/django/core/handlers/base.py", line 113, in _get_response
    response = wrapped_callback(request, *callback_args, **callback_kwargs)
  File "/home/omarconde/pruebas/pruebas/views.py", line 95, in login
    return render(request,t,{'errores',errores})
UnboundLocalError: local variable 't' referenced before assignment
24-May-22 00:32:17 - INFO - /home/omarconde/pruebas/pruebas/views.py changed, reloading.
24-May-22 00:32:25 - ERROR - Internal Server Error: /login
Traceback (most recent call last):
  File "/home/omarconde/pruebas/pruebas/views.py", line 87, in login
    alumno = models.Alumnos.objects.get(NombreAlumno=nombre,Contraseña=contraseña)
  File "/usr/lib/python3/dist-packages/django/db/models/manager.py", line 82, in manager_method
    return getattr(self.get_queryset(), name)(*args, **kwargs)
  File "/usr/lib/python3/dist-packages/django/db/models/query.py", line 406, in get
    raise self.model.DoesNotExist(
modelo.models.Alumnos.DoesNotExist: Alumnos matching query does not exist.

During handling of the above exception, another exception occurred:

Traceback (most recent call last):
  File "/usr/lib/python3/dist-packages/django/core/handlers/exception.py", line 34, in inner
    response = get_response(request)
  File "/usr/lib/python3/dist-packages/django/core/handlers/base.py", line 115, in _get_response
    response = self.process_exception_by_middleware(e, request)
  File "/usr/lib/python3/dist-packages/django/core/handlers/base.py", line 113, in _get_response
    response = wrapped_callback(request, *callback_args, **callback_kwargs)
  File "/home/omarconde/pruebas/pruebas/views.py", line 95, in login
    return render(request,'login.html',{'errores',errores})
TypeError: unhashable type: 'list'
24-May-22 00:33:28 - INFO - /home/omarconde/pruebas/pruebas/views.py changed, reloading.
24-May-22 00:39:24 - INFO - /home/omarconde/pruebas/pruebas/views.py changed, reloading.
24-May-22 00:39:56 - INFO - usuario logueado:David
24-May-22 01:58:15 - ERROR - Internal Server Error: /login
Traceback (most recent call last):
  File "/home/omarconde/pruebas/pruebas/views.py", line 87, in login
    alumno = models.Alumnos.objects.get(NombreAlumno=nombre)
  File "/usr/lib/python3/dist-packages/django/db/models/manager.py", line 82, in manager_method
    return getattr(self.get_queryset(), name)(*args, **kwargs)
  File "/usr/lib/python3/dist-packages/django/db/models/query.py", line 406, in get
    raise self.model.DoesNotExist(
modelo.models.Alumnos.DoesNotExist: Alumnos matching query does not exist.

During handling of the above exception, another exception occurred:

Traceback (most recent call last):
  File "/usr/lib/python3/dist-packages/django/core/handlers/exception.py", line 34, in inner
    response = get_response(request)
  File "/usr/lib/python3/dist-packages/django/core/handlers/base.py", line 115, in _get_response
    response = self.process_exception_by_middleware(e, request)
  File "/usr/lib/python3/dist-packages/django/core/handlers/base.py", line 113, in _get_response
    response = wrapped_callback(request, *callback_args, **callback_kwargs)
  File "/home/omarconde/pruebas/pruebas/views.py", line 95, in login
    return render(request,'login.html',{'errores',errores})
TypeError: unhashable type: 'list'
24-May-22 01:58:33 - ERROR - Internal Server Error: /login
Traceback (most recent call last):
  File "/home/omarconde/pruebas/pruebas/views.py", line 87, in login
    alumno = models.Alumnos.objects.get(NombreAlumno=nombre)
  File "/usr/lib/python3/dist-packages/django/db/models/manager.py", line 82, in manager_method
    return getattr(self.get_queryset(), name)(*args, **kwargs)
  File "/usr/lib/python3/dist-packages/django/db/models/query.py", line 406, in get
    raise self.model.DoesNotExist(
modelo.models.Alumnos.DoesNotExist: Alumnos matching query does not exist.

During handling of the above exception, another exception occurred:

Traceback (most recent call last):
  File "/usr/lib/python3/dist-packages/django/core/handlers/exception.py", line 34, in inner
    response = get_response(request)
  File "/usr/lib/python3/dist-packages/django/core/handlers/base.py", line 115, in _get_response
    response = self.process_exception_by_middleware(e, request)
  File "/usr/lib/python3/dist-packages/django/core/handlers/base.py", line 113, in _get_response
    response = wrapped_callback(request, *callback_args, **callback_kwargs)
  File "/home/omarconde/pruebas/pruebas/views.py", line 95, in login
    return render(request,'login.html',{'errores',errores})
TypeError: unhashable type: 'list'
24-May-22 02:00:56 - INFO - usuario logueado:Saul
24-May-22 02:01:05 - INFO - usuario logueado:Saul
24-May-22 02:02:37 - INFO - usuario logueado:Saul
24-May-22 02:24:52 - INFO - /home/omarconde/pruebas/pruebas/views.py changed, reloading.
24-May-22 02:24:57 - WARNING - Not Found: /favicon.ico
24-May-22 02:25:28 - INFO - usuario logueado:Saul
24-May-22 02:25:30 - WARNING - Not Found: /favicon.ico
24-May-22 02:25:35 - WARNING - Not Found: /favicon.ico
24-May-22 02:26:16 - WARNING - Not Found: /favicon.ico
24-May-22 02:26:34 - ERROR - Internal Server Error: /login
Traceback (most recent call last):
  File "/usr/lib/python3/dist-packages/django/core/handlers/exception.py", line 34, in inner
    response = get_response(request)
  File "/usr/lib/python3/dist-packages/django/core/handlers/base.py", line 124, in _get_response
    raise ValueError(
ValueError: The view pruebas.views.login didn't return an HttpResponse object. It returned None instead.
24-May-22 02:26:35 - WARNING - Not Found: /favicon.ico
24-May-22 02:27:23 - INFO - /home/omarconde/pruebas/pruebas/views.py changed, reloading.
24-May-22 02:27:29 - ERROR - Internal Server Error: /login
Traceback (most recent call last):
  File "/home/omarconde/pruebas/pruebas/views.py", line 88, in login
    alumno = models.Alumnos.objects.get(NombreAlumno=nombre, Contraseña=contraseña)
  File "/usr/lib/python3/dist-packages/django/db/models/manager.py", line 82, in manager_method
    return getattr(self.get_queryset(), name)(*args, **kwargs)
  File "/usr/lib/python3/dist-packages/django/db/models/query.py", line 406, in get
    raise self.model.DoesNotExist(
modelo.models.Alumnos.DoesNotExist: Alumnos matching query does not exist.

During handling of the above exception, another exception occurred:

Traceback (most recent call last):
  File "/usr/lib/python3/dist-packages/django/core/handlers/exception.py", line 34, in inner
    response = get_response(request)
  File "/usr/lib/python3/dist-packages/django/core/handlers/base.py", line 115, in _get_response
    response = self.process_exception_by_middleware(e, request)
  File "/usr/lib/python3/dist-packages/django/core/handlers/base.py", line 113, in _get_response
    response = wrapped_callback(request, *callback_args, **callback_kwargs)
  File "/home/omarconde/pruebas/pruebas/views.py", line 96, in login
    return render(request,'login.html',{'errores',errores})
TypeError: unhashable type: 'list'
24-May-22 02:29:09 - INFO - /home/omarconde/pruebas/pruebas/views.py changed, reloading.
24-May-22 02:29:16 - WARNING - Not Found: /favicon.ico
24-May-22 02:29:38 - INFO - usuario logueado:Saul
24-May-22 02:29:45 - INFO - usuario logueado:Saul
24-May-22 02:33:20 - INFO - /home/omarconde/pruebas/pruebas/views.py changed, reloading.
24-May-22 02:39:58 - INFO - /home/omarconde/pruebas/pruebas/views.py changed, reloading.
24-May-22 02:40:07 - INFO - usuario logueado:Saul
24-May-22 02:41:35 - INFO - /home/omarconde/pruebas/pruebas/views.py changed, reloading.
24-May-22 02:41:40 - INFO - usuario logueado:Saul
24-May-22 02:41:49 - INFO - usuario logueado:Saul
24-May-22 02:43:12 - INFO - /home/omarconde/pruebas/pruebas/views.py changed, reloading.
24-May-22 02:43:58 - INFO - usuario logueado:Saul
24-May-22 02:44:56 - INFO - /home/omarconde/pruebas/pruebas/views.py changed, reloading.
24-May-22 02:45:04 - INFO - usuario logueado:Saul
24-May-22 02:46:09 - INFO - /home/omarconde/pruebas/pruebas/views.py changed, reloading.
24-May-22 02:46:25 - INFO - usuario logueado:Saul
24-May-22 02:49:14 - INFO - /home/omarconde/pruebas/pruebas/views.py changed, reloading.
24-May-22 02:49:56 - WARNING - Not Found: /favicon.ico
24-May-22 02:51:09 - INFO - /home/omarconde/pruebas/pruebas/views.py changed, reloading.
24-May-22 02:51:21 - INFO - /home/omarconde/pruebas/pruebas/views.py changed, reloading.
24-May-22 02:53:40 - INFO - /home/omarconde/pruebas/pruebas/views.py changed, reloading.
24-May-22 02:53:57 - ERROR - Internal Server Error: /login
Traceback (most recent call last):
  File "/home/omarconde/pruebas/pruebas/views.py", line 93, in login
    alumno = models.Alumnos.objects.get(NombreAlumno=nombre)
  File "/usr/lib/python3/dist-packages/django/db/models/manager.py", line 82, in manager_method
    return getattr(self.get_queryset(), name)(*args, **kwargs)
  File "/usr/lib/python3/dist-packages/django/db/models/query.py", line 406, in get
    raise self.model.DoesNotExist(
modelo.models.Alumnos.DoesNotExist: Alumnos matching query does not exist.

During handling of the above exception, another exception occurred:

Traceback (most recent call last):
  File "/usr/lib/python3/dist-packages/django/core/handlers/exception.py", line 34, in inner
    response = get_response(request)
  File "/usr/lib/python3/dist-packages/django/core/handlers/base.py", line 115, in _get_response
    response = self.process_exception_by_middleware(e, request)
  File "/usr/lib/python3/dist-packages/django/core/handlers/base.py", line 113, in _get_response
    response = wrapped_callback(request, *callback_args, **callback_kwargs)
  File "/home/omarconde/pruebas/pruebas/views.py", line 101, in login
    return render(request,'login.html',{'errores',errores})
TypeError: unhashable type: 'list'
24-May-22 02:54:10 - ERROR - Internal Server Error: /login
Traceback (most recent call last):
  File "/home/omarconde/pruebas/pruebas/views.py", line 93, in login
    alumno = models.Alumnos.objects.get(NombreAlumno=nombre)
  File "/usr/lib/python3/dist-packages/django/db/models/manager.py", line 82, in manager_method
    return getattr(self.get_queryset(), name)(*args, **kwargs)
  File "/usr/lib/python3/dist-packages/django/db/models/query.py", line 406, in get
    raise self.model.DoesNotExist(
modelo.models.Alumnos.DoesNotExist: Alumnos matching query does not exist.

During handling of the above exception, another exception occurred:

Traceback (most recent call last):
  File "/usr/lib/python3/dist-packages/django/core/handlers/exception.py", line 34, in inner
    response = get_response(request)
  File "/usr/lib/python3/dist-packages/django/core/handlers/base.py", line 115, in _get_response
    response = self.process_exception_by_middleware(e, request)
  File "/usr/lib/python3/dist-packages/django/core/handlers/base.py", line 113, in _get_response
    response = wrapped_callback(request, *callback_args, **callback_kwargs)
  File "/home/omarconde/pruebas/pruebas/views.py", line 101, in login
    return render(request,'login.html',{'errores',errores})
TypeError: unhashable type: 'list'
24-May-22 02:54:58 - WARNING - Not Found: /favicon.ico
24-May-22 02:55:46 - INFO - /home/omarconde/pruebas/pruebas/views.py changed, reloading.
24-May-22 02:56:52 - INFO - usuario logueado:Saul
24-May-22 02:57:01 - INFO - usuario logueado:Saul
24-May-22 02:57:53 - INFO - /home/omarconde/pruebas/pruebas/views.py changed, reloading.
24-May-22 02:58:11 - INFO - usuario logueado:Saul
24-May-22 02:59:23 - INFO - /home/omarconde/pruebas/pruebas/views.py changed, reloading.
24-May-22 03:00:14 - INFO - /home/omarconde/pruebas/pruebas/views.py changed, reloading.
24-May-22 03:00:42 - INFO - usuario logueado:Saul
24-May-22 03:00:53 - INFO - usuario logueado:Saul
24-May-22 03:03:19 - INFO - /home/omarconde/pruebas/pruebas/views.py changed, reloading.
24-May-22 03:03:27 - WARNING - Not Found: /favicon.ico
24-May-22 03:03:48 - INFO - usuario logueado:Saul
24-May-22 03:04:02 - INFO - usuario logueado:Saul
24-May-22 03:04:31 - INFO - /home/omarconde/pruebas/pruebas/views.py changed, reloading.
24-May-22 03:04:58 - ERROR - Internal Server Error: /login
Traceback (most recent call last):
  File "/usr/lib/python3/dist-packages/django/core/handlers/exception.py", line 34, in inner
    response = get_response(request)
  File "/usr/lib/python3/dist-packages/django/core/handlers/base.py", line 124, in _get_response
    raise ValueError(
ValueError: The view pruebas.views.login didn't return an HttpResponse object. It returned None instead.
24-May-22 03:08:06 - INFO - /home/omarconde/pruebas/pruebas/views.py changed, reloading.
24-May-22 03:08:33 - INFO - usuario logueado:Saul
24-May-22 03:08:38 - INFO - usuario logueado:Saul
24-May-22 03:21:34 - INFO - /home/omarconde/pruebas/pruebas/views.py changed, reloading.
24-May-22 03:21:44 - WARNING - Not Found: /favicon.ico
24-May-22 03:22:03 - INFO - usuario logueado:Saul
24-May-22 03:22:14 - INFO - usuario logueado:Saul
24-May-22 03:23:07 - INFO - /home/omarconde/pruebas/pruebas/views.py changed, reloading.
24-May-22 03:25:01 - INFO - /home/omarconde/pruebas/pruebas/views.py changed, reloading.
24-May-22 03:29:26 - INFO - /home/omarconde/pruebas/pruebas/views.py changed, reloading.
24-May-22 03:32:37 - INFO - /home/omarconde/pruebas/pruebas/views.py changed, reloading.
24-May-22 03:34:22 - INFO - /home/omarconde/pruebas/pruebas/views.py changed, reloading.
24-May-22 03:42:17 - INFO - /home/omarconde/pruebas/pruebas/views.py changed, reloading.
24-May-22 03:54:42 - INFO - /home/omarconde/pruebas/pruebas/views.py changed, reloading.
24-May-22 04:17:33 - INFO - /home/omarconde/pruebas/pruebas/views.py changed, reloading.
24-May-22 04:17:48 - WARNING - Not Found: /
24-May-22 04:18:18 - INFO - usuario logueado:Saul
24-May-22 04:18:31 - INFO - usuario logueado:Saul
24-May-22 04:21:56 - INFO - /home/omarconde/pruebas/pruebas/views.py changed, reloading.
24-May-22 04:22:01 - ERROR - Internal Server Error: /verificar_token
Traceback (most recent call last):
  File "/home/omarconde/pruebas/pruebas/views.py", line 63, in verificar_token
    token_almacenado = models.Alumnos.objects.get(Token_Env=token)
  File "/usr/lib/python3/dist-packages/django/db/models/manager.py", line 82, in manager_method
    return getattr(self.get_queryset(), name)(*args, **kwargs)
  File "/usr/lib/python3/dist-packages/django/db/models/query.py", line 406, in get
    raise self.model.DoesNotExist(
modelo.models.Alumnos.DoesNotExist: Alumnos matching query does not exist.

During handling of the above exception, another exception occurred:

Traceback (most recent call last):
  File "/usr/lib/python3/dist-packages/django/core/handlers/exception.py", line 34, in inner
    response = get_response(request)
  File "/usr/lib/python3/dist-packages/django/core/handlers/base.py", line 115, in _get_response
    response = self.process_exception_by_middleware(e, request)
  File "/usr/lib/python3/dist-packages/django/core/handlers/base.py", line 113, in _get_response
    response = wrapped_callback(request, *callback_args, **callback_kwargs)
  File "/home/omarconde/pruebas/pruebas/views.py", line 76, in verificar_token
    if token_almacenado.Token_Env == Token:
UnboundLocalError: local variable 'token_almacenado' referenced before assignment
24-May-22 04:22:02 - WARNING - Not Found: /favicon.ico
24-May-22 04:22:14 - INFO - /home/omarconde/pruebas/pruebas/views.py changed, reloading.
24-May-22 04:22:24 - ERROR - Internal Server Error: /verificar_token
Traceback (most recent call last):
  File "/home/omarconde/pruebas/pruebas/views.py", line 63, in verificar_token
    token_almacenado = models.Alumnos.objects.get(Token_Env=token)
  File "/usr/lib/python3/dist-packages/django/db/models/manager.py", line 82, in manager_method
    return getattr(self.get_queryset(), name)(*args, **kwargs)
  File "/usr/lib/python3/dist-packages/django/db/models/query.py", line 406, in get
    raise self.model.DoesNotExist(
modelo.models.Alumnos.DoesNotExist: Alumnos matching query does not exist.

During handling of the above exception, another exception occurred:

Traceback (most recent call last):
  File "/usr/lib/python3/dist-packages/django/core/handlers/exception.py", line 34, in inner
    response = get_response(request)
  File "/usr/lib/python3/dist-packages/django/core/handlers/base.py", line 115, in _get_response
    response = self.process_exception_by_middleware(e, request)
  File "/usr/lib/python3/dist-packages/django/core/handlers/base.py", line 113, in _get_response
    response = wrapped_callback(request, *callback_args, **callback_kwargs)
  File "/home/omarconde/pruebas/pruebas/views.py", line 76, in verificar_token
    if token_almacenado.Token_Env == token:
UnboundLocalError: local variable 'token_almacenado' referenced before assignment
24-May-22 04:23:22 - INFO - /home/omarconde/pruebas/pruebas/views.py changed, reloading.
24-May-22 04:23:30 - ERROR - Internal Server Error: /verificar_token
Traceback (most recent call last):
  File "/home/omarconde/pruebas/pruebas/views.py", line 63, in verificar_token
    token_almacenado = models.Alumnos.objects.get(Token_Env=token)
  File "/usr/lib/python3/dist-packages/django/db/models/manager.py", line 82, in manager_method
    return getattr(self.get_queryset(), name)(*args, **kwargs)
  File "/usr/lib/python3/dist-packages/django/db/models/query.py", line 406, in get
    raise self.model.DoesNotExist(
modelo.models.Alumnos.DoesNotExist: Alumnos matching query does not exist.

During handling of the above exception, another exception occurred:

Traceback (most recent call last):
  File "/usr/lib/python3/dist-packages/django/core/handlers/exception.py", line 34, in inner
    response = get_response(request)
  File "/usr/lib/python3/dist-packages/django/core/handlers/base.py", line 115, in _get_response
    response = self.process_exception_by_middleware(e, request)
  File "/usr/lib/python3/dist-packages/django/core/handlers/base.py", line 113, in _get_response
    response = wrapped_callback(request, *callback_args, **callback_kwargs)
  File "/home/omarconde/pruebas/pruebas/views.py", line 76, in verificar_token
    if token_almacenado.Token_Env == token:
UnboundLocalError: local variable 'token_almacenado' referenced before assignment
24-May-22 04:24:49 - INFO - /home/omarconde/pruebas/pruebas/views.py changed, reloading.
24-May-22 04:25:17 - INFO - usuario logueado:Saul
24-May-22 04:27:09 - INFO - /home/omarconde/pruebas/pruebas/views.py changed, reloading.
24-May-22 04:27:35 - INFO - usuario logueado:Saul
24-May-22 04:28:27 - INFO - /home/omarconde/pruebas/pruebas/views.py changed, reloading.
24-May-22 04:28:31 - INFO - usuario logueado:Saul
24-May-22 04:28:37 - INFO - usuario logueado:Saul
24-May-22 04:29:19 - INFO - /home/omarconde/pruebas/pruebas/views.py changed, reloading.
24-May-22 04:29:29 - INFO - usuario logueado:Saul
24-May-22 04:35:38 - INFO - /home/omarconde/pruebas/pruebas/views.py changed, reloading.
24-May-22 04:36:07 - INFO - usuario logueado:Saul
24-May-22 04:37:39 - INFO - usuario logueado:Saul
24-May-22 04:38:48 - INFO - /home/omarconde/pruebas/pruebas/views.py changed, reloading.
24-May-22 04:39:40 - INFO - usuario logueado:Saul
24-May-22 04:39:56 - INFO - /home/omarconde/pruebas/pruebas/views.py changed, reloading.
24-May-22 04:40:00 - INFO - usuario logueado:Saul
24-May-22 04:40:40 - INFO - usuario logueado:Saul
24-May-22 04:40:53 - INFO - usuario logueado:Saul
24-May-22 04:41:20 - INFO - /home/omarconde/pruebas/pruebas/views.py changed, reloading.
24-May-22 04:41:25 - INFO - usuario logueado:Saul
24-May-22 04:41:55 - INFO - usuario logueado:Saul
24-May-22 04:43:48 - INFO - /home/omarconde/pruebas/pruebas/views.py changed, reloading.
24-May-22 04:44:04 - INFO - usuario logueado:Saul
24-May-22 04:44:13 - INFO - usuario logueado:Saul
24-May-22 04:45:14 - INFO - usuario logueado:Saul
24-May-22 04:45:18 - INFO - usuario logueado:Saul
24-May-22 04:47:04 - INFO - /home/omarconde/pruebas/pruebas/views.py changed, reloading.
24-May-22 04:47:47 - INFO - usuario logueado:Saul
24-May-22 04:52:11 - INFO - /home/omarconde/pruebas/pruebas/views.py changed, reloading.
24-May-22 05:09:16 - INFO - /home/omarconde/pruebas/pruebas/views.py changed, reloading.
24-May-22 05:18:13 - INFO - /home/omarconde/pruebas/pruebas/views.py changed, reloading.
25-May-22 01:22:07 - WARNING - Not Found: /favicon.ico
25-May-22 01:23:48 - INFO - /home/omarconde/pruebas/pruebas/views.py changed, reloading.
25-May-22 01:24:33 - INFO - /home/omarconde/pruebas/pruebas/views.py changed, reloading.
25-May-22 01:26:06 - INFO - /home/omarconde/pruebas/pruebas/views.py changed, reloading.
25-May-22 01:31:06 - INFO - /home/omarconde/pruebas/pruebas/views.py changed, reloading.
25-May-22 01:31:45 - INFO - usuario logueado:Saul
25-May-22 01:32:46 - INFO - /home/omarconde/pruebas/pruebas/views.py changed, reloading.
25-May-22 01:32:54 - INFO - /home/omarconde/pruebas/pruebas/views.py changed, reloading.
25-May-22 01:33:00 - INFO - usuario logueado:Saul
25-May-22 01:33:50 - INFO - /home/omarconde/pruebas/pruebas/views.py changed, reloading.
25-May-22 01:34:05 - ERROR - Internal Server Error: /login
Traceback (most recent call last):
  File "/usr/lib/python3/dist-packages/django/core/handlers/exception.py", line 34, in inner
    response = get_response(request)
  File "/usr/lib/python3/dist-packages/django/core/handlers/base.py", line 124, in _get_response
    raise ValueError(
ValueError: The view pruebas.views.login didn't return an HttpResponse object. It returned None instead.
25-May-22 01:34:29 - INFO - usuario logueado:Saul
25-May-22 01:41:16 - INFO - /home/omarconde/pruebas/pruebas/views.py changed, reloading.
25-May-22 01:41:34 - INFO - /home/omarconde/pruebas/pruebas/views.py changed, reloading.
25-May-22 01:42:08 - INFO - usuario logueado:Saul
25-May-22 01:42:18 - INFO - usuario logueado:Saul
25-May-22 01:43:13 - INFO - usuario logueado:Saul
25-May-22 01:43:20 - INFO - usuario logueado:Saul
25-May-22 01:45:48 - INFO - /home/omarconde/pruebas/pruebas/views.py changed, reloading.
25-May-22 01:47:05 - INFO - /home/omarconde/pruebas/modelo/models.py changed, reloading.
25-May-22 20:24:56 - INFO - /home/omarconde/pruebas/pruebas/views.py changed, reloading.
25-May-22 20:25:24 - INFO - /home/omarconde/pruebas/pruebas/views.py changed, reloading.
25-May-22 20:25:45 - WARNING - Not Found: /
25-May-22 20:25:46 - WARNING - Not Found: /favicon.ico
25-May-22 20:27:40 - INFO - usuario logueado:Saul
25-May-22 20:27:45 - INFO - usuario logueado:Saul
25-May-22 20:33:18 - WARNING - Not Found: /favicon.ico
25-May-22 20:33:38 - WARNING - Not Found: /
25-May-22 20:33:45 - WARNING - Not Found: /
25-May-22 20:34:16 - ERROR - Internal Server Error: /login
Traceback (most recent call last):
  File "/usr/lib/python3/dist-packages/django/core/handlers/exception.py", line 34, in inner
    response = get_response(request)
  File "/usr/lib/python3/dist-packages/django/core/handlers/base.py", line 124, in _get_response
    raise ValueError(
ValueError: The view pruebas.views.login didn't return an HttpResponse object. It returned None instead.
25-May-22 20:34:39 - INFO - usuario logueado:Saul
25-May-22 20:35:20 - INFO - usuario logueado:Saul
25-May-22 20:39:38 - INFO - usuario logueado:Saul
25-May-22 21:02:05 - INFO - usuario logueado:Erik luna villa
25-May-22 21:02:05 - ERROR - Internal Server Error: /verificar_scripts
Traceback (most recent call last):
  File "/usr/local/lib/python3.7/dist-packages/django/core/handlers/exception.py", line 47, in inner
    response = get_response(request)
  File "/usr/local/lib/python3.7/dist-packages/django/core/handlers/base.py", line 181, in _get_response
    response = wrapped_callback(request, *callback_args, **callback_kwargs)
  File "/home/erik/Proyecto_ver_2/Proyectoprograsegura1/ProyectoSeg/pruebas/views.py", line 24, in verificar_scripts
    salida = subprocess.Popen(Comando,stdout=subprocess.PIPE, stderr=subprocess.PIPE)
  File "/usr/lib/python3.7/subprocess.py", line 775, in __init__
    restore_signals, start_new_session)
  File "/usr/lib/python3.7/subprocess.py", line 1522, in _execute_child
    raise child_exception_type(errno_num, err_msg, err_filename)
FileNotFoundError: [Errno 2] No such file or directory: '/home/omarconde/hola.sh': '/home/omarconde/hola.sh'
25-May-22 21:02:52 - INFO - /home/erik/Proyecto_ver_2/Proyectoprograsegura1/ProyectoSeg/pruebas/views.py changed, reloading.
25-May-22 21:03:27 - INFO - usuario logueado:Erik luna villa
25-May-22 21:14:00 - ERROR - Internal Server Error: /login
Traceback (most recent call last):
  File "/usr/local/lib/python3.7/dist-packages/django/core/handlers/exception.py", line 47, in inner
    response = get_response(request)
  File "/usr/local/lib/python3.7/dist-packages/django/core/handlers/base.py", line 181, in _get_response
    response = wrapped_callback(request, *callback_args, **callback_kwargs)
  File "/home/erik/Proyecto_ver_2/Proyectoprograsegura1/ProyectoSeg/pruebas/views.py", line 93, in login
    if puede_hacer_peticion(get_client_ip(request)):
  File "/home/erik/Proyecto_ver_2/Proyectoprograsegura1/ProyectoSeg/pruebas/views.py", line 219, in puede_hacer_peticion
    if not esta_tiempo_en_ventana(registro.timestamp):
  File "/home/erik/Proyecto_ver_2/Proyectoprograsegura1/ProyectoSeg/pruebas/views.py", line 203, in esta_tiempo_en_ventana
    if resta.seconds < conf.VENTANA_SEGUNDOS_INTENTOS_PETICION:
AttributeError: module 'pruebas.settings' has no attribute 'VENTANA_SEGUNDOS_INTENTOS_PETICION'
25-May-22 21:18:51 - ERROR - Internal Server Error: /login
Traceback (most recent call last):
  File "/home/erik/Proyecto_ver_2/Proyectoprograsegura1/ProyectoSeg/pruebas/views.py", line 95, in login
    alumno = models.Alumnos.objects.get(NombreAlumno=nombre)
  File "/usr/local/lib/python3.7/dist-packages/django/db/models/manager.py", line 85, in manager_method
    return getattr(self.get_queryset(), name)(*args, **kwargs)
  File "/usr/local/lib/python3.7/dist-packages/django/db/models/query.py", line 437, in get
    self.model._meta.object_name
modelo.models.Alumnos.DoesNotExist: Alumnos matching query does not exist.

During handling of the above exception, another exception occurred:

Traceback (most recent call last):
  File "/usr/local/lib/python3.7/dist-packages/django/core/handlers/exception.py", line 47, in inner
    response = get_response(request)
  File "/usr/local/lib/python3.7/dist-packages/django/core/handlers/base.py", line 181, in _get_response
    response = wrapped_callback(request, *callback_args, **callback_kwargs)
  File "/home/erik/Proyecto_ver_2/Proyectoprograsegura1/ProyectoSeg/pruebas/views.py", line 103, in login
    return render(request,'login.html',{'errores',errores})
TypeError: unhashable type: 'list'
25-May-22 21:21:27 - INFO - usuario logueado:Omar
25-May-22 21:21:38 - INFO - usuario logueado:Omar
25-May-22 21:22:31 - ERROR - Internal Server Error: /login
Traceback (most recent call last):
  File "/usr/local/lib/python3.7/dist-packages/django/core/handlers/exception.py", line 47, in inner
    response = get_response(request)
  File "/usr/local/lib/python3.7/dist-packages/django/core/handlers/base.py", line 188, in _get_response
    self.check_response(response, callback)
  File "/usr/local/lib/python3.7/dist-packages/django/core/handlers/base.py", line 311, in check_response
    "instead." % name
ValueError: The view pruebas.views.login didn't return an HttpResponse object. It returned None instead.
25-May-22 21:46:13 - ERROR - Invalid HTTP_HOST header: '8c4c-177-240-172-208.ngrok.io'. You may need to add '8c4c-177-240-172-208.ngrok.io' to ALLOWED_HOSTS.
25-May-22 21:46:14 - WARNING - Bad Request: /
25-May-22 21:46:15 - ERROR - Invalid HTTP_HOST header: '8c4c-177-240-172-208.ngrok.io'. You may need to add '8c4c-177-240-172-208.ngrok.io' to ALLOWED_HOSTS.
25-May-22 21:46:15 - WARNING - Bad Request: /
25-May-22 21:46:16 - ERROR - Invalid HTTP_HOST header: '8c4c-177-240-172-208.ngrok.io'. You may need to add '8c4c-177-240-172-208.ngrok.io' to ALLOWED_HOSTS.
25-May-22 21:46:17 - WARNING - Bad Request: /favicon.ico
25-May-22 21:48:32 - ERROR - Invalid HTTP_HOST header: '368e-177-240-172-208.ngrok.io'. You may need to add '368e-177-240-172-208.ngrok.io' to ALLOWED_HOSTS.
25-May-22 21:48:33 - WARNING - Bad Request: /
25-May-22 21:48:33 - ERROR - Invalid HTTP_HOST header: '368e-177-240-172-208.ngrok.io'. You may need to add '368e-177-240-172-208.ngrok.io' to ALLOWED_HOSTS.
25-May-22 21:48:34 - WARNING - Bad Request: /
25-May-22 21:48:35 - ERROR - Invalid HTTP_HOST header: '368e-177-240-172-208.ngrok.io'. You may need to add '368e-177-240-172-208.ngrok.io' to ALLOWED_HOSTS.
25-May-22 21:48:36 - WARNING - Bad Request: /favicon.ico
25-May-22 21:50:50 - ERROR - Invalid HTTP_HOST header: 'b34b-177-240-172-208.ngrok.io'. You may need to add 'b34b-177-240-172-208.ngrok.io' to ALLOWED_HOSTS.
25-May-22 21:50:50 - WARNING - Bad Request: /
25-May-22 21:50:52 - ERROR - Invalid HTTP_HOST header: 'b34b-177-240-172-208.ngrok.io'. You may need to add 'b34b-177-240-172-208.ngrok.io' to ALLOWED_HOSTS.
25-May-22 21:50:53 - WARNING - Bad Request: /favicon.ico
25-May-22 21:51:24 - WARNING - Not Found: /
25-May-22 21:51:25 - WARNING - Not Found: /
25-May-22 21:51:26 - WARNING - Not Found: /favicon.ico
25-May-22 21:53:30 - ERROR - Invalid HTTP_HOST header: '95e6-177-240-172-208.ngrok.io'. You may need to add '95e6-177-240-172-208.ngrok.io' to ALLOWED_HOSTS.
25-May-22 21:53:31 - WARNING - Bad Request: /
25-May-22 21:53:36 - ERROR - Invalid HTTP_HOST header: '95e6-177-240-172-208.ngrok.io'. You may need to add '95e6-177-240-172-208.ngrok.io' to ALLOWED_HOSTS.
25-May-22 21:53:36 - WARNING - Bad Request: /
25-May-22 21:53:37 - ERROR - Invalid HTTP_HOST header: '95e6-177-240-172-208.ngrok.io'. You may need to add '95e6-177-240-172-208.ngrok.io' to ALLOWED_HOSTS.
25-May-22 21:53:37 - WARNING - Bad Request: /favicon.ico
25-May-22 21:53:57 - ERROR - Invalid HTTP_HOST header: '95e6-177-240-172-208.ngrok.io'. You may need to add '95e6-177-240-172-208.ngrok.io' to ALLOWED_HOSTS.
25-May-22 21:53:57 - WARNING - Bad Request: /
25-May-22 21:53:58 - ERROR - Invalid HTTP_HOST header: '95e6-177-240-172-208.ngrok.io'. You may need to add '95e6-177-240-172-208.ngrok.io' to ALLOWED_HOSTS.
25-May-22 21:53:58 - WARNING - Bad Request: /favicon.ico
25-May-22 21:54:13 - ERROR - Invalid HTTP_HOST header: '95e6-177-240-172-208.ngrok.io'. You may need to add '95e6-177-240-172-208.ngrok.io' to ALLOWED_HOSTS.
25-May-22 21:54:13 - WARNING - Bad Request: /
25-May-22 21:54:14 - ERROR - Invalid HTTP_HOST header: '95e6-177-240-172-208.ngrok.io'. You may need to add '95e6-177-240-172-208.ngrok.io' to ALLOWED_HOSTS.
25-May-22 21:54:14 - WARNING - Bad Request: /favicon.ico
25-May-22 21:59:25 - INFO - /home/erik/Proyecto_ver_2/Proyectoprograsegura1/ProyectoSeg/pruebas/settings.py changed, reloading.
25-May-22 22:00:32 - WARNING - Not Found: /
25-May-22 22:00:33 - WARNING - Not Found: /favicon.ico
25-May-22 22:15:11 - WARNING - Not Found: /
25-May-22 22:15:49 - ERROR - Internal Server Error: /login
Traceback (most recent call last):
  File "/usr/local/lib/python3.7/dist-packages/django/core/handlers/exception.py", line 47, in inner
    response = get_response(request)
  File "/usr/local/lib/python3.7/dist-packages/django/core/handlers/base.py", line 188, in _get_response
    self.check_response(response, callback)
  File "/usr/local/lib/python3.7/dist-packages/django/core/handlers/base.py", line 311, in check_response
    "instead." % name
ValueError: The view pruebas.views.login didn't return an HttpResponse object. It returned None instead.
25-May-22 22:19:09 - WARNING - Not Found: /
25-May-22 22:19:29 - WARNING - Not Found: /l
25-May-22 22:20:35 - WARNING - Not Found: /favicon.ico
25-May-22 22:21:06 - ERROR - Internal Server Error: /login
Traceback (most recent call last):
  File "/home/erik/Proyecto_ver_2/Proyectoprograsegura1/ProyectoSeg/pruebas/views.py", line 95, in login
    alumno = models.Alumnos.objects.get(NombreAlumno=nombre)
  File "/usr/local/lib/python3.7/dist-packages/django/db/models/manager.py", line 85, in manager_method
    return getattr(self.get_queryset(), name)(*args, **kwargs)
  File "/usr/local/lib/python3.7/dist-packages/django/db/models/query.py", line 437, in get
    self.model._meta.object_name
modelo.models.Alumnos.DoesNotExist: Alumnos matching query does not exist.

During handling of the above exception, another exception occurred:

Traceback (most recent call last):
  File "/usr/local/lib/python3.7/dist-packages/django/core/handlers/exception.py", line 47, in inner
    response = get_response(request)
  File "/usr/local/lib/python3.7/dist-packages/django/core/handlers/base.py", line 181, in _get_response
    response = wrapped_callback(request, *callback_args, **callback_kwargs)
  File "/home/erik/Proyecto_ver_2/Proyectoprograsegura1/ProyectoSeg/pruebas/views.py", line 103, in login
    return render(request,'login.html',{'errores',errores})
TypeError: unhashable type: 'list'
25-May-22 22:25:23 - INFO - /home/erik/Proyecto_ver_2/Proyectoprograsegura1/ProyectoSeg/pruebas/views.py changed, reloading.
25-May-22 22:25:41 - ERROR - Internal Server Error: /login
Traceback (most recent call last):
  File "/usr/local/lib/python3.7/dist-packages/django/core/handlers/exception.py", line 47, in inner
    response = get_response(request)
  File "/usr/local/lib/python3.7/dist-packages/django/core/handlers/base.py", line 188, in _get_response
    self.check_response(response, callback)
  File "/usr/local/lib/python3.7/dist-packages/django/core/handlers/base.py", line 311, in check_response
    "instead." % name
ValueError: The view pruebas.views.login didn't return an HttpResponse object. It returned None instead.
25-May-22 22:27:32 - WARNING - Not Found: /favicon.ico
25-May-22 22:27:36 - WARNING - Not Found: /favicon.ico
25-May-22 22:27:50 - ERROR - Internal Server Error: /login
Traceback (most recent call last):
  File "/usr/local/lib/python3.7/dist-packages/django/core/handlers/exception.py", line 47, in inner
    response = get_response(request)
  File "/usr/local/lib/python3.7/dist-packages/django/core/handlers/base.py", line 188, in _get_response
    self.check_response(response, callback)
  File "/usr/local/lib/python3.7/dist-packages/django/core/handlers/base.py", line 311, in check_response
    "instead." % name
ValueError: The view pruebas.views.login didn't return an HttpResponse object. It returned None instead.
25-May-22 22:33:41 - ERROR - Internal Server Error: /login
Traceback (most recent call last):
  File "/usr/local/lib/python3.7/dist-packages/django/core/handlers/exception.py", line 47, in inner
    response = get_response(request)
  File "/usr/local/lib/python3.7/dist-packages/django/core/handlers/base.py", line 188, in _get_response
    self.check_response(response, callback)
  File "/usr/local/lib/python3.7/dist-packages/django/core/handlers/base.py", line 311, in check_response
    "instead." % name
ValueError: The view pruebas.views.login didn't return an HttpResponse object. It returned None instead.
25-May-22 22:37:37 - INFO - /home/erik/Proyecto_ver_2/Proyectoprograsegura1/ProyectoSeg/pruebas/views.py changed, reloading.
25-May-22 22:37:47 - ERROR - Internal Server Error: /login
Traceback (most recent call last):
  File "/usr/local/lib/python3.7/dist-packages/django/core/handlers/exception.py", line 47, in inner
    response = get_response(request)
  File "/usr/local/lib/python3.7/dist-packages/django/core/handlers/base.py", line 188, in _get_response
    self.check_response(response, callback)
  File "/usr/local/lib/python3.7/dist-packages/django/core/handlers/base.py", line 311, in check_response
    "instead." % name
ValueError: The view pruebas.views.login didn't return an HttpResponse object. It returned None instead.
25-May-22 22:38:40 - INFO - /home/erik/Proyecto_ver_2/Proyectoprograsegura1/ProyectoSeg/pruebas/views.py changed, reloading.
25-May-22 22:49:45 - INFO - /home/erik/Proyecto_ver_2/Proyectoprograsegura1/ProyectoSeg/pruebas/views.py changed, reloading.
25-May-22 22:50:06 - ERROR - Internal Server Error: /login
Traceback (most recent call last):
  File "/usr/local/lib/python3.7/dist-packages/django/core/handlers/exception.py", line 47, in inner
    response = get_response(request)
  File "/usr/local/lib/python3.7/dist-packages/django/core/handlers/base.py", line 188, in _get_response
    self.check_response(response, callback)
  File "/usr/local/lib/python3.7/dist-packages/django/core/handlers/base.py", line 311, in check_response
    "instead." % name
ValueError: The view pruebas.views.login didn't return an HttpResponse object. It returned None instead.
25-May-22 22:59:10 - ERROR - Internal Server Error: /login
Traceback (most recent call last):
  File "/usr/local/lib/python3.7/dist-packages/django/core/handlers/exception.py", line 47, in inner
    response = get_response(request)
  File "/usr/local/lib/python3.7/dist-packages/django/core/handlers/base.py", line 188, in _get_response
    self.check_response(response, callback)
  File "/usr/local/lib/python3.7/dist-packages/django/core/handlers/base.py", line 311, in check_response
    "instead." % name
ValueError: The view pruebas.views.login didn't return an HttpResponse object. It returned None instead.
25-May-22 22:59:13 - WARNING - Not Found: /favicon.ico
25-May-22 23:05:25 - ERROR - Internal Server Error: /login
Traceback (most recent call last):
  File "/usr/local/lib/python3.7/dist-packages/django/core/handlers/exception.py", line 47, in inner
    response = get_response(request)
  File "/usr/local/lib/python3.7/dist-packages/django/core/handlers/base.py", line 188, in _get_response
    self.check_response(response, callback)
  File "/usr/local/lib/python3.7/dist-packages/django/core/handlers/base.py", line 311, in check_response
    "instead." % name
ValueError: The view pruebas.views.login didn't return an HttpResponse object. It returned None instead.
25-May-22 23:07:15 - INFO - /home/erik/Proyecto_ver_2/Proyectoprograsegura1/ProyectoSeg/pruebas/views.py changed, reloading.
25-May-22 23:13:22 - ERROR - Internal Server Error: /login
Traceback (most recent call last):
  File "/usr/local/lib/python3.7/dist-packages/django/core/handlers/exception.py", line 47, in inner
    response = get_response(request)
  File "/usr/local/lib/python3.7/dist-packages/django/core/handlers/base.py", line 188, in _get_response
    self.check_response(response, callback)
  File "/usr/local/lib/python3.7/dist-packages/django/core/handlers/base.py", line 311, in check_response
    "instead." % name
ValueError: The view pruebas.views.login didn't return an HttpResponse object. It returned None instead.
25-May-22 23:13:48 - ERROR - Internal Server Error: /login
Traceback (most recent call last):
  File "/usr/local/lib/python3.7/dist-packages/django/core/handlers/exception.py", line 47, in inner
    response = get_response(request)
  File "/usr/local/lib/python3.7/dist-packages/django/core/handlers/base.py", line 188, in _get_response
    self.check_response(response, callback)
  File "/usr/local/lib/python3.7/dist-packages/django/core/handlers/base.py", line 311, in check_response
    "instead." % name
ValueError: The view pruebas.views.login didn't return an HttpResponse object. It returned None instead.
25-May-22 23:14:34 - ERROR - Internal Server Error: /login
Traceback (most recent call last):
  File "/usr/local/lib/python3.7/dist-packages/django/core/handlers/exception.py", line 47, in inner
    response = get_response(request)
  File "/usr/local/lib/python3.7/dist-packages/django/core/handlers/base.py", line 188, in _get_response
    self.check_response(response, callback)
  File "/usr/local/lib/python3.7/dist-packages/django/core/handlers/base.py", line 311, in check_response
    "instead." % name
ValueError: The view pruebas.views.login didn't return an HttpResponse object. It returned None instead.
25-May-22 23:15:10 - ERROR - Internal Server Error: /login
Traceback (most recent call last):
  File "/usr/local/lib/python3.7/dist-packages/django/core/handlers/exception.py", line 47, in inner
    response = get_response(request)
  File "/usr/local/lib/python3.7/dist-packages/django/core/handlers/base.py", line 188, in _get_response
    self.check_response(response, callback)
  File "/usr/local/lib/python3.7/dist-packages/django/core/handlers/base.py", line 311, in check_response
    "instead." % name
ValueError: The view pruebas.views.login didn't return an HttpResponse object. It returned None instead.
25-May-22 23:16:05 - ERROR - Internal Server Error: /login
Traceback (most recent call last):
  File "/usr/local/lib/python3.7/dist-packages/django/core/handlers/exception.py", line 47, in inner
    response = get_response(request)
  File "/usr/local/lib/python3.7/dist-packages/django/core/handlers/base.py", line 188, in _get_response
    self.check_response(response, callback)
  File "/usr/local/lib/python3.7/dist-packages/django/core/handlers/base.py", line 311, in check_response
    "instead." % name
ValueError: The view pruebas.views.login didn't return an HttpResponse object. It returned None instead.
25-May-22 23:16:41 - ERROR - Internal Server Error: /login
Traceback (most recent call last):
  File "/usr/local/lib/python3.7/dist-packages/django/core/handlers/exception.py", line 47, in inner
    response = get_response(request)
  File "/usr/local/lib/python3.7/dist-packages/django/core/handlers/base.py", line 188, in _get_response
    self.check_response(response, callback)
  File "/usr/local/lib/python3.7/dist-packages/django/core/handlers/base.py", line 311, in check_response
    "instead." % name
ValueError: The view pruebas.views.login didn't return an HttpResponse object. It returned None instead.
25-May-22 23:18:55 - INFO - usuario logueado:Erik luna villa
25-May-22 23:19:35 - INFO - usuario logueado:Erik luna villa
25-May-22 23:19:49 - INFO - usuario logueado:Erik luna villa
25-May-22 23:20:15 - INFO - /home/erik/Proyecto_ver_2/Proyectoprograsegura1/ProyectoSeg/pruebas/views.py changed, reloading.
25-May-22 23:20:26 - ERROR - Internal Server Error: /login
Traceback (most recent call last):
  File "/usr/local/lib/python3.7/dist-packages/django/core/handlers/exception.py", line 47, in inner
    response = get_response(request)
  File "/usr/local/lib/python3.7/dist-packages/django/core/handlers/base.py", line 188, in _get_response
    self.check_response(response, callback)
  File "/usr/local/lib/python3.7/dist-packages/django/core/handlers/base.py", line 311, in check_response
    "instead." % name
ValueError: The view pruebas.views.login didn't return an HttpResponse object. It returned None instead.
25-May-22 23:21:37 - ERROR - Internal Server Error: /login
Traceback (most recent call last):
  File "/usr/local/lib/python3.7/dist-packages/django/core/handlers/exception.py", line 47, in inner
    response = get_response(request)
  File "/usr/local/lib/python3.7/dist-packages/django/core/handlers/base.py", line 188, in _get_response
    self.check_response(response, callback)
  File "/usr/local/lib/python3.7/dist-packages/django/core/handlers/base.py", line 311, in check_response
    "instead." % name
ValueError: The view pruebas.views.login didn't return an HttpResponse object. It returned None instead.
